Workbook

Sheet Dashboard
A1: RETIREMENT DASHBOARD — 30-Year, 3-Bucket Plan (Age 62 → 92)
B3: Key Metrics
B4: Total Corpus Today (Gold ₹1Cr + Cash ₹1Cr) | E4: Monthly Income — Year 1 | H4: Safe Withdrawal Rate — Year 1
B5: =Corpus -> 20000000 | E5: =MonthlyExp -> 50000 | H5: =(MonthlyExp*12)/Corpus -> 0.03
B7: Retirement Duration | E7: Current Age → Age at Year 30 | H7: Inflation Rate Assumed
B8: =RetYears -> 30 | E8: =Age&" → "&(Age+RetYears) -> 62 → 92 | H8: =Inflation -> 0.07
B10: Bucket 1 Initial (Yrs 1-5, Liquid/FD) | E10: Bucket 2 Initial (Yrs 6-15, Debt/Hybrid) | H10: Bucket 3 Initial (Yrs 16-30, Equity+Gold)
B11: =Corpus*B1Pct -> 3000000 | E11: =Corpus*B2Pct -> 7000000 | H11: =Corpus*B3Pct -> 10000000
B13: Projected Corpus after 30 Years | E13: Overall Plan Health (Year 30) | H13: Avg. Withdrawal Rate (30-yr avg)
B14: ='Annual Summary'!J31 -> 1.957027e+08 | E14: ='Annual Summary'!L31 -> GREEN | H14: =AVERAGE('Annual Summary'!K2:K31) -> 0.027506031
B16: Charts
B17: See charts below — Corpus Growth · Nominal vs Real Income · Bucket Balances · Withdrawal vs Return

Sheet Advisor Mode
A1: ADVISOR MODE — Change these values, the entire plan updates automatically
B3: Change ONLY the yellow cells below. Every sheet in this workbook
B4: (Dashboard, 30-Year Engine, Scenarios, Monte Carlo) recalculates from these.
B6: Current Age (yrs) | C6: 62 | E6: Named ranges used across workbook: Age, Corpus, MonthlyExp, Inflation, GrowthReturn, RetYears
B7: Total Retirement Corpus, ₹ (Gold ₹1 Cr + Cash ₹1 Cr) | C7: 20000000
B8: Desired Monthly Expense — today's value, ₹ | C8: 50000
B9: Expected Inflation Rate | C9: 0.07
B10: Expected Return — Growth/Equity Bucket (Bucket 3) | C10: 0.11
B11: Retirement Duration (Years) | C11: 30
B13: These 5 (+ age) are the ONLY cells you should ever need to touch:
B14: 1) Total Corpus 2) Monthly Expense 3) Inflation 4) Expected Return 5) Retirement Years
B17: Example: if your corpus grows from ₹2 Cr to ₹3 Cr in future, just update C7 — Bucket splits,
B18: the 30-year cash-flow, scenarios and Monte Carlo results will all re-size automatically.

Sheet Assumptions
A1: ASSUMPTIONS — 3-Bucket Allocation, Returns & Scenario Settings
B3: Bucket Allocation (% of Total Corpus) — editable
B4: Bucket 1 — Income Bucket (Yrs 1-5) % | C4: 0.15
B5: Bucket 2 — Refill Bucket (Yrs 6-15) % | C5: 0.35
B6: Bucket 3 — Growth Bucket (Yrs 16-30) % | C6: 0.5
B7: Check — must equal 100% | C7: =C4+C5+C6 -> 1
B9: Bucket Return Offsets vs Growth Rate (Advisor Mode C10) — editable
B10: Bucket 1 offset (Liquid/FD, safest) | C10: -0.04
B11: Bucket 2 offset (Debt/Hybrid) | C11: -0.02
B12: Bucket 3 offset (Equity + Gold, full growth rate) | C12: 0
B14: Resulting Bucket Returns (calculated, linked to Advisor Mode)
B15: Bucket 1 Return p.a. (FD / Liquid Fund) | C15: =GrowthReturn+C10 -> 0.07
B16: Bucket 2 Return p.a. (Debt / Hybrid Fund) | C16: =GrowthReturn+C11 -> 0.09
B17: Bucket 3 Return p.a. (Equity + Gold) | C17: =GrowthReturn+C12 -> 0.11
B19: Bucket Refill Schedule (fixed, per your design)
B20: Bucket 2 → Bucket 1 refills at End of Year | C20: 5, 10, 15, 20, 25
B21: Bucket 3 → Bucket 2 refills at End of Year | C21: 15, 20, 25
B22: Bucket 1 always holds ~5 years of expenses in reserve
B24: Scenario Analysis — Return Delta Applied to Blended Portfolio
B25: Weak / Bad Market Case — return delta | C25: -0.02
B26: Expected / Normal Case — return delta | C26: 0
B27: Best Case — return delta | C27: 0.02
B29: Monte Carlo Volatility Assumptions (std. deviation p.a.) — editable
B30: Bucket 1 Std. Deviation | C30: 0.01
B31: Bucket 2 Std. Deviation | C31: 0.05
B32: Bucket 3 Std. Deviation | C32: 0.16
B34: Safe Withdrawal Rate (SWR) Health-Check Bands
B35: Green: Annual Withdrawal / Opening Corpus ≤ | C35: 0.04
B36: Yellow: up to | C36: 0.06
B37: Red: above Yellow threshold
B39: → See 'Instrument Guide' sheet for which actual instruments to hold in each Bucket.

Sheet Monthly Engine
A1: Month | B1: Year | C1: Age | D1: Monthly Expense (inflated) | E1: B1 Opening | F1: B1 Return | G1: B1 Withdrawal | H1: Transfer Trigger Amt | I1: B1 Transfer In | J1: B1 Closing | K1: B2 Opening | L1: B2 Return | M1: B2 Transfer Out | N1: B2 Transfer In | O1: B2 Closing | P1: B3 Opening | Q1: B3 Return | R1: B3 Transfer Out | S1: B3 Closing | T1: Total Corpus
A2: 1 | B2: =ROUNDUP(A2/12,0) -> 1 | C2: =Age+B2-1 -> 62 | D2: =MonthlyExp*(1+Inflation)^(B2-1) -> 50000 | E2: =Corpus*B1Pct -> 3000000 | F2: =E2*B1Ret/12 -> 17500 | G2: =D2 -> 50000 | H2: 0 | I2: =H2 -> 0 | J2: =E2+F2-G2+I2 -> 2967500 | K2: =Corpus*B2Pct -> 7000000 | L2: =K2*B2Ret/12 -> 52500 | M2: =-I2 -> 0 | N2: 0 | O2: =K2+L2+M2+N2 -> 7052500 | P2: =Corpus*B3Pct -> 10000000 | Q2: =P2*B3Ret/12 -> 91666.667 | R2: =-N2 -> 0 | S2: =P2+Q2+R2 -> 10091667 | T2: =J2+O2+S2 -> 20111667
A3: 2 | B3: =ROUNDUP(A3/12,0) -> 1 | C3: =Age+B3-1 -> 62 | D3: =MonthlyExp*(1+Inflation)^(B3-1) -> 50000 | E3: =J2 -> 2967500 | F3: =E3*B1Ret/12 -> 17310.417 | G3: =D3 -> 50000 | H3: 0 | I3: =H3 -> 0 | J3: =E3+F3-G3+I3 -> 2934810.4 | K3: =O2 -> 7052500 | L3: =K3*B2Ret/12 -> 52893.75 | M3: =-I3 -> 0 | N3: 0 | O3: =K3+L3+M3+N3 -> 7105393.8 | P3: =S2 -> 10091667 | Q3: =P3*B3Ret/12 -> 92506.944 | R3: =-N3 -> 0 | S3: =P3+Q3+R3 -> 10184174 | T3: =J3+O3+S3 -> 20224378
A4: 3 | B4: =ROUNDUP(A4/12,0) -> 1 | C4: =Age+B4-1 -> 62 | D4: =MonthlyExp*(1+Inflation)^(B4-1) -> 50000 | E4: =J3 -> 2934810.4 | F4: =E4*B1Ret/12 -> 17119.727 | G4: =D4 -> 50000 | H4: 0 | I4: =H4 -> 0 | J4: =E4+F4-G4+I4 -> 2901930.1 | K4: =O3 -> 7105393.8 | L4: =K4*B2Ret/12 -> 53290.453 | M4: =-I4 -> 0 | N4: 0 | O4: =K4+L4+M4+N4 -> 7158684.2 | P4: =S3 -> 10184174 | Q4: =P4*B3Ret/12 -> 93354.925 | R4: =-N4 -> 0 | S4: =P4+Q4+R4 -> 10277529 | T4: =J4+O4+S4 -> 20338143
A5: 4 | B5: =ROUNDUP(A5/12,0) -> 1 | C5: =Age+B5-1 -> 62 | D5: =MonthlyExp*(1+Inflation)^(B5-1) -> 50000 | E5: =J4 -> 2901930.1 | F5: =E5*B1Ret/12 -> 16927.926 | G5: =D5 -> 50000 | H5: 0 | I5: =H5 -> 0 | J5: =E5+F5-G5+I5 -> 2868858.1 | K5: =O4 -> 7158684.2 | L5: =K5*B2Ret/12 -> 53690.132 | M5: =-I5 -> 0 | N5: 0 | O5: =K5+L5+M5+N5 -> 7212374.3 | P5: =S4 -> 10277529 | Q5: =P5*B3Ret/12 -> 94210.678 | R5: =-N5 -> 0 | S5: =P5+Q5+R5 -> 10371739 | T5: =J5+O5+S5 -> 20452972
A6: 5 | B6: =ROUNDUP(A6/12,0) -> 1 | C6: =Age+B6-1 -> 62 | D6: =MonthlyExp*(1+Inflation)^(B6-1) -> 50000 | E6: =J5 -> 2868858.1 | F6: =E6*B1Ret/12 -> 16735.005 | G6: =D6 -> 50000 | H6: 0 | I6: =H6 -> 0 | J6: =E6+F6-G6+I6 -> 2835593.1 | K6: =O5 -> 7212374.3 | L6: =K6*B2Ret/12 -> 54092.808 | M6: =-I6 -> 0 | N6: 0 | O6: =K6+L6+M6+N6 -> 7266467.1 | P6: =S5 -> 10371739 | Q6: =P6*B3Ret/12 -> 95074.276 | R6: =-N6 -> 0 | S6: =P6+Q6+R6 -> 10466813 | T6: =J6+O6+S6 -> 20568874
A7: 6 | B7: =ROUNDUP(A7/12,0) -> 1 | C7: =Age+B7-1 -> 62 | D7: =MonthlyExp*(1+Inflation)^(B7-1) -> 50000 | E7: =J6 -> 2835593.1 | F7: =E7*B1Ret/12 -> 16540.96 | G7: =D7 -> 50000 | H7: 0 | I7: =H7 -> 0 | J7: =E7+F7-G7+I7 -> 2802134 | K7: =O6 -> 7266467.1 | L7: =K7*B2Ret/12 -> 54498.504 | M7: =-I7 -> 0 | N7: 0 | O7: =K7+L7+M7+N7 -> 7320965.6 | P7: =S6 -> 10466813 | Q7: =P7*B3Ret/12 -> 95945.79 | R7: =-N7 -> 0 | S7: =P7+Q7+R7 -> 10562759 | T7: =J7+O7+S7 -> 20685859
A8: 7 | B8: =ROUNDUP(A8/12,0) -> 1 | C8: =Age+B8-1 -> 62 | D8: =MonthlyExp*(1+Inflation)^(B8-1) -> 50000 | E8: =J7 -> 2802134 | F8: =E8*B1Ret/12 -> 16345.782 | G8: =D8 -> 50000 | H8: 0 | I8: =H8 -> 0 | J8: =E8+F8-G8+I8 -> 2768479.8 | K8: =O7 -> 7320965.6 | L8: =K8*B2Ret/12 -> 54907.242 | M8: =-I8 -> 0 | N8: 0 | O8: =K8+L8+M8+N8 -> 7375872.9 | P8: =S7 -> 10562759 | Q8: =P8*B3Ret/12 -> 96825.293 | R8: =-N8 -> 0 | S8: =P8+Q8+R8 -> 10659585 | T8: =J8+O8+S8 -> 20803937
A9: 8 | B9: =ROUNDUP(A9/12,0) -> 1 | C9: =Age+B9-1 -> 62 | D9: =MonthlyExp*(1+Inflation)^(B9-1) -> 50000 | E9: =J8 -> 2768479.8 | F9: =E9*B1Ret/12 -> 16149.466 | G9: =D9 -> 50000 | H9: 0 | I9: =H9 -> 0 | J9: =E9+F9-G9+I9 -> 2734629.3 | K9: =O8 -> 7375872.9 | L9: =K9*B2Ret/12 -> 55319.047 | M9: =-I9 -> 0 | N9: 0 | O9: =K9+L9+M9+N9 -> 7431191.9 | P9: =S8 -> 10659585 | Q9: =P9*B3Ret/12 -> 97712.859 | R9: =-N9 -> 0 | S9: =P9+Q9+R9 -> 10757297 | T9: =J9+O9+S9 -> 20923119
A10: 9 | B10: =ROUNDUP(A10/12,0) -> 1 | C10: =Age+B10-1 -> 62 | D10: =MonthlyExp*(1+Inflation)^(B10-1) -> 50000 | E10: =J9 -> 2734629.3 | F10: =E10*B1Ret/12 -> 15952.004 | G10: =D10 -> 50000 | H10: 0 | I10: =H10 -> 0 | J10: =E10+F10-G10+I10 -> 2700581.3 | K10: =O9 -> 7431191.9 | L10: =K10*B2Ret/12 -> 55733.94 | M10: =-I10 -> 0 | N10: 0 | O10: =K10+L10+M10+N10 -> 7486925.9 | P10: =S9 -> 10757297 | Q10: =P10*B3Ret/12 -> 98608.56 | R10: =-N10 -> 0 | S10: =P10+Q10+R10 -> 10855906 | T10: =J10+O10+S10 -> 21043413
A11: 10 | B11: =ROUNDUP(A11/12,0) -> 1 | C11: =Age+B11-1 -> 62 | D11: =MonthlyExp*(1+Inflation)^(B11-1) -> 50000 | E11: =J10 -> 2700581.3 | F11: =E11*B1Ret/12 -> 15753.391 | G11: =D11 -> 50000 | H11: 0 | I11: =H11 -> 0 | J11: =E11+F11-G11+I11 -> 2666334.7 | K11: =O10 -> 7486925.9 | L11: =K11*B2Ret/12 -> 56151.944 | M11: =-I11 -> 0 | N11: 0 | O11: =K11+L11+M11+N11 -> 7543077.8 | P11: =S10 -> 10855906 | Q11: =P11*B3Ret/12 -> 99512.472 | R11: =-N11 -> 0 | S11: =P11+Q11+R11 -> 10955418 | T11: =J11+O11+S11 -> 21164831
A12: 11 | B12: =ROUNDUP(A12/12,0) -> 1 | C12: =Age+B12-1 -> 62 | D12: =MonthlyExp*(1+Inflation)^(B12-1) -> 50000 | E12: =J11 -> 2666334.7 | F12: =E12*B1Ret/12 -> 15553.619 | G12: =D12 -> 50000 | H12: 0 | I12: =H12 -> 0 | J12: =E12+F12-G12+I12 -> 2631888.3 | K12: =O11 -> 7543077.8 | L12: =K12*B2Ret/12 -> 56573.084 | M12: =-I12 -> 0 | N12: 0 | O12: =K12+L12+M12+N12 -> 7599650.9 | P12: =S11 -> 10955418 | Q12: =P12*B3Ret/12 -> 100424.67 | R12: =-N12 -> 0 | S12: =P12+Q12+R12 -> 11055843 | T12: =J12+O12+S12 -> 21287382
A13: 12 | B13: =ROUNDUP(A13/12,0) -> 1 | C13: =Age+B13-1 -> 62 | D13: =MonthlyExp*(1+Inflation)^(B13-1) -> 50000 | E13: =J12 -> 2631888.3 | F13: =E13*B1Ret/12 -> 15352.682 | G13: =D13 -> 50000 | H13: 0 | I13: =H13 -> 0 | J13: =E13+F13-G13+I13 -> 2597241 | K13: =O12 -> 7599650.9 | L13: =K13*B2Ret/12 -> 56997.382 | M13: =-I13 -> 0 | N13: 0 | O13: =K13+L13+M13+N13 -> 7656648.3 | P13: =S12 -> 11055843 | Q13: =P13*B3Ret/12 -> 101345.23 | R13: =-N13 -> 0 | S13: =P13+Q13+R13 -> 11157188 | T13: =J13+O13+S13 -> 21411078
A14: 13 | B14: =ROUNDUP(A14/12,0) -> 2 | C14: =Age+B14-1 -> 63 | D14: =MonthlyExp*(1+Inflation)^(B14-1) -> 53500 | E14: =J13 -> 2597241 | F14: =E14*B1Ret/12 -> 15150.572 | G14: =D14 -> 53500 | H14: 0 | I14: =H14 -> 0 | J14: =E14+F14-G14+I14 -> 2558891.6 | K14: =O13 -> 7656648.3 | L14: =K14*B2Ret/12 -> 57424.862 | M14: =-I14 -> 0 | N14: 0 | O14: =K14+L14+M14+N14 -> 7714073.1 | P14: =S13 -> 11157188 | Q14: =P14*B3Ret/12 -> 102274.23 | R14: =-N14 -> 0 | S14: =P14+Q14+R14 -> 11259463 | T14: =J14+O14+S14 -> 21532427
... A60: 59 | B60: =ROUNDUP(A60/12,0) -> 5 | C60: =Age+B60-1 -> 66 | D60: =MonthlyExp*(1+Inflation)^(B60-1) -> 65539.8 | E60: =J59 -> 302341.63 | F60: =E60*B1Ret/12 -> 1763.6595 | G60: =D60 -> 65539.8 | H60: 0 | I60: =H60 -> 0 | J60: =E60+F60-G60+I60 -> 238565.49 | K60: =O59 -> 10797202 | L60: =K60*B2Ret/12 -> 80979.014 | M60: =-I60 -> 0 | N60: 0 | O60: =K60+L60+M60+N60 -> 10878181 | P60: =S59 -> 16976495 | Q60: =P60*B3Ret/12 -> 155617.87 | R60: =-N60 -> 0 | S60: =P60+Q60+R60 -> 17132113 | T60: =J60+O60+S60 -> 28248859
A61: 60 | B61: =ROUNDUP(A61/12,0) -> 5 | C61: =Age+B61-1 -> 66 | D61: =MonthlyExp*(1+Inflation)^(B61-1) -> 65539.8 | E61: =J60 -> 238565.49 | F61: =E61*B1Ret/12 -> 1391.632 | G61: =D61 -> 65539.8 | H61: =MAX(SUM(D62:D121)-(E61+F61-G61),0) -> 4665008 | I61: =H61 -> 4665008 | J61: =E61+F61-G61+I61 -> 4839425.4 | K61: =O60 -> 10878181 | L61: =K61*B2Ret/12 -> 81586.356 | M61: =-I61 -> -4665008 | N61: 0 | O61: =K61+L61+M61+N61 -> 6294759.1 | P61: =S60 -> 17132113 | Q61: =P61*B3Ret/12 -> 157044.37 | R61: =-N61 -> 0 | S61: =P61+Q61+R61 -> 17289157 | T61: =J61+O61+S61 -> 28423342
A62: 61 | B62: =ROUNDUP(A62/12,0) -> 6 | C62: =Age+B62-1 -> 67 | D62: =MonthlyExp*(1+Inflation)^(B62-1) -> 70127.587 | E62: =J61 -> 4839425.4 | F62: =E62*B1Ret/12 -> 28229.981 | G62: =D62 -> 70127.587 | H62: 0 | I62: =H62 -> 0 | J62: =E62+F62-G62+I62 -> 4797527.8 | K62: =O61 -> 6294759.1 | L62: =K62*B2Ret/12 -> 47210.694 | M62: =-I62 -> 0 | N62: 0 | O62: =K62+L62+M62+N62 -> 6341969.8 | P62: =S61 -> 17289157 | Q62: =P62*B3Ret/12 -> 158483.94 | R62: =-N62 -> 0 | S62: =P62+Q62+R62 -> 17447641 | T62: =J62+O62+S62 -> 28587139
A63: 62 | B63: =ROUNDUP(A63/12,0) -> 6 | C63: =Age+B63-1 -> 67 | D63: =MonthlyExp*(1+Inflation)^(B63-1) -> 70127.587 | E63: =J62 -> 4797527.8 | F63: =E63*B1Ret/12 -> 27985.579 | G63: =D63 -> 70127.587 | H63: 0 | I63: =H63 -> 0 | J63: =E63+F63-G63+I63 -> 4755385.8 | K63: =O62 -> 6341969.8 | L63: =K63*B2Ret/12 -> 47564.774 | M63: =-I63 -> 0 | N63: 0 | O63: =K63+L63+M63+N63 -> 6389534.6 | P63: =S62 -> 17447641 | Q63: =P63*B3Ret/12 -> 159936.71 | R63: =-N63 -> 0 | S63: =P63+Q63+R63 -> 17607578 | T63: =J63+O63+S63 -> 28752498
A64: 63 | B64: =ROUNDUP(A64/12,0) -> 6 | C64: =Age+B64-1 -> 67 | D64: =MonthlyExp*(1+Inflation)^(B64-1) -> 70127.587 | E64: =J63 -> 4755385.8 | F64: =E64*B1Ret/12 -> 27739.75 | G64: =D64 -> 70127.587 | H64: 0 | I64: =H64 -> 0 | J64: =E64+F64-G64+I64 -> 4712997.9 | K64: =O63 -> 6389534.6 | L64: =K64*B2Ret/12 -> 47921.51 | M64: =-I64 -> 0 | N64: 0 | O64: =K64+L64+M64+N64 -> 6437456.1 | P64: =S63 -> 17607578 | Q64: =P64*B3Ret/12 -> 161402.8 | R64: =-N64 -> 0 | S64: =P64+Q64+R64 -> 17768981 | T64: =J64+O64+S64 -> 28919435
A65: 64 | B65: =ROUNDUP(A65/12,0) -> 6 | C65: =Age+B65-1 -> 67 | D65: =MonthlyExp*(1+Inflation)^(B65-1) -> 70127.587 | E65: =J64 -> 4712997.9 | F65: =E65*B1Ret/12 -> 27492.488 | G65: =D65 -> 70127.587 | H65: 0 | I65: =H65 -> 0 | J65: =E65+F65-G65+I65 -> 4670362.8 | K65: =O64 -> 6437456.1 | L65: =K65*B2Ret/12 -> 48280.921 | M65: =-I65 -> 0 | N65: 0 | O65: =K65+L65+M65+N65 -> 6485737 | P65: =S64 -> 17768981 | Q65: =P65*B3Ret/12 -> 162882.32 | R65: =-N65 -> 0 | S65: =P65+Q65+R65 -> 17931863 | T65: =J65+O65+S65 -> 29087963
A66: 65 | B66: =ROUNDUP(A66/12,0) -> 6 | C66: =Age+B66-1 -> 67 | D66: =MonthlyExp*(1+Inflation)^(B66-1) -> 70127.587 | E66: =J65 -> 4670362.8 | F66: =E66*B1Ret/12 -> 27243.783 | G66: =D66 -> 70127.587 | H66: 0 | I66: =H66 -> 0 | J66: =E66+F66-G66+I66 -> 4627479 | K66: =O65 -> 6485737 | L66: =K66*B2Ret/12 -> 48643.028 | M66: =-I66 -> 0 | N66: 0 | O66: =K66+L66+M66+N66 -> 6534380.1 | P66: =S65 -> 17931863 | Q66: =P66*B3Ret/12 -> 164375.41 | R66: =-N66 -> 0 | S66: =P66+Q66+R66 -> 18096238 | T66: =J66+O66+S66 -> 29258098
A67: 66 | B67: =ROUNDUP(A67/12,0) -> 6 | C67: =Age+B67-1 -> 67 | D67: =MonthlyExp*(1+Inflation)^(B67-1) -> 70127.587 | E67: =J66 -> 4627479 | F67: =E67*B1Ret/12 -> 26993.628 | G67: =D67 -> 70127.587 | H67: 0 | I67: =H67 -> 0 | J67: =E67+F67-G67+I67 -> 4584345.1 | K67: =O66 -> 6534380.1 | L67: =K67*B2Ret/12 -> 49007.85 | M67: =-I67 -> 0 | N67: 0 | O67: =K67+L67+M67+N67 -> 6583387.9 | P67: =S66 -> 18096238 | Q67: =P67*B3Ret/12 -> 165882.19 | R67: =-N67 -> 0 | S67: =P67+Q67+R67 -> 18262121 | T67: =J67+O67+S67 -> 29429854
A68: 67 | B68: =ROUNDUP(A68/12,0) -> 6 | C68: =Age+B68-1 -> 67 | D68: =MonthlyExp*(1+Inflation)^(B68-1) -> 70127.587 | E68: =J67 -> 4584345.1 | F68: =E68*B1Ret/12 -> 26742.013 | G68: =D68 -> 70127.587 | H68: 0 | I68: =H68 -> 0 | J68: =E68+F68-G68+I68 -> 4540959.5 | K68: =O67 -> 6583387.9 | L68: =K68*B2Ret/12 -> 49375.409 | M68: =-I68 -> 0 | N68: 0 | O68: =K68+L68+M68+N68 -> 6632763.3 | P68: =S67 -> 18262121 | Q68: =P68*B3Ret/12 -> 167402.77 | R68: =-N68 -> 0 | S68: =P68+Q68+R68 -> 18429523 | T68: =J68+O68+S68 -> 29603246
A69: 68 | B69: =ROUNDUP(A69/12,0) -> 6 | C69: =Age+B69-1 -> 67 | D69: =MonthlyExp*(1+Inflation)^(B69-1) -> 70127.587 | E69: =J68 -> 4540959.5 | F69: =E69*B1Ret/12 -> 26488.93 | G69: =D69 -> 70127.587 | H69: 0 | I69: =H69 -> 0 | J69: =E69+F69-G69+I69 -> 4497320.8 | K69: =O68 -> 6632763.3 | L69: =K69*B2Ret/12 -> 49745.725 | M69: =-I69 -> 0 | N69: 0 | O69: =K69+L69+M69+N69 -> 6682509.1 | P69: =S68 -> 18429523 | Q69: =P69*B3Ret/12 -> 168937.3 | R69: =-N69 -> 0 | S69: =P69+Q69+R69 -> 18598461 | T69: =J69+O69+S69 -> 29778291
A70: 69 | B70: =ROUNDUP(A70/12,0) -> 6 | C70: =Age+B70-1 -> 67 | D70: =MonthlyExp*(1+Inflation)^(B70-1) -> 70127.587 | E70: =J69 -> 4497320.8 | F70: =E70*B1Ret/12 -> 26234.372 | G70: =D70 -> 70127.587 | H70: 0 | I70: =H70 -> 0 | J70: =E70+F70-G70+I70 -> 4453427.6 | K70: =O69 -> 6682509.1 | L70: =K70*B2Ret/12 -> 50118.818 | M70: =-I70 -> 0 | N70: 0 | O70: =K70+L70+M70+N70 -> 6732627.9 | P70: =S69 -> 18598461 | Q70: =P70*B3Ret/12 -> 170485.89 | R70: =-N70 -> 0 | S70: =P70+Q70+R70 -> 18768947 | T70: =J70+O70+S70 -> 29955002
A71: 70 | B71: =ROUNDUP(A71/12,0) -> 6 | C71: =Age+B71-1 -> 67 | D71: =MonthlyExp*(1+Inflation)^(B71-1) -> 70127.587 | E71: =J70 -> 4453427.6 | F71: =E71*B1Ret/12 -> 25978.328 | G71: =D71 -> 70127.587 | H71: 0 | I71: =H71 -> 0 | J71: =E71+F71-G71+I71 -> 4409278.4 | K71: =O70 -> 6732627.9 | L71: =K71*B2Ret/12 -> 50494.709 | M71: =-I71 -> 0 | N71: 0 | O71: =K71+L71+M71+N71 -> 6783122.6 | P71: =S70 -> 18768947 | Q71: =P71*B3Ret/12 -> 172048.68 | R71: =-N71 -> 0 | S71: =P71+Q71+R71 -> 18940995 | T71: =J71+O71+S71 -> 30133396
A72: 71 | B72: =ROUNDUP(A72/12,0) -> 6 | C72: =Age+B72-1 -> 67 | D72: =MonthlyExp*(1+Inflation)^(B72-1) -> 70127.587 | E72: =J71 -> 4409278.4 | F72: =E72*B1Ret/12 -> 25720.79 | G72: =D72 -> 70127.587 | H72: 0 | I72: =H72 -> 0 | J72: =E72+F72-G72+I72 -> 4364871.6 | K72: =O71 -> 6783122.6 | L72: =K72*B2Ret/12 -> 50873.419 | M72: =-I72 -> 0 | N72: 0 | O72: =K72+L72+M72+N72 -> 6833996 | P72: =S71 -> 18940995 | Q72: =P72*B3Ret/12 -> 173625.79 | R72: =-N72 -> 0 | S72: =P72+Q72+R72 -> 19114621 | T72: =J72+O72+S72 -> 30313489
A73: 72 | B73: =ROUNDUP(A73/12,0) -> 6 | C73: =Age+B73-1 -> 67 | D73: =MonthlyExp*(1+Inflation)^(B73-1) -> 70127.587 | E73: =J72 -> 4364871.6 | F73: =E73*B1Ret/12 -> 25461.751 | G73: =D73 -> 70127.587 | H73: 0 | I73: =H73 -> 0 | J73: =E73+F73-G73+I73 -> 4320205.7 | K73: =O72 -> 6833996 | L73: =K73*B2Ret/12 -> 51254.97 | M73: =-I73 -> 0 | N73: 0 | O73: =K73+L73+M73+N73 -> 6885251 | P73: =S72 -> 19114621 | Q73: =P73*B3Ret/12 -> 175217.36 | R73: =-N73 -> 0 | S73: =P73+Q73+R73 -> 19289838 | T73: =J73+O73+S73 -> 30495295
... A120: 119 | B120: =ROUNDUP(A120/12,0) -> 10 | C120: =Age+B120-1 -> 71 | D120: =MonthlyExp*(1+Inflation)^(B120-1) -> 91922.961 | E120: =J119 -> 1309305 | F120: =E120*B1Ret/12 -> 7637.6127 | G120: =D120 -> 91922.961 | H120: 0 | I120: =H120 -> 0 | J120: =E120+F120-G120+I120 -> 1225019.7 | K120: =O119 -> 9709397.8 | L120: =K120*B2Ret/12 -> 72820.484 | M120: =-I120 -> 0 | N120: 0 | O120: =K120+L120+M120+N120 -> 9782218.3 | P120: =S119 -> 29350929 | Q120: =P120*B3Ret/12 -> 269050.19 | R120: =-N120 -> 0 | S120: =P120+Q120+R120 -> 29619980 | T120: =J120+O120+S120 -> 40627218
A121: 120 | B121: =ROUNDUP(A121/12,0) -> 10 | C121: =Age+B121-1 -> 71 | D121: =MonthlyExp*(1+Inflation)^(B121-1) -> 91922.961 | E121: =J120 -> 1225019.7 | F121: =E121*B1Ret/12 -> 7145.9482 | G121: =D121 -> 91922.961 | H121: =MAX(SUM(D122:D181)-(E121+F121-G121),0) -> 5647301.7 | I121: =H121 -> 5647301.7 | J121: =E121+F121-G121+I121 -> 6787544.4 | K121: =O120 -> 9782218.3 | L121: =K121*B2Ret/12 -> 73366.637 | M121: =-I121 -> -5647301.7 | N121: 0 | O121: =K121+L121+M121+N121 -> 4208283.2 | P121: =S120 -> 29619980 | Q121: =P121*B3Ret/12 -> 271516.48 | R121: =-N121 -> 0 | S121: =P121+Q121+R121 -> 29891496 | T121: =J121+O121+S121 -> 40887324
A122: 121 | B122: =ROUNDUP(A122/12,0) -> 11 | C122: =Age+B122-1 -> 72 | D122: =MonthlyExp*(1+Inflation)^(B122-1) -> 98357.568 | E122: =J121 -> 6787544.4 | F122: =E122*B1Ret/12 -> 39594.009 | G122: =D122 -> 98357.568 | H122: 0 | I122: =H122 -> 0 | J122: =E122+F122-G122+I122 -> 6728780.9 | K122: =O121 -> 4208283.2 | L122: =K122*B2Ret/12 -> 31562.124 | M122: =-I122 -> 0 | N122: 0 | O122: =K122+L122+M122+N122 -> 4239845.3 | P122: =S121 -> 29891496 | Q122: =P122*B3Ret/12 -> 274005.38 | R122: =-N122 -> 0 | S122: =P122+Q122+R122 -> 30165501 | T122: =J122+O122+S122 -> 41134128
A123: 122 | B123: =ROUNDUP(A123/12,0) -> 11 | C123: =Age+B123-1 -> 72 | D123: =MonthlyExp*(1+Inflation)^(B123-1) -> 98357.568 | E123: =J122 -> 6728780.9 | F123: =E123*B1Ret/12 -> 39251.222 | G123: =D123 -> 98357.568 | H123: 0 | I123: =H123 -> 0 | J123: =E123+F123-G123+I123 -> 6669674.5 | K123: =O122 -> 4239845.3 | L123: =K123*B2Ret/12 -> 31798.84 | M123: =-I123 -> 0 | N123: 0 | O123: =K123+L123+M123+N123 -> 4271644.2 | P123: =S122 -> 30165501 | Q123: =P123*B3Ret/12 -> 276517.1 | R123: =-N123 -> 0 | S123: =P123+Q123+R123 -> 30442019 | T123: =J123+O123+S123 -> 41383337
A124: 123 | B124: =ROUNDUP(A124/12,0) -> 11 | C124: =Age+B124-1 -> 72 | D124: =MonthlyExp*(1+Inflation)^(B124-1) -> 98357.568 | E124: =J123 -> 6669674.5 | F124: =E124*B1Ret/12 -> 38906.435 | G124: =D124 -> 98357.568 | H124: 0 | I124: =H124 -> 0 | J124: =E124+F124-G124+I124 -> 6610223.4 | K124: =O123 -> 4271644.2 | L124: =K124*B2Ret/12 -> 32037.331 | M124: =-I124 -> 0 | N124: 0 | O124: =K124+L124+M124+N124 -> 4303681.5 | P124: =S123 -> 30442019 | Q124: =P124*B3Ret/12 -> 279051.84 | R124: =-N124 -> 0 | S124: =P124+Q124+R124 -> 30721070 | T124: =J124+O124+S124 -> 41634975
A125: 124 | B125: =ROUNDUP(A125/12,0) -> 11 | C125: =Age+B125-1 -> 72 | D125: =MonthlyExp*(1+Inflation)^(B125-1) -> 98357.568 | E125: =J124 -> 6610223.4 | F125: =E125*B1Ret/12 -> 38559.636 | G125: =D125 -> 98357.568 | H125: 0 | I125: =H125 -> 0 | J125: =E125+F125-G125+I125 -> 6550425.5 | K125: =O124 -> 4303681.5 | L125: =K125*B2Ret/12 -> 32277.611 | M125: =-I125 -> 0 | N125: 0 | O125: =K125+L125+M125+N125 -> 4335959.1 | P125: =S124 -> 30721070 | Q125: =P125*B3Ret/12 -> 281609.81 | R125: =-N125 -> 0 | S125: =P125+Q125+R125 -> 31002680 | T125: =J125+O125+S125 -> 41889065
A126: 125 | B126: =ROUNDUP(A126/12,0) -> 11 | C126: =Age+B126-1 -> 72 | D126: =MonthlyExp*(1+Inflation)^(B126-1) -> 98357.568 | E126: =J125 -> 6550425.5 | F126: =E126*B1Ret/12 -> 38210.815 | G126: =D126 -> 98357.568 | H126: 0 | I126: =H126 -> 0 | J126: =E126+F126-G126+I126 -> 6490278.7 | K126: =O125 -> 4335959.1 | L126: =K126*B2Ret/12 -> 32519.693 | M126: =-I126 -> 0 | N126: 0 | O126: =K126+L126+M126+N126 -> 4368478.8 | P126: =S125 -> 31002680 | Q126: =P126*B3Ret/12 -> 284191.23 | R126: =-N126 -> 0 | S126: =P126+Q126+R126 -> 31286871 | T126: =J126+O126+S126 -> 42145629
A127: 126 | B127: =ROUNDUP(A127/12,0) -> 11 | C127: =Age+B127-1 -> 72 | D127: =MonthlyExp*(1+Inflation)^(B127-1) -> 98357.568 | E127: =J126 -> 6490278.7 | F127: =E127*B1Ret/12 -> 37859.959 | G127: =D127 -> 98357.568 | H127: 0 | I127: =H127 -> 0 | J127: =E127+F127-G127+I127 -> 6429781.1 | K127: =O126 -> 4368478.8 | L127: =K127*B2Ret/12 -> 32763.591 | M127: =-I127 -> 0 | N127: 0 | O127: =K127+L127+M127+N127 -> 4401242.4 | P127: =S126 -> 31286871 | Q127: =P127*B3Ret/12 -> 286796.32 | R127: =-N127 -> 0 | S127: =P127+Q127+R127 -> 31573668 | T127: =J127+O127+S127 -> 42404691
A128: 127 | B128: =ROUNDUP(A128/12,0) -> 11 | C128: =Age+B128-1 -> 72 | D128: =MonthlyExp*(1+Inflation)^(B128-1) -> 98357.568 | E128: =J127 -> 6429781.1 | F128: =E128*B1Ret/12 -> 37507.056 | G128: =D128 -> 98357.568 | H128: 0 | I128: =H128 -> 0 | J128: =E128+F128-G128+I128 -> 6368930.6 | K128: =O127 -> 4401242.4 | L128: =K128*B2Ret/12 -> 33009.318 | M128: =-I128 -> 0 | N128: 0 | O128: =K128+L128+M128+N128 -> 4434251.7 | P128: =S127 -> 31573668 | Q128: =P128*B3Ret/12 -> 289425.29 | R128: =-N128 -> 0 | S128: =P128+Q128+R128 -> 31863093 | T128: =J128+O128+S128 -> 42666275
A129: 128 | B129: =ROUNDUP(A129/12,0) -> 11 | C129: =Age+B129-1 -> 72 | D129: =MonthlyExp*(1+Inflation)^(B129-1) -> 98357.568 | E129: =J128 -> 6368930.6 | F129: =E129*B1Ret/12 -> 37152.095 | G129: =D129 -> 98357.568 | H129: 0 | I129: =H129 -> 0 | J129: =E129+F129-G129+I129 -> 6307725.1 | K129: =O128 -> 4434251.7 | L129: =K129*B2Ret/12 -> 33256.888 | M129: =-I129 -> 0 | N129: 0 | O129: =K129+L129+M129+N129 -> 4467508.6 | P129: =S128 -> 31863093 | Q129: =P129*B3Ret/12 -> 292078.35 | R129: =-N129 -> 0 | S129: =P129+Q129+R129 -> 32155171 | T129: =J129+O129+S129 -> 42930405
A130: 129 | B130: =ROUNDUP(A130/12,0) -> 11 | C130: =Age+B130-1 -> 72 | D130: =MonthlyExp*(1+Inflation)^(B130-1) -> 98357.568 | E130: =J129 -> 6307725.1 | F130: =E130*B1Ret/12 -> 36795.063 | G130: =D130 -> 98357.568 | H130: 0 | I130: =H130 -> 0 | J130: =E130+F130-G130+I130 -> 6246162.6 | K130: =O129 -> 4467508.6 | L130: =K130*B2Ret/12 -> 33506.315 | M130: =-I130 -> 0 | N130: 0 | O130: =K130+L130+M130+N130 -> 4501014.9 | P130: =S129 -> 32155171 | Q130: =P130*B3Ret/12 -> 294755.74 | R130: =-N130 -> 0 | S130: =P130+Q130+R130 -> 32449927 | T130: =J130+O130+S130 -> 43197105
A131: 130 | B131: =ROUNDUP(A131/12,0) -> 11 | C131: =Age+B131-1 -> 72 | D131: =MonthlyExp*(1+Inflation)^(B131-1) -> 98357.568 | E131: =J130 -> 6246162.6 | F131: =E131*B1Ret/12 -> 36435.949 | G131: =D131 -> 98357.568 | H131: 0 | I131: =H131 -> 0 | J131: =E131+F131-G131+I131 -> 6184241 | K131: =O130 -> 4501014.9 | L131: =K131*B2Ret/12 -> 33757.612 | M131: =-I131 -> 0 | N131: 0 | O131: =K131+L131+M131+N131 -> 4534772.5 | P131: =S130 -> 32449927 | Q131: =P131*B3Ret/12 -> 297457.66 | R131: =-N131 -> 0 | S131: =P131+Q131+R131 -> 32747385 | T131: =J131+O131+S131 -> 43466398
...

Sheet Annual Summary
A1: Year | B1: Age | C1: Opening Total Corpus | D1: Annual Withdrawal (inflation-adjusted) | E1: Avg Monthly Income that Year | F1: Investment Return (the year) | G1: Bucket 1 Closing | H1: Bucket 2 Closing | I1: Bucket 3 Closing | J1: Closing Total Corpus | K1: Withdrawal Rate (of Opening Corpus) | L1: Health Status
A2: 1 | B2: =Age+A2-1 -> 62 | C2: =Corpus -> 20000000 | D2: =SUMIFS('Monthly Engine'!$D:$D,'Monthly Engine'!$B:$B,A2) -> 600000 | E2: =D2/12 -> 50000 | F2: =J2-C2+D2 -> 2011077.6 | G2: ='Monthly Engine'!J13 -> 2597241 | H2: ='Monthly Engine'!O13 -> 7656648.3 | I2: ='Monthly Engine'!S13 -> 11157188 | J2: =G2+H2+I2 -> 21411078 | K2: =D2/C2 -> 0.03 | L2: =IF(K2<=GreenBand,"GREEN",IF(K2<=YellowBand,"YELLOW","RED")) -> GREEN
A3: 2 | B3: =Age+A3-1 -> 63 | C3: =J2 -> 21411078 | D3: =SUMIFS('Monthly Engine'!$D:$D,'Monthly Engine'!$B:$B,A3) -> 642000 | E3: =D3/12 -> 53500 | F3: =J3-C3+D3 -> 2176094.7 | G3: ='Monthly Engine'!J25 -> 2121992.4 | H3: ='Monthly Engine'!O25 -> 8374894.7 | I3: ='Monthly Engine'!S25 -> 12448285 | J3: =G3+H3+I3 -> 22945172 | K3: =D3/C3 -> 0.029984479 | L3: =IF(K3<=GreenBand,"GREEN",IF(K3<=YellowBand,"YELLOW","RED")) -> GREEN
A4: 3 | B4: =Age+A4-1 -> 64 | C4: =J3 -> 22945172 | D4: =SUMIFS('Monthly Engine'!$D:$D,'Monthly Engine'!$B:$B,A4) -> 686940 | E4: =D4/12 -> 57245 | F4: =J4-C4+D4 -> 2357049.4 | G4: ='Monthly Engine'!J37 -> 1565977.9 | H4: ='Monthly Engine'!O37 -> 9160517.6 | I4: ='Monthly Engine'!S37 -> 13888786 | J4: =G4+H4+I4 -> 24615282 | K4: =D4/C4 -> 0.029938324 | L4: =IF(K4<=GreenBand,"GREEN",IF(K4<=YellowBand,"YELLOW","RED")) -> GREEN
A5: 4 | B5: =Age+A5-1 -> 65 | C5: =J4 -> 24615282 | D5: =SUMIFS('Monthly Engine'!$D:$D,'Monthly Engine'!$B:$B,A5) -> 735025.8 | E5: =D5/12 -> 61252.15 | F5: =J5-C5+D5 -> 2555671.9 | G5: ='Monthly Engine'!J49 -> 920110.06 | H5: ='Monthly Engine'!O49 -> 10019837 | I5: ='Monthly Engine'!S49 -> 15495980 | J5: =G5+H5+I5 -> 26435928 | K5: =D5/C5 -> 0.029860548 | L5: =IF(K5<=GreenBand,"GREEN",IF(K5<=YellowBand,"YELLOW","RED")) -> GREEN
A6: 5 | B6: =Age+A6-1 -> 66 | C6: =J5 -> 26435928 | D6: =SUMIFS('Monthly Engine'!$D:$D,'Monthly Engine'!$B:$B,A6) -> 786477.61 | E6: =D6/12 -> 65539.8 | F6: =J6-C6+D6 -> 2773891.6 | G6: ='Monthly Engine'!J61 -> 4839425.4 | H6: ='Monthly Engine'!O61 -> 6294759.1 | I6: ='Monthly Engine'!S61 -> 17289157 | J6: =G6+H6+I6 -> 28423342 | K6: =D6/C6 -> 0.029750331 | L6: =IF(K6<=GreenBand,"GREEN",IF(K6<=YellowBand,"YELLOW","RED")) -> GREEN
A7: 6 | B7: =Age+A7-1 -> 67 | C7: =J6 -> 28423342 | D7: =SUMIFS('Monthly Engine'!$D:$D,'Monthly Engine'!$B:$B,A7) -> 841531.04 | E7: =D7/12 -> 70127.587 | F7: =J7-C7+D7 -> 2913484.4 | G7: ='Monthly Engine'!J73 -> 4320205.7 | H7: ='Monthly Engine'!O73 -> 6885251 | I7: ='Monthly Engine'!S73 -> 19289838 | J7: =G7+H7+I7 -> 30495295 | K7: =D7/C7 -> 0.029607041 | L7: =IF(K7<=GreenBand,"GREEN",IF(K7<=YellowBand,"YELLOW","RED")) -> GREEN
A8: 7 | B8: =Age+A8-1 -> 68 | C8: =J7 -> 30495295 | D8: =SUMIFS('Monthly Engine'!$D:$D,'Monthly Engine'!$B:$B,A8) -> 900438.21 | E8: =D8/12 -> 75036.518 | F8: =J8-C8+D8 -> 3160931.5 | G8: ='Monthly Engine'!J85 -> 3702617.3 | H8: ='Monthly Engine'!O85 -> 7531135 | I8: ='Monthly Engine'!S85 -> 21522036 | J8: =G8+H8+I8 -> 32755788 | K8: =D8/C8 -> 0.029527119 | L8: =IF(K8<=GreenBand,"GREEN",IF(K8<=YellowBand,"YELLOW","RED")) -> GREEN
A9: 8 | B9: =Age+A9-1 -> 69 | C9: =J8 -> 32755788 | D9: =SUMIFS('Monthly Engine'!$D:$D,'Monthly Engine'!$B:$B,A9) -> 963468.89 | E9: =D9/12 -> 80289.074 | F9: =J9-C9+D9 -> 3433119.6 | G9: ='Monthly Engine'!J97 -> 2975290.6 | H9: ='Monthly Engine'!O97 -> 8237607.4 | I9: ='Monthly Engine'!S97 -> 24012541 | J9: =G9+H9+I9 -> 35225439 | K9: =D9/C9 -> 0.029413699 | L9: =IF(K9<=GreenBand,"GREEN",IF(K9<=YellowBand,"YELLOW","RED")) -> GREEN
A10: 9 | B10: =Age+A10-1 -> 70 | C10: =J9 -> 35225439 | D10: =SUMIFS('Monthly Engine'!$D:$D,'Monthly Engine'!$B:$B,A10) -> 1030911.7 | E10: =D10/12 -> 85909.309 | F10: =J10-C10+D10 -> 3732805 | G10: ='Monthly Engine'!J109 -> 2125736.2 | H10: ='Monthly Engine'!O109 -> 9010351.8 | I10: ='Monthly Engine'!S109 -> 26791244 | J10: =G10+H10+I10 -> 37927332 | K10: =D10/C10 -> 0.029266114 | L10: =IF(K10<=GreenBand,"GREEN",IF(K10<=YellowBand,"YELLOW","RED")) -> GREEN
A11: 10 | B11: =Age+A11-1 -> 71 | C11: =J10 -> 37927332 | D11: =SUMIFS('Monthly Engine'!$D:$D,'Monthly Engine'!$B:$B,A11) -> 1103075.5 | E11: =D11/12 -> 91922.961 | F11: =J11-C11+D11 -> 4063066.8 | G11: ='Monthly Engine'!J121 -> 6787544.4 | H11: ='Monthly Engine'!O121 -> 4208283.2 | I11: ='Monthly Engine'!S121 -> 29891496 | J11: =G11+H11+I11 -> 40887324 | K11: =D11/C11 -> 0.029083921 | L11: =IF(K11<=GreenBand,"GREEN",IF(K11<=YellowBand,"YELLOW","RED")) -> GREEN
A12: 11 | B12: =Age+A12-1 -> 72 | C12: =J11 -> 40887324 | D12: =SUMIFS('Monthly Engine'!$D:$D,'Monthly Engine'!$B:$B,A12) -> 1180290.8 | E12: =D12/12 -> 98357.568 | F12: =J12-C12+D12 -> 4305833.5 | G12: ='Monthly Engine'!J133 -> 6059312 | H12: ='Monthly Engine'!O133 -> 4603049.2 | I12: ='Monthly Engine'!S133 -> 33350505 | J12: =G12+H12+I12 -> 44012866 | K12: =D12/C12 -> 0.028866913 | L12: =IF(K12<=GreenBand,"GREEN",IF(K12<=YellowBand,"YELLOW","RED")) -> GREEN
A13: 12 | B13: =Age+A13-1 -> 73 | C13: =J12 -> 44012866 | D13: =SUMIFS('Monthly Engine'!$D:$D,'Monthly Engine'!$B:$B,A13) -> 1262911.2 | E13: =D13/12 -> 105242.6 | F13: =J13-C13+D13 -> 4687790.9 | G13: ='Monthly Engine'!J145 -> 5193112.3 | H13: ='Monthly Engine'!O145 -> 5034847 | I13: ='Monthly Engine'!S145 -> 37209787 | J13: =G13+H13+I13 -> 47437746 | K13: =D13/C13 -> 0.028694136 | L13: =IF(K13<=GreenBand,"GREEN",IF(K13<=YellowBand,"YELLOW","RED")) -> GREEN
A14: 13 | B14: =Age+A14-1 -> 74 | C14: =J13 -> 47437746 | D14: =SUMIFS('Monthly Engine'!$D:$D,'Monthly Engine'!$B:$B,A14) -> 1351315 | E14: =D14/12 -> 112609.58 | F14: =J14-C14+D14 -> 5109378.2 | G14: ='Monthly Engine'!J157 -> 4172999 | H14: ='Monthly Engine'!O157 -> 5507150.3 | I14: ='Monthly Engine'!S157 -> 41515660 | J14: =G14+H14+I14 -> 51195809 | K14: =D14/C14 -> 0.02848607 | L14: =IF(K14<=GreenBand,"GREEN",IF(K14<=YellowBand,"YELLOW","RED")) -> GREEN
A15: 14 | B15: =Age+A15-1 -> 75 | C15: =J14 -> 51195809 | D15: =SUMIFS('Monthly Engine'!$D:$D,'Monthly Engine'!$B:$B,A15) -> 1445907 | E15: =D15/12 -> 120492.25 | F15: =J15-C15+D15 -> 5575115.5 | G15: ='Monthly Engine'!J169 -> 2981454.9 | H15: ='Monthly Engine'!O169 -> 6023759 | I15: ='Monthly Engine'!S169 -> 46319804 | J15: =G15+H15+I15 -> 55325018 | K15: =D15/C15 -> 0.028242683 | L15: =IF(K15<=GreenBand,"GREEN",IF(K15<=YellowBand,"YELLOW","RED")) -> GREEN
A16: 15 | B16: =Age+A16-1 -> 76 | C16: =J15 -> 55325018 | D16: =SUMIFS('Monthly Engine'!$D:$D,'Monthly Engine'!$B:$B,A16) -> 1547120.5 | E16: =D16/12 -> 128926.71 | F16: =J16-C16+D16 -> 6090058.8 | G16: ='Monthly Engine'!J181 -> 9519882.2 | H16: ='Monthly Engine'!O181 -> 6588829.2 | I16: ='Monthly Engine'!S181 -> 43759245 | J16: =G16+H16+I16 -> 59867956 | K16: =D16/C16 -> 0.027964211 | L16: =IF(K16<=GreenBand,"GREEN",IF(K16<=YellowBand,"YELLOW","RED")) -> GREEN
A17: 16 | B17: =Age+A17-1 -> 77 | C17: =J16 -> 59867956 | D17: =SUMIFS('Monthly Engine'!$D:$D,'Monthly Engine'!$B:$B,A17) -> 1655418.9 | E17: =D17/12 -> 137951.58 | F17: =J17-C17+D17 -> 6315881.8 | G17: ='Monthly Engine'!J193 -> 8498498.6 | H17: ='Monthly Engine'!O193 -> 7206906.8 | I17: ='Monthly Engine'!S193 -> 48823014 | J17: =G17+H17+I17 -> 64528419 | K17: =D17/C17 -> 0.027651168 | L17: =IF(K17<=GreenBand,"GREEN",IF(K17<=YellowBand,"YELLOW","RED")) -> GREEN
A18: 17 | B18: =Age+A18-1 -> 78 | C18: =J17 -> 64528419 | D18: =SUMIFS('Monthly Engine'!$D:$D,'Monthly Engine'!$B:$B,A18) -> 1771298.2 | E18: =D18/12 -> 147608.19 | F18: =J18-C18+D18 -> 6882208.2 | G18: ='Monthly Engine'!J205 -> 7283608.7 | H18: ='Monthly Engine'!O205 -> 7882964.4 | I18: ='Monthly Engine'!S205 -> 54472756 | J18: =G18+H18+I18 -> 69639329 | K18: =D18/C18 -> 0.027449894 | L18: =IF(K18<=GreenBand,"GREEN",IF(K18<=YellowBand,"YELLOW","RED")) -> GREEN
A19: 18 | B19: =Age+A19-1 -> 79 | C19: =J18 -> 69639329 | D19: =SUMIFS('Monthly Engine'!$D:$D,'Monthly Engine'!$B:$B,A19) -> 1895289.1 | E19: =D19/12 -> 157940.76 | F19: =J19-C19+D19 -> 7507527.8 | G19: ='Monthly Engine'!J217 -> 5852847 | H19: ='Monthly Engine'!O217 -> 8622440.8 | I19: ='Monthly Engine'!S217 -> 60776280 | J19: =G19+H19+I19 -> 75251568 | K19: =D19/C19 -> 0.027215787 | L19: =IF(K19<=GreenBand,"GREEN",IF(K19<=YellowBand,"YELLOW","RED")) -> GREEN
A20: 19 | B20: =Age+A20-1 -> 80 | C20: =J19 -> 75251568 | D20: =SUMIFS('Monthly Engine'!$D:$D,'Monthly Engine'!$B:$B,A20) -> 2027959.4 | E20: =D20/12 -> 168996.61 | F20: =J20-C20+D20 -> 8198562 | G20: ='Monthly Engine'!J229 -> 4181644.8 | H20: ='Monthly Engine'!O229 -> 9431285.2 | I20: ='Monthly Engine'!S229 -> 67809240 | J20: =G20+H20+I20 -> 81422170 | K20: =D20/C20 -> 0.026949065 | L20: =IF(K20<=GreenBand,"GREEN",IF(K20<=YellowBand,"YELLOW","RED")) -> GREEN
A21: 20 | B21: =Age+A21-1 -> 81 | C21: =J20 -> 81422170 | D21: =SUMIFS('Monthly Engine'!$D:$D,'Monthly Engine'!$B:$B,A21) -> 2169916.5 | E21: =D21/12 -> 180826.38 | F21: =J21-C21+D21 -> 8962827.7 | G21: ='Monthly Engine'!J241 -> 13352127 | H21: ='Monthly Engine'!O241 -> 10316005 | I21: ='Monthly Engine'!S241 -> 64546949 | J21: =G21+H21+I21 -> 88215082 | K21: =D21/C21 -> 0.026650193 | L21: =IF(K21<=GreenBand,"GREEN",IF(K21<=YellowBand,"YELLOW","RED")) -> GREEN
A22: 21 | B22: =Age+A22-1 -> 82 | C22: =J21 -> 88215082 | D22: =SUMIFS('Monthly Engine'!$D:$D,'Monthly Engine'!$B:$B,A22) -> 2321810.7 | E22: =D22/12 -> 193484.22 | F22: =J22-C22+D22 -> 9326277.6 | G22: ='Monthly Engine'!J253 -> 11919584 | H22: ='Monthly Engine'!O253 -> 11283717 | I22: ='Monthly Engine'!S253 -> 72016247 | J22: =G22+H22+I22 -> 95219548 | K22: =D22/C22 -> 0.026319884 | L22: =IF(K22<=GreenBand,"GREEN",IF(K22<=YellowBand,"YELLOW","RED")) -> GREEN
A23: 22 | B23: =Age+A23-1 -> 83 | C23: =J22 -> 95219548 | D23: =SUMIFS('Monthly Engine'!$D:$D,'Monthly Engine'!$B:$B,A23) -> 2484337.4 | E23: =D23/12 -> 207028.12 | F23: =J23-C23+D23 -> 10172518 | G23: ='Monthly Engine'!J265 -> 10215638 | H23: ='Monthly Engine'!O265 -> 12342208 | I23: ='Monthly Engine'!S265 -> 80349884 | J23: =G23+H23+I23 -> 1.0290773e+08 | K23: =D23/C23 -> 0.026090624 | L23: =IF(K23<=GreenBand,"GREEN",IF(K23<=YellowBand,"YELLOW","RED")) -> GREEN
A24: 23 | B24: =Age+A24-1 -> 84 | C24: =J23 -> 1.0290773e+08 | D24: =SUMIFS('Monthly Engine'!$D:$D,'Monthly Engine'!$B:$B,A24) -> 2658241 | E24: =D24/12 -> 221520.09 | F24: =J24-C24+D24 -> 11107303 | G24: ='Monthly Engine'!J277 -> 8208920.6 | H24: ='Monthly Engine'!O277 -> 13499992 | I24: ='Monthly Engine'!S277 -> 89647879 | J24: =G24+H24+I24 -> 1.1135679e+08 | K24: =D24/C24 -> 0.025831306 | L24: =IF(K24<=GreenBand,"GREEN",IF(K24<=YellowBand,"YELLOW","RED")) -> GREEN
A25: 24 | B25: =Age+A25-1 -> 85 | C25: =J24 -> 1.1135679e+08 | D25: =SUMIFS('Monthly Engine'!$D:$D,'Monthly Engine'!$B:$B,A25) -> 2844317.9 | E25: =D25/12 -> 237026.49 | F25: =J25-C25+D25 -> 12140711 | G25: ='Monthly Engine'!J289 -> 5864973.1 | H25: ='Monthly Engine'!O289 -> 14766384 | I25: ='Monthly Engine'!S289 -> 1.0002183e+08 | J25: =G25+H25+I25 -> 1.2065318e+08 | K25: =D25/C25 -> 0.025542384 | L25: =IF(K25<=GreenBand,"GREEN",IF(K25<=YellowBand,"YELLOW","RED")) -> GREEN
A26: 25 | B26: =Age+A26-1 -> 86 | C26: =J25 -> 1.2065318e+08 | D26: =SUMIFS('Monthly Engine'!$D:$D,'Monthly Engine'!$B:$B,A26) -> 3043420.2 | E26: =D26/12 -> 253618.35 | F26: =J26-C26+D26 -> 13284011 | G26: ='Monthly Engine'!J301 -> 18727049 | H26: ='Monthly Engine'!O301 -> 16151573 | I26: ='Monthly Engine'!S301 -> 96015153 | J26: =G26+H26+I26 -> 1.3089377e+08 | K26: =D26/C26 -> 0.025224533 | L26: =IF(K26<=GreenBand,"GREEN",IF(K26<=YellowBand,"YELLOW","RED")) -> GREEN
A27: 26 | B27: =Age+A27-1 -> 87 | C27: =J26 -> 1.3089377e+08 | D27: =SUMIFS('Monthly Engine'!$D:$D,'Monthly Engine'!$B:$B,A27) -> 3256459.6 | E27: =D27/12 -> 271371.63 | F27: =J27-C27+D27 -> 13873134 | G27: ='Monthly Engine'!J313 -> 16717833 | H27: ='Monthly Engine'!O313 -> 17666702 | I27: ='Monthly Engine'!S313 -> 1.0712591e+08 | J27: =G27+H27+I27 -> 1.4151045e+08 | K27: =D27/C27 -> 0.024878644 | L27: =IF(K27<=GreenBand,"GREEN",IF(K27<=YellowBand,"YELLOW","RED")) -> GREEN
A28: 27 | B28: =Age+A28-1 -> 88 | C28: =J27 -> 1.4151045e+08 | D28: =SUMIFS('Monthly Engine'!$D:$D,'Monthly Engine'!$B:$B,A28) -> 3484411.8 | E28: =D28/12 -> 290367.65 | F28: =J28-C28+D28 -> 15148284 | G28: ='Monthly Engine'!J325 -> 14327961 | H28: ='Monthly Engine'!O325 -> 19323960 | I28: ='Monthly Engine'!S325 -> 1.195224e+08 | J28: =G28+H28+I28 -> 1.5317432e+08 | K28: =D28/C28 -> 0.024623 | L28: =IF(K28<=GreenBand,"GREEN",IF(K28<=YellowBand,"YELLOW","RED")) -> GREEN
A29: 28 | B29: =Age+A29-1 -> 89 | C29: =J28 -> 1.5317432e+08 | D29: =SUMIFS('Monthly Engine'!$D:$D,'Monthly Engine'!$B:$B,A29) -> 3728320.6 | E29: =D29/12 -> 310693.38 | F29: =J29-C29+D29 -> 16557510 | G29: ='Monthly Engine'!J337 -> 11513436 | H29: ='Monthly Engine'!O337 -> 21136681 | I29: ='Monthly Engine'!S337 -> 1.3335339e+08 | J29: =G29+H29+I29 -> 1.6600351e+08 | K29: =D29/C29 -> 0.024340376 | L29: =IF(K29<=GreenBand,"GREEN",IF(K29<=YellowBand,"YELLOW","RED")) -> GREEN
A30: 29 | B30: =Age+A30-1 -> 90 | C30: =J29 -> 1.6600351e+08 | D30: =SUMIFS('Monthly Engine'!$D:$D,'Monthly Engine'!$B:$B,A30) -> 3989303 | E30: =D30/12 -> 332441.92 | F30: =J30-C30+D30 -> 18116061 | G30: ='Monthly Engine'!J349 -> 8225928.2 | H30: ='Monthly Engine'!O349 -> 23119448 | I30: ='Monthly Engine'!S349 -> 1.4878489e+08 | J30: =G30+H30+I30 -> 1.8013027e+08 | K30: =D30/C30 -> 0.024031438 | L30: =IF(K30<=GreenBand,"GREEN",IF(K30<=YellowBand,"YELLOW","RED")) -> GREEN
A31: 30 | B31: =Age+A31-1 -> 91 | C31: =J30 -> 1.8013027e+08 | D31: =SUMIFS('Monthly Engine'!$D:$D,'Monthly Engine'!$B:$B,A31) -> 4268554.2 | E31: =D31/12 -> 355712.85 | F31: =J31-C31+D31 -> 19840984 | G31: ='Monthly Engine'!J361 -> 4412379.4 | H31: ='Monthly Engine'!O361 -> 25288211 | I31: ='Monthly Engine'!S361 -> 1.6600211e+08 | J31: =G31+H31+I31 -> 1.957027e+08 | K31: =D31/C31 -> 0.02369704 | L31: =IF(K31<=GreenBand,"GREEN",IF(K31<=YellowBand,"YELLOW","RED")) -> GREEN
A33: Note: Health Status compares each year's Withdrawal Rate to the SWR bands set in Assumptions (green ≤ 4%, yellow ≤ 6%, red above).

Sheet Scenario Analysis
A1: SCENARIO ANALYSIS — Worst / Expected / Best Case (simplified blended-portfolio view)
B3: Note: This sheet uses ONE blended portfolio return (weighted avg of the 3 buckets) applied annually — a simplified approximation for quick comparison. The detailed, accurate model is the 3-bucket 'Monthly Engine' + 'Annual Summary'.
B5: Blended Portfolio Return (Expected) | C5: =B1Pct*B1Ret+B2Pct*B2Ret+B3Pct*B3Ret -> 0.097
A7: Year | B7: Age | C7: Weak Case Closing Corpus | D7: Weak Case Annual Withdrawal | E7: Expected Case Closing Corpus | F7: Expected Case Annual Withdrawal | G7: Best Case Closing Corpus | H7: Best Case Annual Withdrawal
A8: 1 | B8: =Age+A8-1 -> 62 | C8: =(Corpus-D8)*(1+$C$5+Assumptions!$C$25) -> 20893800 | D8: =MonthlyExp*12*(1+Inflation)^(A8-1) -> 600000 | E8: =(Corpus-F8)*(1+$C$5+Assumptions!$C$26) -> 21281800 | F8: =MonthlyExp*12*(1+Inflation)^(A8-1) -> 600000 | G8: =(Corpus-H8)*(1+$C$5+Assumptions!$C$27) -> 21669800 | H8: =MonthlyExp*12*(1+Inflation)^(A8-1) -> 600000
A9: 2 | B9: =Age+A9-1 -> 63 | C9: =(C8-D9)*(1+$C$5+Assumptions!$C$25) -> 21811189 | D9: =MonthlyExp*12*(1+Inflation)^(A9-1) -> 642000 | E9: =(E8-F9)*(1+$C$5+Assumptions!$C$26) -> 22641861 | F9: =MonthlyExp*12*(1+Inflation)^(A9-1) -> 642000 | G9: =(G8-H9)*(1+$C$5+Assumptions!$C$27) -> 23488053 | H9: =MonthlyExp*12*(1+Inflation)^(A9-1) -> 642000
A10: 3 | B10: =Age+A10-1 -> 64 | C10: =(C9-D10)*(1+$C$5+Assumptions!$C$25) -> 22750816 | D10: =MonthlyExp*12*(1+Inflation)^(A10-1) -> 686940 | E10: =(E9-F10)*(1+$C$5+Assumptions!$C$26) -> 24084548 | F10: =MonthlyExp*12*(1+Inflation)^(A10-1) -> 686940 | G10: =(G9-H10)*(1+$C$5+Assumptions!$C$27) -> 25468843 | H10: =MonthlyExp*12*(1+Inflation)^(A10-1) -> 686940
A11: 4 | B11: =Age+A11-1 -> 65 | C11: =(C10-D11)*(1+$C$5+Assumptions!$C$25) -> 23711006 | D11: =MonthlyExp*12*(1+Inflation)^(A11-1) -> 735025.8 | E11: =(E10-F11)*(1+$C$5+Assumptions!$C$26) -> 25614426 | F11: =MonthlyExp*12*(1+Inflation)^(A11-1) -> 735025.8 | G11: =(G10-H11)*(1+$C$5+Assumptions!$C$27) -> 27627674 | H11: =MonthlyExp*12*(1+Inflation)^(A11-1) -> 735025.8
A12: 5 | B12: =Age+A12-1 -> 66 | C12: =(C11-D12)*(1+$C$5+Assumptions!$C$25) -> 24689717 | D12: =MonthlyExp*12*(1+Inflation)^(A12-1) -> 786477.61 | E12: =(E11-F12)*(1+$C$5+Assumptions!$C$26) -> 27236259 | F12: =MonthlyExp*12*(1+Inflation)^(A12-1) -> 786477.61 | G12: =(G11-H12)*(1+$C$5+Assumptions!$C$27) -> 29981616 | H12: =MonthlyExp*12*(1+Inflation)^(A12-1) -> 786477.61
A13: 6 | B13: =Age+A13-1 -> 67 | C13: =(C12-D13)*(1+$C$5+Assumptions!$C$25) -> 25684496 | D13: =MonthlyExp*12*(1+Inflation)^(A13-1) -> 841531.04 | E13: =(E12-F13)*(1+$C$5+Assumptions!$C$26) -> 28955017 | F13: =MonthlyExp*12*(1+Inflation)^(A13-1) -> 841531.04 | G13: =(G12-H13)*(1+$C$5+Assumptions!$C$27) -> 32549475 | H13: =MonthlyExp*12*(1+Inflation)^(A13-1) -> 841531.04
A14: 7 | B14: =Age+A14-1 -> 68 | C14: =(C13-D14)*(1+$C$5+Assumptions!$C$25) -> 26692430 | D14: =MonthlyExp*12*(1+Inflation)^(A14-1) -> 900438.21 | E14: =(E13-F14)*(1+$C$5+Assumptions!$C$26) -> 30775873 | F14: =MonthlyExp*12*(1+Inflation)^(A14-1) -> 900438.21 | G14: =(G13-H14)*(1+$C$5+Assumptions!$C$27) -> 35351974 | H14: =MonthlyExp*12*(1+Inflation)^(A14-1) -> 900438.21
A15: 8 | B15: =Age+A15-1 -> 69 | C15: =(C14-D15)*(1+$C$5+Assumptions!$C$25) -> 27710091 | D15: =MonthlyExp*12*(1+Inflation)^(A15-1) -> 963468.89 | E15: =(E14-F15)*(1+$C$5+Assumptions!$C$26) -> 32704207 | F15: =MonthlyExp*12*(1+Inflation)^(A15-1) -> 963468.89 | G15: =(G14-H15)*(1+$C$5+Assumptions!$C$27) -> 38411960 | H15: =MonthlyExp*12*(1+Inflation)^(A15-1) -> 963468.89
A16: 9 | B16: =Age+A16-1 -> 70 | C16: =(C15-D16)*(1+$C$5+Assumptions!$C$25) -> 28733477 | D16: =MonthlyExp*12*(1+Inflation)^(A16-1) -> 1030911.7 | E16: =(E15-F16)*(1+$C$5+Assumptions!$C$26) -> 34745605 | F16: =MonthlyExp*12*(1+Inflation)^(A16-1) -> 1030911.7 | G16: =(G15-H16)*(1+$C$5+Assumptions!$C$27) -> 41754631 | H16: =MonthlyExp*12*(1+Inflation)^(A16-1) -> 1030911.7
A17: 10 | B17: =Age+A17-1 -> 71 | C17: =(C16-D17)*(1+$C$5+Assumptions!$C$25) -> 29757942 | D17: =MonthlyExp*12*(1+Inflation)^(A17-1) -> 1103075.5 | E17: =(E16-F17)*(1+$C$5+Assumptions!$C$26) -> 36905855 | F17: =MonthlyExp*12*(1+Inflation)^(A17-1) -> 1103075.5 | G17: =(G16-H17)*(1+$C$5+Assumptions!$C$27) -> 45407787 | H17: =MonthlyExp*12*(1+Inflation)^(A17-1) -> 1103075.5
A18: 11 | B18: =Age+A18-1 -> 72 | C18: =(C17-D18)*(1+$C$5+Assumptions!$C$25) -> 30778130 | D18: =MonthlyExp*12*(1+Inflation)^(A18-1) -> 1180290.8 | E18: =(E17-F18)*(1+$C$5+Assumptions!$C$26) -> 39190943 | F18: =MonthlyExp*12*(1+Inflation)^(A18-1) -> 1180290.8 | G18: =(G17-H18)*(1+$C$5+Assumptions!$C$27) -> 49402114 | H18: =MonthlyExp*12*(1+Inflation)^(A18-1) -> 1180290.8
A19: 12 | B19: =Age+A19-1 -> 73 | C19: =(C18-D19)*(1+$C$5+Assumptions!$C$25) -> 31787891 | D19: =MonthlyExp*12*(1+Inflation)^(A19-1) -> 1262911.2 | E19: =(E18-F19)*(1+$C$5+Assumptions!$C$26) -> 41607051 | F19: =MonthlyExp*12*(1+Inflation)^(A19-1) -> 1262911.2 | G19: =(G18-H19)*(1+$C$5+Assumptions!$C$27) -> 53771489 | H19: =MonthlyExp*12*(1+Inflation)^(A19-1) -> 1262911.2
A20: 13 | B20: =Age+A20-1 -> 74 | C20: =(C19-D20)*(1+$C$5+Assumptions!$C$25) -> 32780192 | D20: =MonthlyExp*12*(1+Inflation)^(A20-1) -> 1351315 | E20: =(E19-F20)*(1+$C$5+Assumptions!$C$26) -> 44160543 | F20: =MonthlyExp*12*(1+Inflation)^(A20-1) -> 1351315 | G20: =(G19-H20)*(1+$C$5+Assumptions!$C$27) -> 58553335 | H20: =MonthlyExp*12*(1+Inflation)^(A20-1) -> 1351315
... A37: 30 | B37: =Age+A37-1 -> 91 | C37: =(C36-D37)*(1+$C$5+Assumptions!$C$25) -> 33305257 | D37: =MonthlyExp*12*(1+Inflation)^(A37-1) -> 4268554.2 | E37: =(E36-F37)*(1+$C$5+Assumptions!$C$26) -> 1.1518933e+08 | F37: =MonthlyExp*12*(1+Inflation)^(A37-1) -> 4268554.2 | G37: =(G36-H37)*(1+$C$5+Assumptions!$C$27) -> 2.6723376e+08 | H37: =MonthlyExp*12*(1+Inflation)^(A37-1) -> 4268554.2
B39: Ending Corpus after 30 Years: | C39: =C37 -> 33305257 | E39: =E37 -> 1.1518933e+08 | G39: =G37 -> 2.6723376e+08
B40: Corpus Lasts Full 30 Years? | C40: =IF(MIN(C8:C37)>0,"YES","NO") -> YES | E40: =IF(MIN(E8:E37)>0,"YES","NO") -> YES | G40: =IF(MIN(G8:G37)>0,"YES","NO") -> YES

Sheet Monte Carlo
A1: MONTE CARLO SIMULATION — Probability Analysis (40 random trials, press F9 to resample)
B3: Each trial draws a random annual portfolio return every year (Normal distribution, mean = blended expected return, std. dev. = blended volatility from Assumptions) and applies it to the same withdrawal schedule as the Expected Case. Corpus is floored at ₹0 (cannot go negative).
B6: Blended Expected Return | C6: =B1Pct*B1Ret+B2Pct*B2Ret+B3Pct*B3Ret -> 0.097 | D6: Blended Volatility (std dev, approx.) | E6: =SQRT((B1Pct*Assumptions!$C$30)^2+(B2Pct*Assumptions!$C$31)^2+(B3Pct*Assumptions!$C$32)^2) -> 0.081905433
A8: Trial # | B8: Year 0 | C8: Yr 1 | D8: Yr 2 | E8: Yr 3 | F8: Yr 4 | G8: Yr 5 | H8: Yr 6 | I8: Yr 7 | J8: Yr 8 | K8: Yr 9 | L8: Yr 10 | M8: Yr 11 | N8: Yr 12 | O8: Yr 13 | P8: Yr 14 | Q8: Yr 15 | R8: Yr 16 | S8: Yr 17 | T8: Yr 18 | U8: Yr 19 | V8: Yr 20 | W8: Yr 21 | X8: Yr 22 | Y8: Yr 23 | Z8: Yr 24 | AA8: Yr 25 | AB8: Yr 26 | AC8: Yr 27 | AD8: Yr 28 | AE8: Yr 29 | AF8: Yr 30
A9: 1 | B9: =Corpus -> 20000000 | C9: =MAX(B9*(1+NORMINV(RAND(),$C$6,$E$6))-MonthlyExp*12*(1+Inflation)^(1-1),0) -> 21042407 | D9: =MAX(C9*(1+NORMINV(RAND(),$C$6,$E$6))-MonthlyExp*12*(1+Inflation)^(2-1),0) -> 21464807 | E9: =MAX(D9*(1+NORMINV(RAND(),$C$6,$E$6))-MonthlyExp*12*(1+Inflation)^(3-1),0) -> 23123505 | F9: =MAX(E9*(1+NORMINV(RAND(),$C$6,$E$6))-MonthlyExp*12*(1+Inflation)^(4-1),0) -> 23335189 | G9: =MAX(F9*(1+NORMINV(RAND(),$C$6,$E$6))-MonthlyExp*12*(1+Inflation)^(5-1),0) -> 21680300 | H9: =MAX(G9*(1+NORMINV(RAND(),$C$6,$E$6))-MonthlyExp*12*(1+Inflation)^(6-1),0) -> 23613216 | I9: =MAX(H9*(1+NORMINV(RAND(),$C$6,$E$6))-MonthlyExp*12*(1+Inflation)^(7-1),0) -> 25001599 | J9: =MAX(I9*(1+NORMINV(RAND(),$C$6,$E$6))-MonthlyExp*12*(1+Inflation)^(8-1),0) -> 28027599 | K9: =MAX(J9*(1+NORMINV(RAND(),$C$6,$E$6))-MonthlyExp*12*(1+Inflation)^(9-1),0) -> 31190971 | L9: =MAX(K9*(1+NORMINV(RAND(),$C$6,$E$6))-MonthlyExp*12*(1+Inflation)^(10-1),0) -> 32500616 | M9: =MAX(L9*(1+NORMINV(RAND(),$C$6,$E$6))-MonthlyExp*12*(1+Inflation)^(11-1),0) -> 35565178 | N9: =MAX(M9*(1+NORMINV(RAND(),$C$6,$E$6))-MonthlyExp*12*(1+Inflation)^(12-1),0) -> 35709514 | O9: =MAX(N9*(1+NORMINV(RAND(),$C$6,$E$6))-MonthlyExp*12*(1+Inflation)^(13-1),0) -> 29383458 | P9: =MAX(O9*(1+NORMINV(RAND(),$C$6,$E$6))-MonthlyExp*12*(1+Inflation)^(14-1),0) -> 30046338 | Q9: =MAX(P9*(1+NORMINV(RAND(),$C$6,$E$6))-MonthlyExp*12*(1+Inflation)^(15-1),0) -> 29765285 | R9: =MAX(Q9*(1+NORMINV(RAND(),$C$6,$E$6))-MonthlyExp*12*(1+Inflation)^(16-1),0) -> 34342416 | S9: =MAX(R9*(1+NORMINV(RAND(),$C$6,$E$6))-MonthlyExp*12*(1+Inflation)^(17-1),0) -> 35589235 | T9: =MAX(S9*(1+NORMINV(RAND(),$C$6,$E$6))-MonthlyExp*12*(1+Inflation)^(18-1),0) -> 36358974 | U9: =MAX(T9*(1+NORMINV(RAND(),$C$6,$E$6))-MonthlyExp*12*(1+Inflation)^(19-1),0) -> 41879900 | V9: =MAX(U9*(1+NORMINV(RAND(),$C$6,$E$6))-MonthlyExp*12*(1+Inflation)^(20-1),0) -> 38797759 | W9: =MAX(V9*(1+NORMINV(RAND(),$C$6,$E$6))-MonthlyExp*12*(1+Inflation)^(21-1),0) -> 42226484 | X9: =MAX(W9*(1+NORMINV(RAND(),$C$6,$E$6))-MonthlyExp*12*(1+Inflation)^(22-1),0) -> 46148197 | Y9: =MAX(X9*(1+NORMINV(RAND(),$C$6,$E$6))-MonthlyExp*12*(1+Inflation)^(23-1),0) -> 42465586 | Z9: =MAX(Y9*(1+NORMINV(RAND(),$C$6,$E$6))-MonthlyExp*12*(1+Inflation)^(24-1),0) -> 39540427 | AA9: =MAX(Z9*(1+NORMINV(RAND(),$C$6,$E$6))-MonthlyExp*12*(1+Inflation)^(25-1),0) -> 43397607 | AB9: =MAX(AA9*(1+NORMINV(RAND(),$C$6,$E$6))-MonthlyExp*12*(1+Inflation)^(26-1),0) -> 51284322 | AC9: =MAX(AB9*(1+NORMINV(RAND(),$C$6,$E$6))-MonthlyExp*12*(1+Inflation)^(27-1),0) -> 48392876 | AD9: =MAX(AC9*(1+NORMINV(RAND(),$C$6,$E$6))-MonthlyExp*12*(1+Inflation)^(28-1),0) -> 49594197 | AE9: =MAX(AD9*(1+NORMINV(RAND(),$C$6,$E$6))-MonthlyExp*12*(1+Inflation)^(29-1),0) -> 58080027 | AF9: =MAX(AE9*(1+NORMINV(RAND(),$C$6,$E$6))-MonthlyExp*12*(1+Inflation)^(30-1),0) -> 55651651
A10: 2 | B10: =Corpus -> 20000000 | C10: =MAX(B10*(1+NORMINV(RAND(),$C$6,$E$6))-MonthlyExp*12*(1+Inflation)^(1-1),0) -> 21087293 | D10: =MAX(C10*(1+NORMINV(RAND(),$C$6,$E$6))-MonthlyExp*12*(1+Inflation)^(2-1),0) -> 25694380 | E10: =MAX(D10*(1+NORMINV(RAND(),$C$6,$E$6))-MonthlyExp*12*(1+Inflation)^(3-1),0) -> 26494553 | F10: =MAX(E10*(1+NORMINV(RAND(),$C$6,$E$6))-MonthlyExp*12*(1+Inflation)^(4-1),0) -> 28652704 | G10: =MAX(F10*(1+NORMINV(RAND(),$C$6,$E$6))-MonthlyExp*12*(1+Inflation)^(5-1),0) -> 29294270 | H10: =MAX(G10*(1+NORMINV(RAND(),$C$6,$E$6))-MonthlyExp*12*(1+Inflation)^(6-1),0) -> 30651537 | I10: =MAX(H10*(1+NORMINV(RAND(),$C$6,$E$6))-MonthlyExp*12*(1+Inflation)^(7-1),0) -> 30033240 | J10: =MAX(I10*(1+NORMINV(RAND(),$C$6,$E$6))-MonthlyExp*12*(1+Inflation)^(8-1),0) -> 36478639 | K10: =MAX(J10*(1+NORMINV(RAND(),$C$6,$E$6))-MonthlyExp*12*(1+Inflation)^(9-1),0) -> 37217126 | L10: =MAX(K10*(1+NORMINV(RAND(),$C$6,$E$6))-MonthlyExp*12*(1+Inflation)^(10-1),0) -> 38377530 | M10: =MAX(L10*(1+NORMINV(RAND(),$C$6,$E$6))-MonthlyExp*12*(1+Inflation)^(11-1),0) -> 35293489 | N10: =MAX(M10*(1+NORMINV(RAND(),$C$6,$E$6))-MonthlyExp*12*(1+Inflation)^(12-1),0) -> 37095333 | O10: =MAX(N10*(1+NORMINV(RAND(),$C$6,$E$6))-MonthlyExp*12*(1+Inflation)^(13-1),0) -> 42844509 | P10: =MAX(O10*(1+NORMINV(RAND(),$C$6,$E$6))-MonthlyExp*12*(1+Inflation)^(14-1),0) -> 46658766 | Q10: =MAX(P10*(1+NORMINV(RAND(),$C$6,$E$6))-MonthlyExp*12*(1+Inflation)^(15-1),0) -> 58595069 | R10: =MAX(Q10*(1+NORMINV(RAND(),$C$6,$E$6))-MonthlyExp*12*(1+Inflation)^(16-1),0) -> 64536365 | S10: =MAX(R10*(1+NORMINV(RAND(),$C$6,$E$6))-MonthlyExp*12*(1+Inflation)^(17-1),0) -> 66685779 | T10: =MAX(S10*(1+NORMINV(RAND(),$C$6,$E$6))-MonthlyExp*12*(1+Inflation)^(18-1),0) -> 69624589 | U10: =MAX(T10*(1+NORMINV(RAND(),$C$6,$E$6))-MonthlyExp*12*(1+Inflation)^(19-1),0) -> 67169342 | V10: =MAX(U10*(1+NORMINV(RAND(),$C$6,$E$6))-MonthlyExp*12*(1+Inflation)^(20-1),0) -> 49338110 | W10: =MAX(V10*(1+NORMINV(RAND(),$C$6,$E$6))-MonthlyExp*12*(1+Inflation)^(21-1),0) -> 56260847 | X10: =MAX(W10*(1+NORMINV(RAND(),$C$6,$E$6))-MonthlyExp*12*(1+Inflation)^(22-1),0) -> 62292110 | Y10: =MAX(X10*(1+NORMINV(RAND(),$C$6,$E$6))-MonthlyExp*12*(1+Inflation)^(23-1),0) -> 64451739 | Z10: =MAX(Y10*(1+NORMINV(RAND(),$C$6,$E$6))-MonthlyExp*12*(1+Inflation)^(24-1),0) -> 71553736 | AA10: =MAX(Z10*(1+NORMINV(RAND(),$C$6,$E$6))-MonthlyExp*12*(1+Inflation)^(25-1),0) -> 70061463 | AB10: =MAX(AA10*(1+NORMINV(RAND(),$C$6,$E$6))-MonthlyExp*12*(1+Inflation)^(26-1),0) -> 77794610 | AC10: =MAX(AB10*(1+NORMINV(RAND(),$C$6,$E$6))-MonthlyExp*12*(1+Inflation)^(27-1),0) -> 85398967 | AD10: =MAX(AC10*(1+NORMINV(RAND(),$C$6,$E$6))-MonthlyExp*12*(1+Inflation)^(28-1),0) -> 88695129 | AE10: =MAX(AD10*(1+NORMINV(RAND(),$C$6,$E$6))-MonthlyExp*12*(1+Inflation)^(29-1),0) -> 93860328 | AF10: =MAX(AE10*(1+NORMINV(RAND(),$C$6,$E$6))-MonthlyExp*12*(1+Inflation)^(30-1),0) -> 1.1432185e+08
A11: 3 | B11: =Corpus -> 20000000 | C11: =MAX(B11*(1+NORMINV(RAND(),$C$6,$E$6))-MonthlyExp*12*(1+Inflation)^(1-1),0) -> 23987539 | D11: =MAX(C11*(1+NORMINV(RAND(),$C$6,$E$6))-MonthlyExp*12*(1+Inflation)^(2-1),0) -> 26762291 | E11: =MAX(D11*(1+NORMINV(RAND(),$C$6,$E$6))-MonthlyExp*12*(1+Inflation)^(3-1),0) -> 28662027 | F11: =MAX(E11*(1+NORMINV(RAND(),$C$6,$E$6))-MonthlyExp*12*(1+Inflation)^(4-1),0) -> 31289607 | G11: =MAX(F11*(1+NORMINV(RAND(),$C$6,$E$6))-MonthlyExp*12*(1+Inflation)^(5-1),0) -> 34119792 | H11: =MAX(G11*(1+NORMINV(RAND(),$C$6,$E$6))-MonthlyExp*12*(1+Inflation)^(6-1),0) -> 36702352 | I11: =MAX(H11*(1+NORMINV(RAND(),$C$6,$E$6))-MonthlyExp*12*(1+Inflation)^(7-1),0) -> 41825068 | J11: =MAX(I11*(1+NORMINV(RAND(),$C$6,$E$6))-MonthlyExp*12*(1+Inflation)^(8-1),0) -> 43964298 | K11: =MAX(J11*(1+NORMINV(RAND(),$C$6,$E$6))-MonthlyExp*12*(1+Inflation)^(9-1),0) -> 50475081 | L11: =MAX(K11*(1+NORMINV(RAND(),$C$6,$E$6))-MonthlyExp*12*(1+Inflation)^(10-1),0) -> 54546040 | M11: =MAX(L11*(1+NORMINV(RAND(),$C$6,$E$6))-MonthlyExp*12*(1+Inflation)^(11-1),0) -> 60459801 | N11: =MAX(M11*(1+NORMINV(RAND(),$C$6,$E$6))-MonthlyExp*12*(1+Inflation)^(12-1),0) -> 69615160 | O11: =MAX(N11*(1+NORMINV(RAND(),$C$6,$E$6))-MonthlyExp*12*(1+Inflation)^(13-1),0) -> 79340579 | P11: =MAX(O11*(1+NORMINV(RAND(),$C$6,$E$6))-MonthlyExp*12*(1+Inflation)^(14-1),0) -> 79333424 | Q11: =MAX(P11*(1+NORMINV(RAND(),$C$6,$E$6))-MonthlyExp*12*(1+Inflation)^(15-1),0) -> 93344113 | R11: =MAX(Q11*(1+NORMINV(RAND(),$C$6,$E$6))-MonthlyExp*12*(1+Inflation)^(16-1),0) -> 1.0943407e+08 | S11: =MAX(R11*(1+NORMINV(RAND(),$C$6,$E$6))-MonthlyExp*12*(1+Inflation)^(17-1),0) -> 1.239596e+08 | T11: =MAX(S11*(1+NORMINV(RAND(),$C$6,$E$6))-MonthlyExp*12*(1+Inflation)^(18-1),0) -> 1.1541557e+08 | U11: =MAX(T11*(1+NORMINV(RAND(),$C$6,$E$6))-MonthlyExp*12*(1+Inflation)^(19-1),0) -> 1.2621285e+08 | V11: =MAX(U11*(1+NORMINV(RAND(),$C$6,$E$6))-MonthlyExp*12*(1+Inflation)^(20-1),0) -> 1.30787e+08 | W11: =MAX(V11*(1+NORMINV(RAND(),$C$6,$E$6))-MonthlyExp*12*(1+Inflation)^(21-1),0) -> 1.2551702e+08 | X11: =MAX(W11*(1+NORMINV(RAND(),$C$6,$E$6))-MonthlyExp*12*(1+Inflation)^(22-1),0) -> 1.3063681e+08 | Y11: =MAX(X11*(1+NORMINV(RAND(),$C$6,$E$6))-MonthlyExp*12*(1+Inflation)^(23-1),0) -> 1.3361503e+08 | Z11: =MAX(Y11*(1+NORMINV(RAND(),$C$6,$E$6))-MonthlyExp*12*(1+Inflation)^(24-1),0) -> 1.3975435e+08 | AA11: =MAX(Z11*(1+NORMINV(RAND(),$C$6,$E$6))-MonthlyExp*12*(1+Inflation)^(25-1),0) -> 1.4629701e+08 | AB11: =MAX(AA11*(1+NORMINV(RAND(),$C$6,$E$6))-MonthlyExp*12*(1+Inflation)^(26-1),0) -> 1.427657e+08 | AC11: =MAX(AB11*(1+NORMINV(RAND(),$C$6,$E$6))-MonthlyExp*12*(1+Inflation)^(27-1),0) -> 1.3493392e+08 | AD11: =MAX(AC11*(1+NORMINV(RAND(),$C$6,$E$6))-MonthlyExp*12*(1+Inflation)^(28-1),0) -> 1.334897e+08 | AE11: =MAX(AD11*(1+NORMINV(RAND(),$C$6,$E$6))-MonthlyExp*12*(1+Inflation)^(29-1),0) -> 1.3187251e+08 | AF11: =MAX(AE11*(1+NORMINV(RAND(),$C$6,$E$6))-MonthlyExp*12*(1+Inflation)^(30-1),0) -> 1.4400093e+08
A12: 4 | B12: =Corpus -> 20000000 | C12: =MAX(B12*(1+NORMINV(RAND(),$C$6,$E$6))-MonthlyExp*12*(1+Inflation)^(1-1),0) -> 20291985 | D12: =MAX(C12*(1+NORMINV(RAND(),$C$6,$E$6))-MonthlyExp*12*(1+Inflation)^(2-1),0) -> 23601955 | E12: =MAX(D12*(1+NORMINV(RAND(),$C$6,$E$6))-MonthlyExp*12*(1+Inflation)^(3-1),0) -> 24366722 | F12: =MAX(E12*(1+NORMINV(RAND(),$C$6,$E$6))-MonthlyExp*12*(1+Inflation)^(4-1),0) -> 27609447 | G12: =MAX(F12*(1+NORMINV(RAND(),$C$6,$E$6))-MonthlyExp*12*(1+Inflation)^(5-1),0) -> 30188770 | H12: =MAX(G12*(1+NORMINV(RAND(),$C$6,$E$6))-MonthlyExp*12*(1+Inflation)^(6-1),0) -> 29831617 | I12: =MAX(H12*(1+NORMINV(RAND(),$C$6,$E$6))-MonthlyExp*12*(1+Inflation)^(7-1),0) -> 34201786 | J12: =MAX(I12*(1+NORMINV(RAND(),$C$6,$E$6))-MonthlyExp*12*(1+Inflation)^(8-1),0) -> 33463147 | K12: =MAX(J12*(1+NORMINV(RAND(),$C$6,$E$6))-MonthlyExp*12*(1+Inflation)^(9-1),0) -> 39667618 | L12: =MAX(K12*(1+NORMINV(RAND(),$C$6,$E$6))-MonthlyExp*12*(1+Inflation)^(10-1),0) -> 39557273 | M12: =MAX(L12*(1+NORMINV(RAND(),$C$6,$E$6))-MonthlyExp*12*(1+Inflation)^(11-1),0) -> 42687474 | N12: =MAX(M12*(1+NORMINV(RAND(),$C$6,$E$6))-MonthlyExp*12*(1+Inflation)^(12-1),0) -> 44854845 | O12: =MAX(N12*(1+NORMINV(RAND(),$C$6,$E$6))-MonthlyExp*12*(1+Inflation)^(13-1),0) -> 47479851 | P12: =MAX(O12*(1+NORMINV(RAND(),$C$6,$E$6))-MonthlyExp*12*(1+Inflation)^(14-1),0) -> 48797330 | Q12: =MAX(P12*(1+NORMINV(RAND(),$C$6,$E$6))-MonthlyExp*12*(1+Inflation)^(15-1),0) -> 50563135 | R12: =MAX(Q12*(1+NORMINV(RAND(),$C$6,$E$6))-MonthlyExp*12*(1+Inflation)^(16-1),0) -> 52304848 | S12: =MAX(R12*(1+NORMINV(RAND(),$C$6,$E$6))-MonthlyExp*12*(1+Inflation)^(17-1),0) -> 52072362 | T12: =MAX(S12*(1+NORMINV(RAND(),$C$6,$E$6))-MonthlyExp*12*(1+Inflation)^(18-1),0) -> 51754605 | U12: =MAX(T12*(1+NORMINV(RAND(),$C$6,$E$6))-MonthlyExp*12*(1+Inflation)^(19-1),0) -> 55987372 | V12: =MAX(U12*(1+NORMINV(RAND(),$C$6,$E$6))-MonthlyExp*12*(1+Inflation)^(20-1),0) -> 62196057 | W12: =MAX(V12*(1+NORMINV(RAND(),$C$6,$E$6))-MonthlyExp*12*(1+Inflation)^(21-1),0) -> 64705316 | X12: =MAX(W12*(1+NORMINV(RAND(),$C$6,$E$6))-MonthlyExp*12*(1+Inflation)^(22-1),0) -> 67450803 | Y12: =MAX(X12*(1+NORMINV(RAND(),$C$6,$E$6))-MonthlyExp*12*(1+Inflation)^(23-1),0) -> 63478297 | Z12: =MAX(Y12*(1+NORMINV(RAND(),$C$6,$E$6))-MonthlyExp*12*(1+Inflation)^(24-1),0) -> 68085724 | AA12: =MAX(Z12*(1+NORMINV(RAND(),$C$6,$E$6))-MonthlyExp*12*(1+Inflation)^(25-1),0) -> 67584200 | AB12: =MAX(AA12*(1+NORMINV(RAND(),$C$6,$E$6))-MonthlyExp*12*(1+Inflation)^(26-1),0) -> 78802001 | AC12: =MAX(AB12*(1+NORMINV(RAND(),$C$6,$E$6))-MonthlyExp*12*(1+Inflation)^(27-1),0) -> 74525515 | AD12: =MAX(AC12*(1+NORMINV(RAND(),$C$6,$E$6))-MonthlyExp*12*(1+Inflation)^(28-1),0) -> 84243624 | AE12: =MAX(AD12*(1+NORMINV(RAND(),$C$6,$E$6))-MonthlyExp*12*(1+Inflation)^(29-1),0) -> 89836224 | AF12: =MAX(AE12*(1+NORMINV(RAND(),$C$6,$E$6))-MonthlyExp*12*(1+Inflation)^(30-1),0) -> 90668516
