Workbook
Name d: OFFSET([1]DATA!$M$3,,,COUNTIF([1]DATA!$M$1:$M$65536,"?*"))
Name DRIVER: 'DATA '!$AH$1:$AH$2
Name PLANT: 'DATA '!$AG$1:$AG$3

Sheet OTHER PLANT ATTN.
A1: ='RJ ATTENDENCE SHEET'!A1 -> 46204 | D1: 1 | E1: 2 | F1: 3 | G1: 4 | H1: 5 | I1: 6 | J1: 7 | K1: 8 | L1: 9 | M1: 10 | N1: 11 | O1: 12 | P1: 13 | Q1: 14 | R1: 15 | S1: 16 | T1: 17 | U1: 18 | V1: 19 | W1: 20 | X1: 21 | Y1: 22 | Z1: 23 | AA1: 24 | AB1: 25 | AC1: 26 | AD1: 27 | AE1: 28 | AF1: 29 | AG1: 30 | AH1: 31
A2: PLANT | B2: CATEGORY | C2: RAJARHAT / JALAN TRIP | D2: 1 | E2: 2 | F2: 3 | G2: 4 | H2: 5 | I2: 6 | J2: 7 | K2: 8 | L2: 9 | M2: 10 | N2: 11 | O2: 12 | P2: 13 | Q2: 14 | R2: 15 | S2: 16 | T2: 17 | U2: 18 | V2: 19 | W2: 20 | X2: 21 | Y2: 22 | Z2: 23 | AA2: 24 | AB2: 25 | AC2: 26 | AD2: 27 | AE2: 28 | AF2: 29 | AG2: 30 | AH2: 31
A3: TARATALA | B3: DRIVER | C3: MANOJ | E3: 1
A4: TARATALA | B4: DRIVER
A5: TARATALA | B5: DRIVER | C5: TAPAS | F5: 2 | G5: 2 | J5: 1
A6: TARATALA | B6: HELPER | C6: KRISH | E6: 1
A7: TARATALA | B7: HELPER | C7: KHAIRUL | G7: 1 | H7: 2 | I7: 3 | J7: 1
A8: TARATALA | B8: HELPER | C8: SAJAN
A9: TARATALA | B9: DRIVER | C9: GIASUDDIN | F9: 1 | H9: 2 | I9: 3
A10: JALAN | B10: DRIVER | C10: RAKESH | I10: 2
A11: TARATALA | B11: DRIVER | C11: ANSAR | I11: 2
A12: TARATALA | B12: DRIVER | C12: RANJIT
A13: TARATALA | B13: HELPER | C13: KAPIL | I13: 2
A14: TARATALA | B14: HELPER | C14: RINTU
A15: TARATALA | B15: HELPER | C15: RABIN
A16: JALAN | B16: HELPER | C16: MITHUN | I16: 2
A17: JALAN | B17: HELPER | C17: RAMU | I17: 1
A18: JALAN | B18: DRIVER | C18: TAPAS | I18: 1
A19: TARATALA | B19: DRIVER | C19: SANJOY
A20: TARATALA | B20: DRIVER | C20: ASIT
A21: TARATALA | B21: HELPER | C21: BIJOY
A22: TARATALA | B22: HELPER | C22: LOUL
A23: TARATALA | B23: HELPER | C23: SAMIR BARMAN
A24: TARATALA | B24: DRIVER | C24: ROBIUL
A25: TARATALA | B25: HELPER | C25: SALEK
A26: TARATALA | B26: DRIVER | C26: HASAN
A27: TARATALA | B27: HELPER | C27: ASISH
A28: TARATALA | B28: DRIVER | C28: LALJI
A29: TARATALA | B29: DRIVER | C29: TAPAS
A30: JALAN | B30: DRIVER | C30: CHORUA
... A58: TARATALA | B58: DRIVER | C58: SABIR

Sheet DATA 
C1: ='RJ ATTENDENCE SHEET'!B:B -> 0 | D1: ='RJ ATTENDENCE SHEET'!C:C -> 0 | E1: =C1 -> 0 | X1: ='OTHER PLANT ATTN.'!C:C -> 0 | AC1: SALARY | AD1: WAGES | AE1: CONTRACT | AG1: RAJARHAT | AH1: DRIVER
C2: ='RJ ATTENDENCE SHEET'!B:B -> SUB-CATEGORY | D2: ='RJ ATTENDENCE SHEET'!C:C -> NAME | E2: =C2 -> SUB-CATEGORY | F2: SALARY | I2: WAGES | M2: CONTRACT | Q2: SALARY | T2: SALARY | X2: ='OTHER PLANT ATTN.'!C:C -> RAJARHAT / JALAN TRIP | Y2: =Table1[[#This Row],[CATEGORY ]] -> #VALUE! | Z2: =Table1[[#This Row],[PLANT]] -> #VALUE! | AB2: SALARY | AC2: OFFICE | AD2: LAB | AE2: LAB | AG2: JALAN | AH2: HELPER
A3: =CONCATENATE(B3,C3,D3) -> SALARYOFFICEABED ALI | B3: =Table4[[#This Row],[CATEGORY]] -> SALARY | C3: =Table4[[#This Row],[SUB-CATEGORY]] -> OFFICE | D3: ='RJ ATTENDENCE SHEET'!C:C -> ABED ALI | E3: =C3 -> OFFICE | F3: =IFERROR(SEARCH("SALARYOFFICE",$A:$A),"") -> 1 | G3: =IFERROR(IF(F3=0,"",COUNTIF($F$3:F3,">0")),"") -> 1 | H3: =IFERROR(VLOOKUP(INDEX($A:$A,MATCH(ROW(F1),G:G,0)),$A:$D,4,0),"") -> ABED ALI | I3: =IFERROR(SEARCH("WAGES",$A:$A),"") | J3: =IFERROR(IF(I3=0,"",COUNTIF($I$3:I3,">0")),"") -> 0 | K3: =IFERROR(VLOOKUP(INDEX($A:$A,MATCH(ROW(I1),J:J,0)),$A:$D,4,0),"") -> ANISUR | L3: =IFERROR(VLOOKUP(K3,$D:$E,2,0),"") -> DRIVER | M3: =IFERROR(SEARCH("CONTRACT",$A:$A),"") | N3: =IFERROR(IF(M3=0,"",COUNTIF($M$3:M3,">0")),"") -> 0 | O3: =IFERROR(VLOOKUP(INDEX($A:$A,MATCH(ROW(M1),N:N,0)),$A:$D,4,0),"") -> AMIT BISWAS | P3: =IFERROR(VLOOKUP(O3,$D:$E,2,0),"") -> HELPER | Q3: =IFERROR(SEARCH("SALARY",$A:$A),"") -> 1 | R3: =IFERROR(IF(Q3=0,"",COUNTIF($Q$3:Q3,">0")),"") -> 1 | S3: =IFERROR(VLOOKUP(INDEX($A:$A,MATCH(ROW(Q1),R:R,0)),$A:$D,4,0),"") -> ABED ALI | T3: =IFERROR(SEARCH("OTHERS0",$A:$A),"") | U3: =IFERROR(IF(T3=0,"",COUNTIF($T$3:T3,">0")),"") -> 0 | V3: =IFERROR(VLOOKUP(INDEX($A:$A,MATCH(ROW(T1),U:U,0)),$A:$D,4,0),"") | W3: =CONCATENATE(Z3,Y3,X3) -> TARATALADRIVERMANOJ | X3: ='OTHER PLANT ATTN.'!C:C -> MANOJ | Y3: =Table1[[#This Row],[CATEGORY ]] -> DRIVER | Z3: =Table1[[#This Row],[PLANT]] -> TARATALA | AA3: =DAY(WHATSAPP!$K$4) -> 21 | AB3: WAGES | AC3: OTHERS | AD3: DRIVER | AE3: DRIVER | AG3: TARATALA
A4: =CONCATENATE(B4,C4,D4) -> SALARYOFFICEABHI MUKHERJEE | B4: =Table4[[#This Row],[CATEGORY]] -> SALARY | C4: =Table4[[#This Row],[SUB-CATEGORY]] -> OFFICE | D4: ='RJ ATTENDENCE SHEET'!C:C -> ABHI MUKHERJEE | E4: =C4 -> OFFICE | F4: =IFERROR(SEARCH("SALARYOFFICE",$A:$A),"") -> 1 | G4: =IFERROR(IF(F4=0,"",COUNTIF($F$3:F4,">0")),"") -> 2 | H4: =IFERROR(VLOOKUP(INDEX($A:$A,MATCH(ROW(F2),G:G,0)),$A:$D,4,0),"") -> ABHI MUKHERJEE | I4: =IFERROR(SEARCH("WAGES",$A:$A),"") | J4: =IFERROR(IF(I4=0,"",COUNTIF($I$3:I4,">0")),"") -> 0 | K4: =IFERROR(VLOOKUP(INDEX($A:$A,MATCH(ROW(I2),J:J,0)),$A:$D,4,0),"") -> ARMAN ALI MONDAL | L4: =IFERROR(VLOOKUP(K4,$D:$E,2,0),"") -> DRIVER | M4: =IFERROR(SEARCH("CONTRACT",$A:$A),"") | N4: =IFERROR(IF(M4=0,"",COUNTIF($M$3:M4,">0")),"") -> 0 | O4: =IFERROR(VLOOKUP(INDEX($A:$A,MATCH(ROW(M2),N:N,0)),$A:$D,4,0),"") -> JHANTU MONDAL | P4: =IFERROR(VLOOKUP(O4,$D:$E,2,0),"") -> HELPER | Q4: =IFERROR(SEARCH("SALARY",$A:$A),"") -> 1 | R4: =IFERROR(IF(Q4=0,"",COUNTIF($Q$3:Q4,">0")),"") -> 2 | S4: =IFERROR(VLOOKUP(INDEX($A:$A,MATCH(ROW(Q2),R:R,0)),$A:$D,4,0),"") -> ABHI MUKHERJEE | T4: =IFERROR(SEARCH("OTHERS0",$A:$A),"") | U4: =IFERROR(IF(T4=0,"",COUNTIF($T$3:T4,">0")),"") -> 0 | V4: =IFERROR(VLOOKUP(INDEX($A:$A,MATCH(ROW(T2),U:U,0)),$A:$D,4,0),"") | W4: =CONCATENATE(Z4,Y4,X4) -> TARATALADRIVER0 | X4: ='OTHER PLANT ATTN.'!C:C -> 0 | Y4: =Table1[[#This Row],[CATEGORY ]] -> DRIVER | Z4: =Table1[[#This Row],[PLANT]] -> TARATALA | AB4: CONTRACT | AD4: HELPER | AE4: HELPER
A5: =CONCATENATE(B5,C5,D5) -> SALARYOFFICEACHIN GUPTA | B5: =Table4[[#This Row],[CATEGORY]] -> SALARY | C5: =Table4[[#This Row],[SUB-CATEGORY]] -> OFFICE | D5: ='RJ ATTENDENCE SHEET'!C:C -> ACHIN GUPTA | E5: =C5 -> OFFICE | F5: =IFERROR(SEARCH("SALARYOFFICE",$A:$A),"") -> 1 | G5: =IFERROR(IF(F5=0,"",COUNTIF($F$3:F5,">0")),"") -> 3 | H5: =IFERROR(VLOOKUP(INDEX($A:$A,MATCH(ROW(F3),G:G,0)),$A:$D,4,0),"") -> ACHIN GUPTA | I5: =IFERROR(SEARCH("WAGES",$A:$A),"") | J5: =IFERROR(IF(I5=0,"",COUNTIF($I$3:I5,">0")),"") -> 0 | K5: =IFERROR(VLOOKUP(INDEX($A:$A,MATCH(ROW(I3),J:J,0)),$A:$D,4,0),"") -> ASUTOSH SARDAR | L5: =IFERROR(VLOOKUP(K5,$D:$E,2,0),"") -> HELPER | M5: =IFERROR(SEARCH("CONTRACT",$A:$A),"") | N5: =IFERROR(IF(M5=0,"",COUNTIF($M$3:M5,">0")),"") -> 0 | O5: =IFERROR(VLOOKUP(INDEX($A:$A,MATCH(ROW(M3),N:N,0)),$A:$D,4,0),"") -> ASHIT BISWAS | P5: =IFERROR(VLOOKUP(O5,$D:$E,2,0),"") -> DRIVER | Q5: =IFERROR(SEARCH("SALARY",$A:$A),"") -> 1 | R5: =IFERROR(IF(Q5=0,"",COUNTIF($Q$3:Q5,">0")),"") -> 3 | S5: =IFERROR(VLOOKUP(INDEX($A:$A,MATCH(ROW(Q3),R:R,0)),$A:$D,4,0),"") -> ACHIN GUPTA | T5: =IFERROR(SEARCH("OTHERS0",$A:$A),"") | U5: =IFERROR(IF(T5=0,"",COUNTIF($T$3:T5,">0")),"") -> 0 | V5: =IFERROR(VLOOKUP(INDEX($A:$A,MATCH(ROW(T3),U:U,0)),$A:$D,4,0),"") | W5: =CONCATENATE(Z5,Y5,X5) -> TARATALADRIVERTAPAS | X5: ='OTHER PLANT ATTN.'!C:C -> TAPAS | Y5: =Table1[[#This Row],[CATEGORY ]] -> DRIVER | Z5: =Table1[[#This Row],[PLANT]] -> TARATALA | AD5: HOPPER | AE5: HOPPER
A6: =CONCATENATE(B6,C6,D6) -> SALARYOFFICEAMIN YADAV | B6: =Table4[[#This Row],[CATEGORY]] -> SALARY | C6: =Table4[[#This Row],[SUB-CATEGORY]] -> OFFICE | D6: ='RJ ATTENDENCE SHEET'!C:C -> AMIN YADAV | E6: =C6 -> OFFICE | F6: =IFERROR(SEARCH("SALARYOFFICE",$A:$A),"") -> 1 | G6: =IFERROR(IF(F6=0,"",COUNTIF($F$3:F6,">0")),"") -> 4 | H6: =IFERROR(VLOOKUP(INDEX($A:$A,MATCH(ROW(F4),G:G,0)),$A:$D,4,0),"") -> AMIN YADAV | I6: =IFERROR(SEARCH("WAGES",$A:$A),"") | J6: =IFERROR(IF(I6=0,"",COUNTIF($I$3:I6,">0")),"") -> 0 | K6: =IFERROR(VLOOKUP(INDEX($A:$A,MATCH(ROW(I4),J:J,0)),$A:$D,4,0),"") -> BUDDHADEV SEAL | L6: =IFERROR(VLOOKUP(K6,$D:$E,2,0),"") -> LAB | M6: =IFERROR(SEARCH("CONTRACT",$A:$A),"") | N6: =IFERROR(IF(M6=0,"",COUNTIF($M$3:M6,">0")),"") -> 0 | O6: =IFERROR(VLOOKUP(INDEX($A:$A,MATCH(ROW(M4),N:N,0)),$A:$D,4,0),"") -> NASIB KARIKAR | P6: =IFERROR(VLOOKUP(O6,$D:$E,2,0),"") -> HELPER | Q6: =IFERROR(SEARCH("SALARY",$A:$A),"") -> 1 | R6: =IFERROR(IF(Q6=0,"",COUNTIF($Q$3:Q6,">0")),"") -> 4 | S6: =IFERROR(VLOOKUP(INDEX($A:$A,MATCH(ROW(Q4),R:R,0)),$A:$D,4,0),"") -> AMIN YADAV | T6: =IFERROR(SEARCH("OTHERS0",$A:$A),"") | U6: =IFERROR(IF(T6=0,"",COUNTIF($T$3:T6,">0")),"") -> 0 | V6: =IFERROR(VLOOKUP(INDEX($A:$A,MATCH(ROW(T4),U:U,0)),$A:$D,4,0),"") | W6: =CONCATENATE(Z6,Y6,X6) -> TARATALAHELPERKRISH | X6: ='OTHER PLANT ATTN.'!C:C -> KRISH | Y6: =Table1[[#This Row],[CATEGORY ]] -> HELPER | Z6: =Table1[[#This Row],[PLANT]] -> TARATALA | AD6: OTHERS | AE6: OTHERS
A7: =CONCATENATE(B7,C7,D7) -> CONTRACTHELPERAMIT BISWAS | B7: =Table4[[#This Row],[CATEGORY]] -> CONTRACT | C7: =Table4[[#This Row],[SUB-CATEGORY]] -> HELPER | D7: ='RJ ATTENDENCE SHEET'!C:C -> AMIT BISWAS | E7: =C7 -> HELPER | F7: =IFERROR(SEARCH("SALARYOFFICE",$A:$A),"") | G7: =IFERROR(IF(F7=0,"",COUNTIF($F$3:F7,">0")),"") -> 4 | H7: =IFERROR(VLOOKUP(INDEX($A:$A,MATCH(ROW(F5),G:G,0)),$A:$D,4,0),"") -> ANOWAR MOLLA | I7: =IFERROR(SEARCH("WAGES",$A:$A),"") | J7: =IFERROR(IF(I7=0,"",COUNTIF($I$3:I7,">0")),"") -> 0 | K7: =IFERROR(VLOOKUP(INDEX($A:$A,MATCH(ROW(I5),J:J,0)),$A:$D,4,0),"") -> FARUK ALI | L7: =IFERROR(VLOOKUP(K7,$D:$E,2,0),"") -> DRIVER | M7: =IFERROR(SEARCH("CONTRACT",$A:$A),"") -> 1 | N7: =IFERROR(IF(M7=0,"",COUNTIF($M$3:M7,">0")),"") -> 1 | O7: =IFERROR(VLOOKUP(INDEX($A:$A,MATCH(ROW(M5),N:N,0)),$A:$D,4,0),"") -> BASIRUDDIN KHAN | P7: =IFERROR(VLOOKUP(O7,$D:$E,2,0),"") -> OTHERS | Q7: =IFERROR(SEARCH("SALARY",$A:$A),"") | R7: =IFERROR(IF(Q7=0,"",COUNTIF($Q$3:Q7,">0")),"") -> 4 | S7: =IFERROR(VLOOKUP(INDEX($A:$A,MATCH(ROW(Q5),R:R,0)),$A:$D,4,0),"") -> ANOWAR MOLLA | T7: =IFERROR(SEARCH("OTHERS0",$A:$A),"") | U7: =IFERROR(IF(T7=0,"",COUNTIF($T$3:T7,">0")),"") -> 0 | V7: =IFERROR(VLOOKUP(INDEX($A:$A,MATCH(ROW(T5),U:U,0)),$A:$D,4,0),"") | W7: =CONCATENATE(Z7,Y7,X7) -> TARATALAHELPERKHAIRUL | X7: ='OTHER PLANT ATTN.'!C:C -> KHAIRUL | Y7: =Table1[[#This Row],[CATEGORY ]] -> HELPER | Z7: =Table1[[#This Row],[PLANT]] -> TARATALA
A8: =CONCATENATE(B8,C8,D8) -> WAGESDRIVERANISUR | B8: =Table4[[#This Row],[CATEGORY]] -> WAGES | C8: =Table4[[#This Row],[SUB-CATEGORY]] -> DRIVER | D8: ='RJ ATTENDENCE SHEET'!C:C -> ANISUR | E8: =C8 -> DRIVER | F8: =IFERROR(SEARCH("SALARYOFFICE",$A:$A),"") | G8: =IFERROR(IF(F8=0,"",COUNTIF($F$3:F8,">0")),"") -> 4 | H8: =IFERROR(VLOOKUP(INDEX($A:$A,MATCH(ROW(F6),G:G,0)),$A:$D,4,0),"") -> DIBAKAR MONDAL | I8: =IFERROR(SEARCH("WAGES",$A:$A),"") -> 1 | J8: =IFERROR(IF(I8=0,"",COUNTIF($I$3:I8,">0")),"") -> 1 | K8: =IFERROR(VLOOKUP(INDEX($A:$A,MATCH(ROW(I6),J:J,0)),$A:$D,4,0),"") -> KUTUBUDDIN MOLLA | L8: =IFERROR(VLOOKUP(K8,$D:$E,2,0),"") -> HOPPER | M8: =IFERROR(SEARCH("CONTRACT",$A:$A),"") | N8: =IFERROR(IF(M8=0,"",COUNTIF($M$3:M8,">0")),"") -> 1 | O8: =IFERROR(VLOOKUP(INDEX($A:$A,MATCH(ROW(M6),N:N,0)),$A:$D,4,0),"") -> DIN MOHAMMOD ALI | P8: =IFERROR(VLOOKUP(O8,$D:$E,2,0),"") -> DRIVER | Q8: =IFERROR(SEARCH("SALARY",$A:$A),"") | R8: =IFERROR(IF(Q8=0,"",COUNTIF($Q$3:Q8,">0")),"") -> 4 | S8: =IFERROR(VLOOKUP(INDEX($A:$A,MATCH(ROW(Q6),R:R,0)),$A:$D,4,0),"") -> DIBAKAR MONDAL | T8: =IFERROR(SEARCH("OTHERS0",$A:$A),"") | U8: =IFERROR(IF(T8=0,"",COUNTIF($T$3:T8,">0")),"") -> 0 | V8: =IFERROR(VLOOKUP(INDEX($A:$A,MATCH(ROW(T6),U:U,0)),$A:$D,4,0),"") | W8: =CONCATENATE(Z8,Y8,X8) -> TARATALAHELPERSAJAN | X8: ='OTHER PLANT ATTN.'!C:C -> SAJAN | Y8: =Table1[[#This Row],[CATEGORY ]] -> HELPER | Z8: =Table1[[#This Row],[PLANT]] -> TARATALA
A9: =CONCATENATE(B9,C9,D9) -> SALARYOFFICEANOWAR MOLLA | B9: =Table4[[#This Row],[CATEGORY]] -> SALARY | C9: =Table4[[#This Row],[SUB-CATEGORY]] -> OFFICE | D9: ='RJ ATTENDENCE SHEET'!C:C -> ANOWAR MOLLA | E9: =C9 -> OFFICE | F9: =IFERROR(SEARCH("SALARYOFFICE",$A:$A),"") -> 1 | G9: =IFERROR(IF(F9=0,"",COUNTIF($F$3:F9,">0")),"") -> 5 | H9: =IFERROR(VLOOKUP(INDEX($A:$A,MATCH(ROW(F7),G:G,0)),$A:$D,4,0),"") -> GOLAM SARWAR | I9: =IFERROR(SEARCH("WAGES",$A:$A),"") | J9: =IFERROR(IF(I9=0,"",COUNTIF($I$3:I9,">0")),"") -> 1 | K9: =IFERROR(VLOOKUP(INDEX($A:$A,MATCH(ROW(I7),J:J,0)),$A:$D,4,0),"") -> MD. SAMIM AKRAM | L9: =IFERROR(VLOOKUP(K9,$D:$E,2,0),"") -> OTHERS | M9: =IFERROR(SEARCH("CONTRACT",$A:$A),"") | N9: =IFERROR(IF(M9=0,"",COUNTIF($M$3:M9,">0")),"") -> 1 | O9: =IFERROR(VLOOKUP(INDEX($A:$A,MATCH(ROW(M7),N:N,0)),$A:$D,4,0),"") -> RAFIQUE MOLLA | P9: =IFERROR(VLOOKUP(O9,$D:$E,2,0),"") -> DRIVER | Q9: =IFERROR(SEARCH("SALARY",$A:$A),"") -> 1 | R9: =IFERROR(IF(Q9=0,"",COUNTIF($Q$3:Q9,">0")),"") -> 5 | S9: =IFERROR(VLOOKUP(INDEX($A:$A,MATCH(ROW(Q7),R:R,0)),$A:$D,4,0),"") -> GOLAM SARWAR | T9: =IFERROR(SEARCH("OTHERS0",$A:$A),"") | U9: =IFERROR(IF(T9=0,"",COUNTIF($T$3:T9,">0")),"") -> 0 | V9: =IFERROR(VLOOKUP(INDEX($A:$A,MATCH(ROW(T7),U:U,0)),$A:$D,4,0),"") | W9: =CONCATENATE(Z9,Y9,X9) -> TARATALADRIVERGIASUDDIN | X9: ='OTHER PLANT ATTN.'!C:C -> GIASUDDIN | Y9: =Table1[[#This Row],[CATEGORY ]] -> DRIVER | Z9: =Table1[[#This Row],[PLANT]] -> TARATALA
A10: =CONCATENATE(B10,C10,D10) -> WAGESDRIVERARMAN ALI MONDAL | B10: =Table4[[#This Row],[CATEGORY]] -> WAGES | C10: =Table4[[#This Row],[SUB-CATEGORY]] -> DRIVER | D10: ='RJ ATTENDENCE SHEET'!C:C -> ARMAN ALI MONDAL | E10: =C10 -> DRIVER | F10: =IFERROR(SEARCH("SALARYOFFICE",$A:$A),"") | G10: =IFERROR(IF(F10=0,"",COUNTIF($F$3:F10,">0")),"") -> 5 | H10: =IFERROR(VLOOKUP(INDEX($A:$A,MATCH(ROW(F8),G:G,0)),$A:$D,4,0),"") -> IMAN ALI MOLLA | I10: =IFERROR(SEARCH("WAGES",$A:$A),"") -> 1 | J10: =IFERROR(IF(I10=0,"",COUNTIF($I$3:I10,">0")),"") -> 2 | K10: =IFERROR(VLOOKUP(INDEX($A:$A,MATCH(ROW(I8),J:J,0)),$A:$D,4,0),"") -> MOTIAR RAHAMAN | L10: =IFERROR(VLOOKUP(K10,$D:$E,2,0),"") -> DRIVER | M10: =IFERROR(SEARCH("CONTRACT",$A:$A),"") | N10: =IFERROR(IF(M10=0,"",COUNTIF($M$3:M10,">0")),"") -> 1 | O10: =IFERROR(VLOOKUP(INDEX($A:$A,MATCH(ROW(M8),N:N,0)),$A:$D,4,0),"") -> RAFIKUL MOLLA | P10: =IFERROR(VLOOKUP(O10,$D:$E,2,0),"") -> HELPER | Q10: =IFERROR(SEARCH("SALARY",$A:$A),"") | R10: =IFERROR(IF(Q10=0,"",COUNTIF($Q$3:Q10,">0")),"") -> 5 | S10: =IFERROR(VLOOKUP(INDEX($A:$A,MATCH(ROW(Q8),R:R,0)),$A:$D,4,0),"") -> IMAN ALI MOLLA | T10: =IFERROR(SEARCH("OTHERS0",$A:$A),"") | U10: =IFERROR(IF(T10=0,"",COUNTIF($T$3:T10,">0")),"") -> 0 | V10: =IFERROR(VLOOKUP(INDEX($A:$A,MATCH(ROW(T8),U:U,0)),$A:$D,4,0),"") | W10: =CONCATENATE(Z10,Y10,X10) -> JALANDRIVERRAKESH | X10: ='OTHER PLANT ATTN.'!C:C -> RAKESH | Y10: =Table1[[#This Row],[CATEGORY ]] -> DRIVER | Z10: =Table1[[#This Row],[PLANT]] -> JALAN
A11: =CONCATENATE(B11,C11,D11) -> CONTRACTHELPERJHANTU MONDAL | B11: =Table4[[#This Row],[CATEGORY]] -> CONTRACT | C11: =Table4[[#This Row],[SUB-CATEGORY]] -> HELPER | D11: ='RJ ATTENDENCE SHEET'!C:C -> JHANTU MONDAL | E11: =C11 -> HELPER | F11: =IFERROR(SEARCH("SALARYOFFICE",$A:$A),"") | G11: =IFERROR(IF(F11=0,"",COUNTIF($F$3:F11,">0")),"") -> 5 | H11: =IFERROR(VLOOKUP(INDEX($A:$A,MATCH(ROW(F9),G:G,0)),$A:$D,4,0),"") -> PULIN MONDAL | I11: =IFERROR(SEARCH("WAGES",$A:$A),"") | J11: =IFERROR(IF(I11=0,"",COUNTIF($I$3:I11,">0")),"") -> 2 | K11: =IFERROR(VLOOKUP(INDEX($A:$A,MATCH(ROW(I9),J:J,0)),$A:$D,4,0),"") -> MOKSHED ALI | L11: =IFERROR(VLOOKUP(K11,$D:$E,2,0),"") -> DRIVER | M11: =IFERROR(SEARCH("CONTRACT",$A:$A),"") -> 1 | N11: =IFERROR(IF(M11=0,"",COUNTIF($M$3:M11,">0")),"") -> 2 | O11: =IFERROR(VLOOKUP(INDEX($A:$A,MATCH(ROW(M9),N:N,0)),$A:$D,4,0),"") -> AYAN PAUL | P11: =IFERROR(VLOOKUP(O11,$D:$E,2,0),"") -> OTHERS | Q11: =IFERROR(SEARCH("SALARY",$A:$A),"") | R11: =IFERROR(IF(Q11=0,"",COUNTIF($Q$3:Q11,">0")),"") -> 5 | S11: =IFERROR(VLOOKUP(INDEX($A:$A,MATCH(ROW(Q9),R:R,0)),$A:$D,4,0),"") -> PULIN MONDAL | T11: =IFERROR(SEARCH("OTHERS0",$A:$A),"") | U11: =IFERROR(IF(T11=0,"",COUNTIF($T$3:T11,">0")),"") -> 0 | V11: =IFERROR(VLOOKUP(INDEX($A:$A,MATCH(ROW(T9),U:U,0)),$A:$D,4,0),"") | W11: =CONCATENATE(Z11,Y11,X11) -> TARATALADRIVERANSAR | X11: ='OTHER PLANT ATTN.'!C:C -> ANSAR | Y11: =Table1[[#This Row],[CATEGORY ]] -> DRIVER | Z11: =Table1[[#This Row],[PLANT]] -> TARATALA
A12: =CONCATENATE(B12,C12,D12) -> CONTRACTDRIVERASHIT BISWAS | B12: =Table4[[#This Row],[CATEGORY]] -> CONTRACT | C12: =Table4[[#This Row],[SUB-CATEGORY]] -> DRIVER | D12: ='RJ ATTENDENCE SHEET'!C:C -> ASHIT BISWAS | E12: =C12 -> DRIVER | F12: =IFERROR(SEARCH("SALARYOFFICE",$A:$A),"") | G12: =IFERROR(IF(F12=0,"",COUNTIF($F$3:F12,">0")),"") -> 5 | H12: =IFERROR(VLOOKUP(INDEX($A:$A,MATCH(ROW(F10),G:G,0)),$A:$D,4,0),"") -> RAJU PAL | I12: =IFERROR(SEARCH("WAGES",$A:$A),"") | J12: =IFERROR(IF(I12=0,"",COUNTIF($I$3:I12,">0")),"") -> 2 | K12: =IFERROR(VLOOKUP(INDEX($A:$A,MATCH(ROW(I10),J:J,0)),$A:$D,4,0),"") -> SAMSER ALI | L12: =IFERROR(VLOOKUP(K12,$D:$E,2,0),"") -> DRIVER | M12: =IFERROR(SEARCH("CONTRACT",$A:$A),"") -> 1 | N12: =IFERROR(IF(M12=0,"",COUNTIF($M$3:M12,">0")),"") -> 3 | O12: =IFERROR(VLOOKUP(INDEX($A:$A,MATCH(ROW(M10),N:N,0)),$A:$D,4,0),"") -> NAYAN MONDAL | P12: =IFERROR(VLOOKUP(O12,$D:$E,2,0),"") -> HELPER | Q12: =IFERROR(SEARCH("SALARY",$A:$A),"") | R12: =IFERROR(IF(Q12=0,"",COUNTIF($Q$3:Q12,">0")),"") -> 5 | S12: =IFERROR(VLOOKUP(INDEX($A:$A,MATCH(ROW(Q10),R:R,0)),$A:$D,4,0),"") -> RAJU PAL | T12: =IFERROR(SEARCH("OTHERS0",$A:$A),"") | U12: =IFERROR(IF(T12=0,"",COUNTIF($T$3:T12,">0")),"") -> 0 | V12: =IFERROR(VLOOKUP(INDEX($A:$A,MATCH(ROW(T10),U:U,0)),$A:$D,4,0),"") | W12: =CONCATENATE(Z12,Y12,X12) -> TARATALADRIVERRANJIT | X12: ='OTHER PLANT ATTN.'!C:C -> RANJIT | Y12: =Table1[[#This Row],[CATEGORY ]] -> DRIVER | Z12: =Table1[[#This Row],[PLANT]] -> TARATALA
A13: =CONCATENATE(B13,C13,D13) -> WAGESHELPERASUTOSH SARDAR | B13: =Table4[[#This Row],[CATEGORY]] -> WAGES | C13: =Table4[[#This Row],[SUB-CATEGORY]] -> HELPER | D13: ='RJ ATTENDENCE SHEET'!C:C -> ASUTOSH SARDAR | E13: =C13 -> HELPER | F13: =IFERROR(SEARCH("SALARYOFFICE",$A:$A),"") | G13: =IFERROR(IF(F13=0,"",COUNTIF($F$3:F13,">0")),"") -> 5 | H13: =IFERROR(VLOOKUP(INDEX($A:$A,MATCH(ROW(F11),G:G,0)),$A:$D,4,0),"") -> UJJAL MUKHERJEE | I13: =IFERROR(SEARCH("WAGES",$A:$A),"") -> 1 | J13: =IFERROR(IF(I13=0,"",COUNTIF($I$3:I13,">0")),"") -> 3 | K13: =IFERROR(VLOOKUP(INDEX($A:$A,MATCH(ROW(I11),J:J,0)),$A:$D,4,0),"") -> SHANTI MONDAL | L13: =IFERROR(VLOOKUP(K13,$D:$E,2,0),"") -> DRIVER | M13: =IFERROR(SEARCH("CONTRACT",$A:$A),"") | N13: =IFERROR(IF(M13=0,"",COUNTIF($M$3:M13,">0")),"") -> 3 | O13: =IFERROR(VLOOKUP(INDEX($A:$A,MATCH(ROW(M11),N:N,0)),$A:$D,4,0),"") -> SHIB SANKAR MAJHI | P13: =IFERROR(VLOOKUP(O13,$D:$E,2,0),"") -> OTHERS | Q13: =IFERROR(SEARCH("SALARY",$A:$A),"") | R13: =IFERROR(IF(Q13=0,"",COUNTIF($Q$3:Q13,">0")),"") -> 5 | S13: =IFERROR(VLOOKUP(INDEX($A:$A,MATCH(ROW(Q11),R:R,0)),$A:$D,4,0),"") -> UJJAL MUKHERJEE | T13: =IFERROR(SEARCH("OTHERS0",$A:$A),"") | U13: =IFERROR(IF(T13=0,"",COUNTIF($T$3:T13,">0")),"") -> 0 | V13: =IFERROR(VLOOKUP(INDEX($A:$A,MATCH(ROW(T11),U:U,0)),$A:$D,4,0),"") | W13: =CONCATENATE(Z13,Y13,X13) -> TARATALAHELPERKAPIL | X13: ='OTHER PLANT ATTN.'!C:C -> KAPIL | Y13: =Table1[[#This Row],[CATEGORY ]] -> HELPER | Z13: =Table1[[#This Row],[PLANT]] -> TARATALA
A14: =CONCATENATE(B14,C14,D14) -> CONTRACTHELPERNASIB KARIKAR | B14: =Table4[[#This Row],[CATEGORY]] -> CONTRACT | C14: =Table4[[#This Row],[SUB-CATEGORY]] -> HELPER | D14: ='RJ ATTENDENCE SHEET'!C:C -> NASIB KARIKAR | E14: =C14 -> HELPER | F14: =IFERROR(SEARCH("SALARYOFFICE",$A:$A),"") | G14: =IFERROR(IF(F14=0,"",COUNTIF($F$3:F14,">0")),"") -> 5 | H14: =IFERROR(VLOOKUP(INDEX($A:$A,MATCH(ROW(F12),G:G,0)),$A:$D,4,0),"") -> PROBIR GHOSH | I14: =IFERROR(SEARCH("WAGES",$A:$A),"") | J14: =IFERROR(IF(I14=0,"",COUNTIF($I$3:I14,">0")),"") -> 3 | K14: =IFERROR(VLOOKUP(INDEX($A:$A,MATCH(ROW(I12),J:J,0)),$A:$D,4,0),"") -> SIRAJUL MOLLA | L14: =IFERROR(VLOOKUP(K14,$D:$E,2,0),"") -> DRIVER | M14: =IFERROR(SEARCH("CONTRACT",$A:$A),"") -> 1 | N14: =IFERROR(IF(M14=0,"",COUNTIF($M$3:M14,">0")),"") -> 4 | O14: =IFERROR(VLOOKUP(INDEX($A:$A,MATCH(ROW(M12),N:N,0)),$A:$D,4,0),"") -> ABUL KALAM AZAD | P14: =IFERROR(VLOOKUP(O14,$D:$E,2,0),"") -> OTHERS | Q14: =IFERROR(SEARCH("SALARY",$A:$A),"") | R14: =IFERROR(IF(Q14=0,"",COUNTIF($Q$3:Q14,">0")),"") -> 5 | S14: =IFERROR(VLOOKUP(INDEX($A:$A,MATCH(ROW(Q12),R:R,0)),$A:$D,4,0),"") -> PROBIR GHOSH | T14: =IFERROR(SEARCH("OTHERS0",$A:$A),"") | U14: =IFERROR(IF(T14=0,"",COUNTIF($T$3:T14,">0")),"") -> 0 | V14: =IFERROR(VLOOKUP(INDEX($A:$A,MATCH(ROW(T12),U:U,0)),$A:$D,4,0),"") | W14: =CONCATENATE(Z14,Y14,X14) -> TARATALAHELPERRINTU | X14: ='OTHER PLANT ATTN.'!C:C -> RINTU | Y14: =Table1[[#This Row],[CATEGORY ]] -> HELPER | Z14: =Table1[[#This Row],[PLANT]] -> TARATALA
A15: =CONCATENATE(B15,C15,D15) -> CONTRACTOTHERSBASIRUDDIN KHAN | B15: =Table4[[#This Row],[CATEGORY]] -> CONTRACT | C15: =Table4[[#This Row],[SUB-CATEGORY]] -> OTHERS | D15: ='RJ ATTENDENCE SHEET'!C:C -> BASIRUDDIN KHAN | E15: =C15 -> OTHERS | F15: =IFERROR(SEARCH("SALARYOFFICE",$A:$A),"") | G15: =IFERROR(IF(F15=0,"",COUNTIF($F$3:F15,">0")),"") -> 5 | H15: =IFERROR(VLOOKUP(INDEX($A:$A,MATCH(ROW(F13),G:G,0)),$A:$D,4,0),"") -> NABA KUMAR BISWAS | I15: =IFERROR(SEARCH("WAGES",$A:$A),"") | J15: =IFERROR(IF(I15=0,"",COUNTIF($I$3:I15,">0")),"") -> 3 | K15: =IFERROR(VLOOKUP(INDEX($A:$A,MATCH(ROW(I13),J:J,0)),$A:$D,4,0),"") -> SK. ANARUL ISLAM | L15: =IFERROR(VLOOKUP(K15,$D:$E,2,0),"") -> HELPER | M15: =IFERROR(SEARCH("CONTRACT",$A:$A),"") -> 1 | N15: =IFERROR(IF(M15=0,"",COUNTIF($M$3:M15,">0")),"") -> 5 | O15: =IFERROR(VLOOKUP(INDEX($A:$A,MATCH(ROW(M13),N:N,0)),$A:$D,4,0),"") -> SATYA NASKAR | P15: =IFERROR(VLOOKUP(O15,$D:$E,2,0),"") -> DRIVER | Q15: =IFERROR(SEARCH("SALARY",$A:$A),"") | R15: =IFERROR(IF(Q15=0,"",COUNTIF($Q$3:Q15,">0")),"") -> 5 | S15: =IFERROR(VLOOKUP(INDEX($A:$A,MATCH(ROW(Q13),R:R,0)),$A:$D,4,0),"") -> NABA KUMAR BISWAS | T15: =IFERROR(SEARCH("OTHERS0",$A:$A),"") | U15: =IFERROR(IF(T15=0,"",COUNTIF($T$3:T15,">0")),"") -> 0 | V15: =IFERROR(VLOOKUP(INDEX($A:$A,MATCH(ROW(T13),U:U,0)),$A:$D,4,0),"") | W15: =CONCATENATE(Z15,Y15,X15) -> TARATALAHELPERRABIN | X15: ='OTHER PLANT ATTN.'!C:C -> RABIN | Y15: =Table1[[#This Row],[CATEGORY ]] -> HELPER | Z15: =Table1[[#This Row],[PLANT]] -> TARATALA
A16: =CONCATENATE(B16,C16,D16) -> WAGESLABBUDDHADEV SEAL | B16: =Table4[[#This Row],[CATEGORY]] -> WAGES | C16: =Table4[[#This Row],[SUB-CATEGORY]] -> LAB | D16: ='RJ ATTENDENCE SHEET'!C:C -> BUDDHADEV SEAL | E16: =C16 -> LAB | F16: =IFERROR(SEARCH("SALARYOFFICE",$A:$A),"") | G16: =IFERROR(IF(F16=0,"",COUNTIF($F$3:F16,">0")),"") -> 5 | H16: =IFERROR(VLOOKUP(INDEX($A:$A,MATCH(ROW(F14),G:G,0)),$A:$D,4,0),"") -> ASIM KHUNTIA | I16: =IFERROR(SEARCH("WAGES",$A:$A),"") -> 1 | J16: =IFERROR(IF(I16=0,"",COUNTIF($I$3:I16,">0")),"") -> 4 | K16: =IFERROR(VLOOKUP(INDEX($A:$A,MATCH(ROW(I14),J:J,0)),$A:$D,4,0),"") -> SRISTI DHAR MONDAL | L16: =IFERROR(VLOOKUP(K16,$D:$E,2,0),"") -> HOPPER | M16: =IFERROR(SEARCH("CONTRACT",$A:$A),"") | N16: =IFERROR(IF(M16=0,"",COUNTIF($M$3:M16,">0")),"") -> 5 | O16: =IFERROR(VLOOKUP(INDEX($A:$A,MATCH(ROW(M14),N:N,0)),$A:$D,4,0),"") -> JAMSHED ALI | P16: =IFERROR(VLOOKUP(O16,$D:$E,2,0),"") -> HELPER | Q16: =IFERROR(SEARCH("SALARY",$A:$A),"") | R16: =IFERROR(IF(Q16=0,"",COUNTIF($Q$3:Q16,">0")),"") -> 5 | S16: =IFERROR(VLOOKUP(INDEX($A:$A,MATCH(ROW(Q14),R:R,0)),$A:$D,4,0),"") -> ASIM KHUNTIA | T16: =IFERROR(SEARCH("OTHERS0",$A:$A),"") | U16: =IFERROR(IF(T16=0,"",COUNTIF($T$3:T16,">0")),"") -> 0 | V16: =IFERROR(VLOOKUP(INDEX($A:$A,MATCH(ROW(T14),U:U,0)),$A:$D,4,0),"") | W16: =CONCATENATE(Z16,Y16,X16) -> JALANHELPERMITHUN | X16: ='OTHER PLANT ATTN.'!C:C -> MITHUN | Y16: =Table1[[#This Row],[CATEGORY ]] -> HELPER | Z16: =Table1[[#This Row],[PLANT]] -> JALAN
A17: =CONCATENATE(B17,C17,D17) -> SALARYOFFICEDIBAKAR MONDAL | B17: =Table4[[#This Row],[CATEGORY]] -> SALARY | C17: =Table4[[#This Row],[SUB-CATEGORY]] -> OFFICE | D17: ='RJ ATTENDENCE SHEET'!C:C -> DIBAKAR MONDAL | E17: =C17 -> OFFICE | F17: =IFERROR(SEARCH("SALARYOFFICE",$A:$A),"") -> 1 | G17: =IFERROR(IF(F17=0,"",COUNTIF($F$3:F17,">0")),"") -> 6 | H17: =IFERROR(VLOOKUP(INDEX($A:$A,MATCH(ROW(F15),G:G,0)),$A:$D,4,0),"") -> MANABINDU BISWAS | I17: =IFERROR(SEARCH("WAGES",$A:$A),"") | J17: =IFERROR(IF(I17=0,"",COUNTIF($I$3:I17,">0")),"") -> 4 | K17: =IFERROR(VLOOKUP(INDEX($A:$A,MATCH(ROW(I15),J:J,0)),$A:$D,4,0),"") -> SUDHAN MONDAL | L17: =IFERROR(VLOOKUP(K17,$D:$E,2,0),"") -> HOPPER | M17: =IFERROR(SEARCH("CONTRACT",$A:$A),"") | N17: =IFERROR(IF(M17=0,"",COUNTIF($M$3:M17,">0")),"") -> 5 | O17: =IFERROR(VLOOKUP(INDEX($A:$A,MATCH(ROW(M15),N:N,0)),$A:$D,4,0),"") -> ABHIJIT MONDAL | P17: =IFERROR(VLOOKUP(O17,$D:$E,2,0),"") -> HELPER | Q17: =IFERROR(SEARCH("SALARY",$A:$A),"") -> 1 | R17: =IFERROR(IF(Q17=0,"",COUNTIF($Q$3:Q17,">0")),"") -> 6 | S17: =IFERROR(VLOOKUP(INDEX($A:$A,MATCH(ROW(Q15),R:R,0)),$A:$D,4,0),"") -> MANABINDU BISWAS | T17: =IFERROR(SEARCH("OTHERS0",$A:$A),"") | U17: =IFERROR(IF(T17=0,"",COUNTIF($T$3:T17,">0")),"") -> 0 | V17: =IFERROR(VLOOKUP(INDEX($A:$A,MATCH(ROW(T15),U:U,0)),$A:$D,4,0),"") | W17: =CONCATENATE(Z17,Y17,X17) -> JALANHELPERRAMU | X17: ='OTHER PLANT ATTN.'!C:C -> RAMU | Y17: =Table1[[#This Row],[CATEGORY ]] -> HELPER | Z17: =Table1[[#This Row],[PLANT]] -> JALAN
A18: =CONCATENATE(B18,C18,D18) -> CONTRACTDRIVERDIN MOHAMMOD ALI | B18: =Table4[[#This Row],[CATEGORY]] -> CONTRACT | C18: =Table4[[#This Row],[SUB-CATEGORY]] -> DRIVER | D18: ='RJ ATTENDENCE SHEET'!C:C -> DIN MOHAMMOD ALI | E18: =C18 -> DRIVER | F18: =IFERROR(SEARCH("SALARYOFFICE",$A:$A),"") | G18: =IFERROR(IF(F18=0,"",COUNTIF($F$3:F18,">0")),"") -> 6 | H18: =IFERROR(VLOOKUP(INDEX($A:$A,MATCH(ROW(F16),G:G,0)),$A:$D,4,0),"") -> SUVANKAR SAMADDAR | I18: =IFERROR(SEARCH("WAGES",$A:$A),"") | J18: =IFERROR(IF(I18=0,"",COUNTIF($I$3:I18,">0")),"") -> 4 | K18: =IFERROR(VLOOKUP(INDEX($A:$A,MATCH(ROW(I16),J:J,0)),$A:$D,4,0),"") -> SWAPAN MONDAL | L18: =IFERROR(VLOOKUP(K18,$D:$E,2,0),"") -> LAB | M18: =IFERROR(SEARCH("CONTRACT",$A:$A),"") -> 1 | N18: =IFERROR(IF(M18=0,"",COUNTIF($M$3:M18,">0")),"") -> 6 | O18: =IFERROR(VLOOKUP(INDEX($A:$A,MATCH(ROW(M16),N:N,0)),$A:$D,4,0),"") -> KHALEK DHALI | P18: =IFERROR(VLOOKUP(O18,$D:$E,2,0),"") -> HELPER | Q18: =IFERROR(SEARCH("SALARY",$A:$A),"") | R18: =IFERROR(IF(Q18=0,"",COUNTIF($Q$3:Q18,">0")),"") -> 6 | S18: =IFERROR(VLOOKUP(INDEX($A:$A,MATCH(ROW(Q16),R:R,0)),$A:$D,4,0),"") -> SUVANKAR SAMADDAR | T18: =IFERROR(SEARCH("OTHERS0",$A:$A),"") | U18: =IFERROR(IF(T18=0,"",COUNTIF($T$3:T18,">0")),"") -> 0 | V18: =IFERROR(VLOOKUP(INDEX($A:$A,MATCH(ROW(T16),U:U,0)),$A:$D,4,0),"") | W18: =CONCATENATE(Z18,Y18,X18) -> JALANDRIVERTAPAS | X18: ='OTHER PLANT ATTN.'!C:C -> TAPAS | Y18: =Table1[[#This Row],[CATEGORY ]] -> DRIVER | Z18: =Table1[[#This Row],[PLANT]] -> JALAN
... A438: =CONCATENATE(B438,C438,D438) -> #VALUE! | B438: =Table4[[#This Row],[CATEGORY]] -> #VALUE! | C438: =Table4[[#This Row],[SUB-CATEGORY]] -> #VALUE! | D438: ='RJ ATTENDENCE SHEET'!C:C -> 0 | E438: =C438 -> #VALUE! | F438: =IFERROR(SEARCH("SALARYOFFICE",$A:$A),"") | G438: =IFERROR(IF(F438=0,"",COUNTIF($F$3:F438,">0")),"") -> 16 | H438: =IFERROR(VLOOKUP(INDEX($A:$A,MATCH(ROW(F436),G:G,0)),$A:$D,4,0),"") | I438: =IFERROR(SEARCH("WAGES",$A:$A),"") | J438: =IFERROR(IF(I438=0,"",COUNTIF($I$3:I438,">0")),"") -> 34 | K438: =IFERROR(VLOOKUP(INDEX($A:$A,MATCH(ROW(I436),J:J,0)),$A:$D,4,0),"") | L438: =IFERROR(VLOOKUP(K438,$D:$E,2,0),"") | M438: =IFERROR(SEARCH("CONTRACT",$A:$A),"") | N438: =IFERROR(IF(M438=0,"",COUNTIF($M$3:M438,">0")),"") -> 33 | O438: =IFERROR(VLOOKUP(INDEX($A:$A,MATCH(ROW(M436),N:N,0)),$A:$D,4,0),"") | P438: =IFERROR(VLOOKUP(O438,$D:$E,2,0),"") | Q438: =IFERROR(SEARCH("SALARY",$A:$A),"") | R438: =IFERROR(IF(Q438=0,"",COUNTIF($Q$3:Q438,">0")),"") -> 16 | S438: =IFERROR(VLOOKUP(INDEX($A:$A,MATCH(ROW(Q436),R:R,0)),$A:$D,4,0),"") | T438: =IFERROR(SEARCH("OTHERS0",$A:$A),"") | U438: =IFERROR(IF(T438=0,"",COUNTIF($T$3:T438,">0")),"") -> 0 | V438: =IFERROR(VLOOKUP(INDEX($A:$A,MATCH(ROW(T436),U:U,0)),$A:$D,4,0),"") | W438: =CONCATENATE(Z438,Y438,X438) -> #VALUE! | X438: ='OTHER PLANT ATTN.'!C:C -> 0 | Y438: =Table1[[#This Row],[CATEGORY ]] -> #VALUE! | Z438: =Table1[[#This Row],[PLANT]] -> #VALUE!
A439: =CONCATENATE(B439,C439,D439) -> #VALUE! | B439: =Table4[[#This Row],[CATEGORY]] -> #VALUE! | C439: =Table4[[#This Row],[SUB-CATEGORY]] -> #VALUE! | D439: ='RJ ATTENDENCE SHEET'!C:C -> 0 | E439: =C439 -> #VALUE! | F439: =IFERROR(SEARCH("SALARYOFFICE",$A:$A),"") | G439: =IFERROR(IF(F439=0,"",COUNTIF($F$3:F439,">0")),"") -> 16 | H439: =IFERROR(VLOOKUP(INDEX($A:$A,MATCH(ROW(F437),G:G,0)),$A:$D,4,0),"") | I439: =IFERROR(SEARCH("WAGES",$A:$A),"") | J439: =IFERROR(IF(I439=0,"",COUNTIF($I$3:I439,">0")),"") -> 34 | K439: =IFERROR(VLOOKUP(INDEX($A:$A,MATCH(ROW(I437),J:J,0)),$A:$D,4,0),"") | L439: =IFERROR(VLOOKUP(K439,$D:$E,2,0),"") | M439: =IFERROR(SEARCH("CONTRACT",$A:$A),"") | N439: =IFERROR(IF(M439=0,"",COUNTIF($M$3:M439,">0")),"") -> 33 | O439: =IFERROR(VLOOKUP(INDEX($A:$A,MATCH(ROW(M437),N:N,0)),$A:$D,4,0),"") | P439: =IFERROR(VLOOKUP(O439,$D:$E,2,0),"") | Q439: =IFERROR(SEARCH("SALARY",$A:$A),"") | R439: =IFERROR(IF(Q439=0,"",COUNTIF($Q$3:Q439,">0")),"") -> 16 | S439: =IFERROR(VLOOKUP(INDEX($A:$A,MATCH(ROW(Q437),R:R,0)),$A:$D,4,0),"") | T439: =IFERROR(SEARCH("OTHERS0",$A:$A),"") | U439: =IFERROR(IF(T439=0,"",COUNTIF($T$3:T439,">0")),"") -> 0 | V439: =IFERROR(VLOOKUP(INDEX($A:$A,MATCH(ROW(T437),U:U,0)),$A:$D,4,0),"")
A440: =CONCATENATE(B440,C440,D440) -> #VALUE! | B440: =Table4[[#This Row],[CATEGORY]] -> #VALUE! | C440: =Table4[[#This Row],[SUB-CATEGORY]] -> #VALUE! | D440: ='RJ ATTENDENCE SHEET'!C:C -> 0 | E440: =C440 -> #VALUE! | F440: =IFERROR(SEARCH("SALARYOFFICE",$A:$A),"") | G440: =IFERROR(IF(F440=0,"",COUNTIF($F$3:F440,">0")),"") -> 16 | H440: =IFERROR(VLOOKUP(INDEX($A:$A,MATCH(ROW(F438),G:G,0)),$A:$D,4,0),"") | I440: =IFERROR(SEARCH("WAGES",$A:$A),"") | J440: =IFERROR(IF(I440=0,"",COUNTIF($I$3:I440,">0")),"") -> 34 | K440: =IFERROR(VLOOKUP(INDEX($A:$A,MATCH(ROW(I438),J:J,0)),$A:$D,4,0),"") | L440: =IFERROR(VLOOKUP(K440,$D:$E,2,0),"") | M440: =IFERROR(SEARCH("CONTRACT",$A:$A),"") | N440: =IFERROR(IF(M440=0,"",COUNTIF($M$3:M440,">0")),"") -> 33 | O440: =IFERROR(VLOOKUP(INDEX($A:$A,MATCH(ROW(M438),N:N,0)),$A:$D,4,0),"") | P440: =IFERROR(VLOOKUP(O440,$D:$E,2,0),"") | Q440: =IFERROR(SEARCH("SALARY",$A:$A),"") | R440: =IFERROR(IF(Q440=0,"",COUNTIF($Q$3:Q440,">0")),"") -> 16 | S440: =IFERROR(VLOOKUP(INDEX($A:$A,MATCH(ROW(Q438),R:R,0)),$A:$D,4,0),"") | T440: =IFERROR(SEARCH("OTHERS0",$A:$A),"") | U440: =IFERROR(IF(T440=0,"",COUNTIF($T$3:T440,">0")),"") -> 0 | V440: =IFERROR(VLOOKUP(INDEX($A:$A,MATCH(ROW(T438),U:U,0)),$A:$D,4,0),"")
A441: =CONCATENATE(B441,C441,D441) -> #VALUE! | B441: =Table4[[#This Row],[CATEGORY]] -> #VALUE! | C441: =Table4[[#This Row],[SUB-CATEGORY]] -> #VALUE! | D441: ='RJ ATTENDENCE SHEET'!C:C -> 0 | E441: =C441 -> #VALUE! | F441: =IFERROR(SEARCH("SALARYOFFICE",$A:$A),"") | G441: =IFERROR(IF(F441=0,"",COUNTIF($F$3:F441,">0")),"") -> 16 | H441: =IFERROR(VLOOKUP(INDEX($A:$A,MATCH(ROW(F439),G:G,0)),$A:$D,4,0),"") | I441: =IFERROR(SEARCH("WAGES",$A:$A),"") | J441: =IFERROR(IF(I441=0,"",COUNTIF($I$3:I441,">0")),"") -> 34 | K441: =IFERROR(VLOOKUP(INDEX($A:$A,MATCH(ROW(I439),J:J,0)),$A:$D,4,0),"") | L441: =IFERROR(VLOOKUP(K441,$D:$E,2,0),"") | M441: =IFERROR(SEARCH("CONTRACT",$A:$A),"") | N441: =IFERROR(IF(M441=0,"",COUNTIF($M$3:M441,">0")),"") -> 33 | O441: =IFERROR(VLOOKUP(INDEX($A:$A,MATCH(ROW(M439),N:N,0)),$A:$D,4,0),"") | P441: =IFERROR(VLOOKUP(O441,$D:$E,2,0),"") | Q441: =IFERROR(SEARCH("SALARY",$A:$A),"") | R441: =IFERROR(IF(Q441=0,"",COUNTIF($Q$3:Q441,">0")),"") -> 16 | S441: =IFERROR(VLOOKUP(INDEX($A:$A,MATCH(ROW(Q439),R:R,0)),$A:$D,4,0),"") | T441: =IFERROR(SEARCH("OTHERS0",$A:$A),"") | U441: =IFERROR(IF(T441=0,"",COUNTIF($T$3:T441,">0")),"") -> 0 | V441: =IFERROR(VLOOKUP(INDEX($A:$A,MATCH(ROW(T439),U:U,0)),$A:$D,4,0),"")
A442: =CONCATENATE(B442,C442,D442) -> #VALUE! | B442: =Table4[[#This Row],[CATEGORY]] -> #VALUE! | C442: =Table4[[#This Row],[SUB-CATEGORY]] -> #VALUE! | D442: ='RJ ATTENDENCE SHEET'!C:C -> 0 | E442: =C442 -> #VALUE! | F442: =IFERROR(SEARCH("SALARYOFFICE",$A:$A),"") | G442: =IFERROR(IF(F442=0,"",COUNTIF($F$3:F442,">0")),"") -> 16 | H442: =IFERROR(VLOOKUP(INDEX($A:$A,MATCH(ROW(F440),G:G,0)),$A:$D,4,0),"") | I442: =IFERROR(SEARCH("WAGES",$A:$A),"") | J442: =IFERROR(IF(I442=0,"",COUNTIF($I$3:I442,">0")),"") -> 34 | K442: =IFERROR(VLOOKUP(INDEX($A:$A,MATCH(ROW(I440),J:J,0)),$A:$D,4,0),"") | L442: =IFERROR(VLOOKUP(K442,$D:$E,2,0),"") | M442: =IFERROR(SEARCH("CONTRACT",$A:$A),"") | N442: =IFERROR(IF(M442=0,"",COUNTIF($M$3:M442,">0")),"") -> 33 | O442: =IFERROR(VLOOKUP(INDEX($A:$A,MATCH(ROW(M440),N:N,0)),$A:$D,4,0),"") | P442: =IFERROR(VLOOKUP(O442,$D:$E,2,0),"") | Q442: =IFERROR(SEARCH("SALARY",$A:$A),"") | R442: =IFERROR(IF(Q442=0,"",COUNTIF($Q$3:Q442,">0")),"") -> 16 | S442: =IFERROR(VLOOKUP(INDEX($A:$A,MATCH(ROW(Q440),R:R,0)),$A:$D,4,0),"") | T442: =IFERROR(SEARCH("OTHERS0",$A:$A),"") | U442: =IFERROR(IF(T442=0,"",COUNTIF($T$3:T442,">0")),"") -> 0 | V442: =IFERROR(VLOOKUP(INDEX($A:$A,MATCH(ROW(T440),U:U,0)),$A:$D,4,0),"")
A443: =CONCATENATE(B443,C443,D443) -> #VALUE! | B443: =Table4[[#This Row],[CATEGORY]] -> #VALUE! | C443: =Table4[[#This Row],[SUB-CATEGORY]] -> #VALUE! | D443: ='RJ ATTENDENCE SHEET'!C:C -> 0 | E443: =C443 -> #VALUE! | F443: =IFERROR(SEARCH("SALARYOFFICE",$A:$A),"") | G443: =IFERROR(IF(F443=0,"",COUNTIF($F$3:F443,">0")),"") -> 16 | H443: =IFERROR(VLOOKUP(INDEX($A:$A,MATCH(ROW(F441),G:G,0)),$A:$D,4,0),"") | I443: =IFERROR(SEARCH("WAGES",$A:$A),"") | J443: =IFERROR(IF(I443=0,"",COUNTIF($I$3:I443,">0")),"") -> 34 | K443: =IFERROR(VLOOKUP(INDEX($A:$A,MATCH(ROW(I441),J:J,0)),$A:$D,4,0),"") | L443: =IFERROR(VLOOKUP(K443,$D:$E,2,0),"") | M443: =IFERROR(SEARCH("CONTRACT",$A:$A),"") | N443: =IFERROR(IF(M443=0,"",COUNTIF($M$3:M443,">0")),"") -> 33 | O443: =IFERROR(VLOOKUP(INDEX($A:$A,MATCH(ROW(M441),N:N,0)),$A:$D,4,0),"") | P443: =IFERROR(VLOOKUP(O443,$D:$E,2,0),"") | Q443: =IFERROR(SEARCH("SALARY",$A:$A),"") | R443: =IFERROR(IF(Q443=0,"",COUNTIF($Q$3:Q443,">0")),"") -> 16 | S443: =IFERROR(VLOOKUP(INDEX($A:$A,MATCH(ROW(Q441),R:R,0)),$A:$D,4,0),"") | T443: =IFERROR(SEARCH("OTHERS0",$A:$A),"") | U443: =IFERROR(IF(T443=0,"",COUNTIF($T$3:T443,">0")),"") -> 0 | V443: =IFERROR(VLOOKUP(INDEX($A:$A,MATCH(ROW(T441),U:U,0)),$A:$D,4,0),"")
A444: =CONCATENATE(B444,C444,D444) -> #VALUE! | B444: =Table4[[#This Row],[CATEGORY]] -> #VALUE! | C444: =Table4[[#This Row],[SUB-CATEGORY]] -> #VALUE! | D444: ='RJ ATTENDENCE SHEET'!C:C -> 0 | E444: =C444 -> #VALUE! | F444: =IFERROR(SEARCH("SALARYOFFICE",$A:$A),"") | G444: =IFERROR(IF(F444=0,"",COUNTIF($F$3:F444,">0")),"") -> 16 | H444: =IFERROR(VLOOKUP(INDEX($A:$A,MATCH(ROW(F442),G:G,0)),$A:$D,4,0),"") | I444: =IFERROR(SEARCH("WAGES",$A:$A),"") | J444: =IFERROR(IF(I444=0,"",COUNTIF($I$3:I444,">0")),"") -> 34 | K444: =IFERROR(VLOOKUP(INDEX($A:$A,MATCH(ROW(I442),J:J,0)),$A:$D,4,0),"") | L444: =IFERROR(VLOOKUP(K444,$D:$E,2,0),"") | M444: =IFERROR(SEARCH("CONTRACT",$A:$A),"") | N444: =IFERROR(IF(M444=0,"",COUNTIF($M$3:M444,">0")),"") -> 33 | O444: =IFERROR(VLOOKUP(INDEX($A:$A,MATCH(ROW(M442),N:N,0)),$A:$D,4,0),"") | P444: =IFERROR(VLOOKUP(O444,$D:$E,2,0),"") | Q444: =IFERROR(SEARCH("SALARY",$A:$A),"") | R444: =IFERROR(IF(Q444=0,"",COUNTIF($Q$3:Q444,">0")),"") -> 16 | S444: =IFERROR(VLOOKUP(INDEX($A:$A,MATCH(ROW(Q442),R:R,0)),$A:$D,4,0),"") | T444: =IFERROR(SEARCH("OTHERS0",$A:$A),"") | U444: =IFERROR(IF(T444=0,"",COUNTIF($T$3:T444,">0")),"") -> 0 | V444: =IFERROR(VLOOKUP(INDEX($A:$A,MATCH(ROW(T442),U:U,0)),$A:$D,4,0),"")
A445: =CONCATENATE(B445,C445,D445) -> #VALUE! | B445: =Table4[[#This Row],[CATEGORY]] -> #VALUE! | C445: =Table4[[#This Row],[SUB-CATEGORY]] -> #VALUE! | D445: ='RJ ATTENDENCE SHEET'!C:C -> 0 | E445: =C445 -> #VALUE! | F445: =IFERROR(SEARCH("SALARYOFFICE",$A:$A),"") | G445: =IFERROR(IF(F445=0,"",COUNTIF($F$3:F445,">0")),"") -> 16 | H445: =IFERROR(VLOOKUP(INDEX($A:$A,MATCH(ROW(F443),G:G,0)),$A:$D,4,0),"") | I445: =IFERROR(SEARCH("WAGES",$A:$A),"") | J445: =IFERROR(IF(I445=0,"",COUNTIF($I$3:I445,">0")),"") -> 34 | K445: =IFERROR(VLOOKUP(INDEX($A:$A,MATCH(ROW(I443),J:J,0)),$A:$D,4,0),"") | L445: =IFERROR(VLOOKUP(K445,$D:$E,2,0),"") | M445: =IFERROR(SEARCH("CONTRACT",$A:$A),"") | N445: =IFERROR(IF(M445=0,"",COUNTIF($M$3:M445,">0")),"") -> 33 | O445: =IFERROR(VLOOKUP(INDEX($A:$A,MATCH(ROW(M443),N:N,0)),$A:$D,4,0),"") | P445: =IFERROR(VLOOKUP(O445,$D:$E,2,0),"") | Q445: =IFERROR(SEARCH("SALARY",$A:$A),"") | R445: =IFERROR(IF(Q445=0,"",COUNTIF($Q$3:Q445,">0")),"") -> 16 | S445: =IFERROR(VLOOKUP(INDEX($A:$A,MATCH(ROW(Q443),R:R,0)),$A:$D,4,0),"") | T445: =IFERROR(SEARCH("OTHERS0",$A:$A),"") | U445: =IFERROR(IF(T445=0,"",COUNTIF($T$3:T445,">0")),"") -> 0 | V445: =IFERROR(VLOOKUP(INDEX($A:$A,MATCH(ROW(T443),U:U,0)),$A:$D,4,0),"")
A446: =CONCATENATE(B446,C446,D446) -> #VALUE! | B446: =Table4[[#This Row],[CATEGORY]] -> #VALUE! | C446: =Table4[[#This Row],[SUB-CATEGORY]] -> #VALUE! | D446: ='RJ ATTENDENCE SHEET'!C:C -> 0 | E446: =C446 -> #VALUE! | F446: =IFERROR(SEARCH("SALARYOFFICE",$A:$A),"") | G446: =IFERROR(IF(F446=0,"",COUNTIF($F$3:F446,">0")),"") -> 16 | H446: =IFERROR(VLOOKUP(INDEX($A:$A,MATCH(ROW(F444),G:G,0)),$A:$D,4,0),"") | I446: =IFERROR(SEARCH("WAGES",$A:$A),"") | J446: =IFERROR(IF(I446=0,"",COUNTIF($I$3:I446,">0")),"") -> 34 | K446: =IFERROR(VLOOKUP(INDEX($A:$A,MATCH(ROW(I444),J:J,0)),$A:$D,4,0),"") | L446: =IFERROR(VLOOKUP(K446,$D:$E,2,0),"") | M446: =IFERROR(SEARCH("CONTRACT",$A:$A),"") | N446: =IFERROR(IF(M446=0,"",COUNTIF($M$3:M446,">0")),"") -> 33 | O446: =IFERROR(VLOOKUP(INDEX($A:$A,MATCH(ROW(M444),N:N,0)),$A:$D,4,0),"") | P446: =IFERROR(VLOOKUP(O446,$D:$E,2,0),"") | Q446: =IFERROR(SEARCH("SALARY",$A:$A),"") | R446: =IFERROR(IF(Q446=0,"",COUNTIF($Q$3:Q446,">0")),"") -> 16 | S446: =IFERROR(VLOOKUP(INDEX($A:$A,MATCH(ROW(Q444),R:R,0)),$A:$D,4,0),"") | T446: =IFERROR(SEARCH("OTHERS0",$A:$A),"") | U446: =IFERROR(IF(T446=0,"",COUNTIF($T$3:T446,">0")),"") -> 0 | V446: =IFERROR(VLOOKUP(INDEX($A:$A,MATCH(ROW(T444),U:U,0)),$A:$D,4,0),"")
A447: =CONCATENATE(B447,C447,D447) -> #VALUE! | B447: =Table4[[#This Row],[CATEGORY]] -> #VALUE! | C447: =Table4[[#This Row],[SUB-CATEGORY]] -> #VALUE! | D447: ='RJ ATTENDENCE SHEET'!C:C -> 0 | E447: =C447 -> #VALUE! | F447: =IFERROR(SEARCH("SALARYOFFICE",$A:$A),"") | G447: =IFERROR(IF(F447=0,"",COUNTIF($F$3:F447,">0")),"") -> 16 | H447: =IFERROR(VLOOKUP(INDEX($A:$A,MATCH(ROW(F445),G:G,0)),$A:$D,4,0),"") | I447: =IFERROR(SEARCH("WAGES",$A:$A),"") | J447: =IFERROR(IF(I447=0,"",COUNTIF($I$3:I447,">0")),"") -> 34 | K447: =IFERROR(VLOOKUP(INDEX($A:$A,MATCH(ROW(I445),J:J,0)),$A:$D,4,0),"") | L447: =IFERROR(VLOOKUP(K447,$D:$E,2,0),"") | M447: =IFERROR(SEARCH("CONTRACT",$A:$A),"") | N447: =IFERROR(IF(M447=0,"",COUNTIF($M$3:M447,">0")),"") -> 33 | O447: =IFERROR(VLOOKUP(INDEX($A:$A,MATCH(ROW(M445),N:N,0)),$A:$D,4,0),"") | P447: =IFERROR(VLOOKUP(O447,$D:$E,2,0),"") | Q447: =IFERROR(SEARCH("SALARY",$A:$A),"") | R447: =IFERROR(IF(Q447=0,"",COUNTIF($Q$3:Q447,">0")),"") -> 16 | S447: =IFERROR(VLOOKUP(INDEX($A:$A,MATCH(ROW(Q445),R:R,0)),$A:$D,4,0),"") | T447: =IFERROR(SEARCH("OTHERS0",$A:$A),"") | U447: =IFERROR(IF(T447=0,"",COUNTIF($T$3:T447,">0")),"") -> 0 | V447: =IFERROR(VLOOKUP(INDEX($A:$A,MATCH(ROW(T445),U:U,0)),$A:$D,4,0),"")
A448: =CONCATENATE(B448,C448,D448) -> #VALUE! | B448: =Table4[[#This Row],[CATEGORY]] -> #VALUE! | C448: =Table4[[#This Row],[SUB-CATEGORY]] -> #VALUE! | D448: ='RJ ATTENDENCE SHEET'!C:C -> 0 | E448: =C448 -> #VALUE! | F448: =IFERROR(SEARCH("SALARYOFFICE",$A:$A),"") | G448: =IFERROR(IF(F448=0,"",COUNTIF($F$3:F448,">0")),"") -> 16 | H448: =IFERROR(VLOOKUP(INDEX($A:$A,MATCH(ROW(F446),G:G,0)),$A:$D,4,0),"") | I448: =IFERROR(SEARCH("WAGES",$A:$A),"") | J448: =IFERROR(IF(I448=0,"",COUNTIF($I$3:I448,">0")),"") -> 34 | K448: =IFERROR(VLOOKUP(INDEX($A:$A,MATCH(ROW(I446),J:J,0)),$A:$D,4,0),"") | L448: =IFERROR(VLOOKUP(K448,$D:$E,2,0),"") | M448: =IFERROR(SEARCH("CONTRACT",$A:$A),"") | N448: =IFERROR(IF(M448=0,"",COUNTIF($M$3:M448,">0")),"") -> 33 | O448: =IFERROR(VLOOKUP(INDEX($A:$A,MATCH(ROW(M446),N:N,0)),$A:$D,4,0),"") | P448: =IFERROR(VLOOKUP(O448,$D:$E,2,0),"") | Q448: =IFERROR(SEARCH("SALARY",$A:$A),"") | R448: =IFERROR(IF(Q448=0,"",COUNTIF($Q$3:Q448,">0")),"") -> 16 | S448: =IFERROR(VLOOKUP(INDEX($A:$A,MATCH(ROW(Q446),R:R,0)),$A:$D,4,0),"") | T448: =IFERROR(SEARCH("OTHERS0",$A:$A),"") | U448: =IFERROR(IF(T448=0,"",COUNTIF($T$3:T448,">0")),"") -> 0 | V448: =IFERROR(VLOOKUP(INDEX($A:$A,MATCH(ROW(T446),U:U,0)),$A:$D,4,0),"")
A449: =CONCATENATE(B449,C449,D449) -> #VALUE! | B449: =Table4[[#This Row],[CATEGORY]] -> #VALUE! | C449: =Table4[[#This Row],[SUB-CATEGORY]] -> #VALUE! | D449: ='RJ ATTENDENCE SHEET'!C:C -> 0 | E449: =C449 -> #VALUE! | F449: =IFERROR(SEARCH("SALARYOFFICE",$A:$A),"") | G449: =IFERROR(IF(F449=0,"",COUNTIF($F$3:F449,">0")),"") -> 16 | H449: =IFERROR(VLOOKUP(INDEX($A:$A,MATCH(ROW(F447),G:G,0)),$A:$D,4,0),"") | I449: =IFERROR(SEARCH("WAGES",$A:$A),"") | J449: =IFERROR(IF(I449=0,"",COUNTIF($I$3:I449,">0")),"") -> 34 | K449: =IFERROR(VLOOKUP(INDEX($A:$A,MATCH(ROW(I447),J:J,0)),$A:$D,4,0),"") | L449: =IFERROR(VLOOKUP(K449,$D:$E,2,0),"") | M449: =IFERROR(SEARCH("CONTRACT",$A:$A),"") | N449: =IFERROR(IF(M449=0,"",COUNTIF($M$3:M449,">0")),"") -> 33 | O449: =IFERROR(VLOOKUP(INDEX($A:$A,MATCH(ROW(M447),N:N,0)),$A:$D,4,0),"") | P449: =IFERROR(VLOOKUP(O449,$D:$E,2,0),"") | Q449: =IFERROR(SEARCH("SALARY",$A:$A),"") | R449: =IFERROR(IF(Q449=0,"",COUNTIF($Q$3:Q449,">0")),"") -> 16 | S449: =IFERROR(VLOOKUP(INDEX($A:$A,MATCH(ROW(Q447),R:R,0)),$A:$D,4,0),"") | T449: =IFERROR(SEARCH("OTHERS0",$A:$A),"") | U449: =IFERROR(IF(T449=0,"",COUNTIF($T$3:T449,">0")),"") -> 0 | V449: =IFERROR(VLOOKUP(INDEX($A:$A,MATCH(ROW(T447),U:U,0)),$A:$D,4,0),"")
A450: =CONCATENATE(B450,C450,D450) -> #VALUE! | B450: =Table4[[#This Row],[CATEGORY]] -> #VALUE! | C450: =Table4[[#This Row],[SUB-CATEGORY]] -> #VALUE! | D450: ='RJ ATTENDENCE SHEET'!C:C -> 0 | E450: =C450 -> #VALUE! | F450: =IFERROR(SEARCH("SALARYOFFICE",$A:$A),"") | G450: =IFERROR(IF(F450=0,"",COUNTIF($F$3:F450,">0")),"") -> 16 | H450: =IFERROR(VLOOKUP(INDEX($A:$A,MATCH(ROW(F448),G:G,0)),$A:$D,4,0),"") | I450: =IFERROR(SEARCH("WAGES",$A:$A),"") | J450: =IFERROR(IF(I450=0,"",COUNTIF($I$3:I450,">0")),"") -> 34 | K450: =IFERROR(VLOOKUP(INDEX($A:$A,MATCH(ROW(I448),J:J,0)),$A:$D,4,0),"") | L450: =IFERROR(VLOOKUP(K450,$D:$E,2,0),"") | M450: =IFERROR(SEARCH("CONTRACT",$A:$A),"") | N450: =IFERROR(IF(M450=0,"",COUNTIF($M$3:M450,">0")),"") -> 33 | O450: =IFERROR(VLOOKUP(INDEX($A:$A,MATCH(ROW(M448),N:N,0)),$A:$D,4,0),"") | P450: =IFERROR(VLOOKUP(O450,$D:$E,2,0),"") | Q450: =IFERROR(SEARCH("SALARY",$A:$A),"") | R450: =IFERROR(IF(Q450=0,"",COUNTIF($Q$3:Q450,">0")),"") -> 16 | S450: =IFERROR(VLOOKUP(INDEX($A:$A,MATCH(ROW(Q448),R:R,0)),$A:$D,4,0),"") | T450: =IFERROR(SEARCH("OTHERS0",$A:$A),"") | U450: =IFERROR(IF(T450=0,"",COUNTIF($T$3:T450,">0")),"") -> 0 | V450: =IFERROR(VLOOKUP(INDEX($A:$A,MATCH(ROW(T448),U:U,0)),$A:$D,4,0),"")
... A1000: =CONCATENATE(B1000,C1000,D1000) -> #VALUE! | B1000: =Table4[[#This Row],[CATEGORY]] -> #VALUE! | C1000: =Table4[[#This Row],[SUB-CATEGORY]] -> #VALUE! | D1000: ='RJ ATTENDENCE SHEET'!C:C -> 0 | E1000: =C1000 -> #VALUE! | F1000: =IFERROR(SEARCH("SALARYOFFICE",$A:$A),"") | G1000: =IFERROR(IF(F1000=0,"",COUNTIF($F$3:F1000,">0")),"") -> 16 | H1000: =IFERROR(VLOOKUP(INDEX($A:$A,MATCH(ROW(F998),G:G,0)),$A:$D,4,0),"") | I1000: =IFERROR(SEARCH("WAGES",$A:$A),"") | J1000: =IFERROR(IF(I1000=0,"",COUNTIF($I$3:I1000,">0")),"") -> 34 | K1000: =IFERROR(VLOOKUP(INDEX($A:$A,MATCH(ROW(I998),J:J,0)),$A:$D,4,0),"") | L1000: =IFERROR(VLOOKUP(K1000,$D:$E,2,0),"") | M1000: =IFERROR(SEARCH("CONTRACT",$A:$A),"") | N1000: =IFERROR(IF(M1000=0,"",COUNTIF($M$3:M1000,">0")),"") -> 33 | O1000: =IFERROR(VLOOKUP(INDEX($A:$A,MATCH(ROW(M998),N:N,0)),$A:$D,4,0),"") | P1000: =IFERROR(VLOOKUP(O1000,$D:$E,2,0),"") | Q1000: =IFERROR(SEARCH("SALARY",$A:$A),"") | R1000: =IFERROR(IF(Q1000=0,"",COUNTIF($Q$3:Q1000,">0")),"") -> 16 | S1000: =IFERROR(VLOOKUP(INDEX($A:$A,MATCH(ROW(Q998),R:R,0)),$A:$D,4,0),"") | T1000: =IFERROR(SEARCH("OTHERS0",$A:$A),"") | U1000: =IFERROR(IF(T1000=0,"",COUNTIF($T$3:T1000,">0")),"") -> 0 | V1000: =IFERROR(VLOOKUP(INDEX($A:$A,MATCH(ROW(T998),U:U,0)),$A:$D,4,0),"")
A1200: password : admin
A1201: password : taratala

Sheet WHATSAPP
A3: DAILY STAFF ATTENDANCE REPORT OF RAJARHAT PLANT
J4: DATE: | K4: 43911
A5: SL.NO | B5: NAME | D5: DUTY | H5: SL.NO | J5: NAME | K5: DUTY | M5: TRIP
D6: DAY | E6: NIGHT | K6: DAY | L6: NIGHT
A7: SALARY | H7: CONTRACT
A8: 1 | B8: ='DATA '!S3 -> ABED ALI | D8: =IFERROR(VLOOKUP(B8,'RJ ATTENDENCE SHEET'!$C:$CG,('DATA '!$AA$3+21+('DATA '!$AA$3-1)),0),"") -> P | E8: =IFERROR(VLOOKUP(B8,'RJ ATTENDENCE SHEET'!$C:$CG,('DATA '!$AA$3+22+('DATA '!$AA$3-1)),0),"") -> A | H8: 1 | I8: =VLOOKUP(J8,'DATA '!$O:$P,2,0) -> HELPER | J8: ='DATA '!O3 -> AMIT BISWAS | K8: =IFERROR(VLOOKUP(J8,'RJ ATTENDENCE SHEET'!$C:$CG,('DATA '!$AA$3+21+('DATA '!$AA$3-1)),0),"") -> A | L8: =IFERROR(VLOOKUP(J8,'RJ ATTENDENCE SHEET'!$C:$CG,('DATA '!$AA$3+22+('DATA '!$AA$3-1)),0),"") -> P | M8: =IFERROR(VLOOKUP(J8,'RJ ATTENDENCE SHEET'!$C:$DM,('DATA '!$AA$3+84),0),"") -> 0
A9: 2 | B9: ='DATA '!S4 -> ABHI MUKHERJEE | D9: =IFERROR(VLOOKUP(B9,'RJ ATTENDENCE SHEET'!$C:$CG,('DATA '!$AA$3+21+('DATA '!$AA$3-1)),0),"") -> P | E9: =IFERROR(VLOOKUP(B9,'RJ ATTENDENCE SHEET'!$C:$CG,('DATA '!$AA$3+22+('DATA '!$AA$3-1)),0),"") -> A | H9: 2 | I9: =VLOOKUP(J9,'DATA '!$O:$P,2,0) -> HELPER | J9: ='DATA '!O4 -> JHANTU MONDAL | K9: =IFERROR(VLOOKUP(J9,'RJ ATTENDENCE SHEET'!$C:$CG,('DATA '!$AA$3+21+('DATA '!$AA$3-1)),0),"") -> P | L9: =IFERROR(VLOOKUP(J9,'RJ ATTENDENCE SHEET'!$C:$CG,('DATA '!$AA$3+22+('DATA '!$AA$3-1)),0),"") -> A | M9: =IFERROR(VLOOKUP(J9,'RJ ATTENDENCE SHEET'!$C:$DM,('DATA '!$AA$3+84),0),"") -> 0
A10: 3 | B10: ='DATA '!S5 -> ACHIN GUPTA | D10: =IFERROR(VLOOKUP(B10,'RJ ATTENDENCE SHEET'!$C:$CG,('DATA '!$AA$3+21+('DATA '!$AA$3-1)),0),"") -> P | E10: =IFERROR(VLOOKUP(B10,'RJ ATTENDENCE SHEET'!$C:$CG,('DATA '!$AA$3+22+('DATA '!$AA$3-1)),0),"") -> A | H10: 3 | I10: =VLOOKUP(J10,'DATA '!$O:$P,2,0) -> DRIVER | J10: ='DATA '!O5 -> ASHIT BISWAS | K10: =IFERROR(VLOOKUP(J10,'RJ ATTENDENCE SHEET'!$C:$CG,('DATA '!$AA$3+21+('DATA '!$AA$3-1)),0),"") -> A | L10: =IFERROR(VLOOKUP(J10,'RJ ATTENDENCE SHEET'!$C:$CG,('DATA '!$AA$3+22+('DATA '!$AA$3-1)),0),"") -> P | M10: =IFERROR(VLOOKUP(J10,'RJ ATTENDENCE SHEET'!$C:$DM,('DATA '!$AA$3+84),0),"") -> 0
A11: 4 | B11: ='DATA '!S6 -> AMIN YADAV | D11: =IFERROR(VLOOKUP(B11,'RJ ATTENDENCE SHEET'!$C:$CG,('DATA '!$AA$3+21+('DATA '!$AA$3-1)),0),"") -> P | E11: =IFERROR(VLOOKUP(B11,'RJ ATTENDENCE SHEET'!$C:$CG,('DATA '!$AA$3+22+('DATA '!$AA$3-1)),0),"") -> A | H11: 4 | I11: =VLOOKUP(J11,'DATA '!$O:$P,2,0) -> HELPER | J11: ='DATA '!O6 -> NASIB KARIKAR | K11: =IFERROR(VLOOKUP(J11,'RJ ATTENDENCE SHEET'!$C:$CG,('DATA '!$AA$3+21+('DATA '!$AA$3-1)),0),"") -> P | L11: =IFERROR(VLOOKUP(J11,'RJ ATTENDENCE SHEET'!$C:$CG,('DATA '!$AA$3+22+('DATA '!$AA$3-1)),0),"") -> P | M11: =IFERROR(VLOOKUP(J11,'RJ ATTENDENCE SHEET'!$C:$DM,('DATA '!$AA$3+84),0),"") -> 0
A12: 5 | B12: ='DATA '!S7 -> ANOWAR MOLLA | D12: =IFERROR(VLOOKUP(B12,'RJ ATTENDENCE SHEET'!$C:$CG,('DATA '!$AA$3+21+('DATA '!$AA$3-1)),0),"") -> P | E12: =IFERROR(VLOOKUP(B12,'RJ ATTENDENCE SHEET'!$C:$CG,('DATA '!$AA$3+22+('DATA '!$AA$3-1)),0),"") -> A | H12: 5 | I12: =VLOOKUP(J12,'DATA '!$O:$P,2,0) -> OTHERS | J12: ='DATA '!O7 -> BASIRUDDIN KHAN | K12: =IFERROR(VLOOKUP(J12,'RJ ATTENDENCE SHEET'!$C:$CG,('DATA '!$AA$3+21+('DATA '!$AA$3-1)),0),"") -> P | L12: =IFERROR(VLOOKUP(J12,'RJ ATTENDENCE SHEET'!$C:$CG,('DATA '!$AA$3+22+('DATA '!$AA$3-1)),0),"") -> A | M12: =IFERROR(VLOOKUP(J12,'RJ ATTENDENCE SHEET'!$C:$DM,('DATA '!$AA$3+84),0),"") -> 0
A13: 6 | B13: ='DATA '!S8 -> DIBAKAR MONDAL | D13: =IFERROR(VLOOKUP(B13,'RJ ATTENDENCE SHEET'!$C:$CG,('DATA '!$AA$3+21+('DATA '!$AA$3-1)),0),"") -> P | E13: =IFERROR(VLOOKUP(B13,'RJ ATTENDENCE SHEET'!$C:$CG,('DATA '!$AA$3+22+('DATA '!$AA$3-1)),0),"") -> A | H13: 6 | I13: =VLOOKUP(J13,'DATA '!$O:$P,2,0) -> DRIVER | J13: ='DATA '!O8 -> DIN MOHAMMOD ALI | K13: =IFERROR(VLOOKUP(J13,'RJ ATTENDENCE SHEET'!$C:$CG,('DATA '!$AA$3+21+('DATA '!$AA$3-1)),0),"") -> P | L13: =IFERROR(VLOOKUP(J13,'RJ ATTENDENCE SHEET'!$C:$CG,('DATA '!$AA$3+22+('DATA '!$AA$3-1)),0),"") -> A | M13: =IFERROR(VLOOKUP(J13,'RJ ATTENDENCE SHEET'!$C:$DM,('DATA '!$AA$3+84),0),"") -> 0
A14: 7 | B14: ='DATA '!S9 -> GOLAM SARWAR | D14: =IFERROR(VLOOKUP(B14,'RJ ATTENDENCE SHEET'!$C:$CG,('DATA '!$AA$3+21+('DATA '!$AA$3-1)),0),"") -> P | E14: =IFERROR(VLOOKUP(B14,'RJ ATTENDENCE SHEET'!$C:$CG,('DATA '!$AA$3+22+('DATA '!$AA$3-1)),0),"") -> A | H14: 7 | I14: =VLOOKUP(J14,'DATA '!$O:$P,2,0) -> DRIVER | J14: ='DATA '!O9 -> RAFIQUE MOLLA | K14: =IFERROR(VLOOKUP(J14,'RJ ATTENDENCE SHEET'!$C:$CG,('DATA '!$AA$3+21+('DATA '!$AA$3-1)),0),"") -> A | L14: =IFERROR(VLOOKUP(J14,'RJ ATTENDENCE SHEET'!$C:$CG,('DATA '!$AA$3+22+('DATA '!$AA$3-1)),0),"") -> P | M14: =IFERROR(VLOOKUP(J14,'RJ ATTENDENCE SHEET'!$C:$DM,('DATA '!$AA$3+84),0),"") -> 0
A15: 8 | B15: ='DATA '!S10 -> IMAN ALI MOLLA | D15: =IFERROR(VLOOKUP(B15,'RJ ATTENDENCE SHEET'!$C:$CG,('DATA '!$AA$3+21+('DATA '!$AA$3-1)),0),"") -> P | E15: =IFERROR(VLOOKUP(B15,'RJ ATTENDENCE SHEET'!$C:$CG,('DATA '!$AA$3+22+('DATA '!$AA$3-1)),0),"") -> A | H15: 8 | I15: =VLOOKUP(J15,'DATA '!$O:$P,2,0) -> HELPER | J15: ='DATA '!O10 -> RAFIKUL MOLLA | K15: =IFERROR(VLOOKUP(J15,'RJ ATTENDENCE SHEET'!$C:$CG,('DATA '!$AA$3+21+('DATA '!$AA$3-1)),0),"") -> A | L15: =IFERROR(VLOOKUP(J15,'RJ ATTENDENCE SHEET'!$C:$CG,('DATA '!$AA$3+22+('DATA '!$AA$3-1)),0),"") -> A | M15: =IFERROR(VLOOKUP(J15,'RJ ATTENDENCE SHEET'!$C:$DM,('DATA '!$AA$3+84),0),"") -> 0
A16: 9 | B16: ='DATA '!S11 -> PULIN MONDAL | D16: =IFERROR(VLOOKUP(B16,'RJ ATTENDENCE SHEET'!$C:$CG,('DATA '!$AA$3+21+('DATA '!$AA$3-1)),0),"") -> P | E16: =IFERROR(VLOOKUP(B16,'RJ ATTENDENCE SHEET'!$C:$CG,('DATA '!$AA$3+22+('DATA '!$AA$3-1)),0),"") -> A | H16: 9 | I16: =VLOOKUP(J16,'DATA '!$O:$P,2,0) -> OTHERS | J16: ='DATA '!O11 -> AYAN PAUL | K16: =IFERROR(VLOOKUP(J16,'RJ ATTENDENCE SHEET'!$C:$CG,('DATA '!$AA$3+21+('DATA '!$AA$3-1)),0),"") -> P | L16: =IFERROR(VLOOKUP(J16,'RJ ATTENDENCE SHEET'!$C:$CG,('DATA '!$AA$3+22+('DATA '!$AA$3-1)),0),"") -> A | M16: =IFERROR(VLOOKUP(J16,'RJ ATTENDENCE SHEET'!$C:$DM,('DATA '!$AA$3+84),0),"") -> 0
A17: 10 | B17: ='DATA '!S12 -> RAJU PAL | D17: =IFERROR(VLOOKUP(B17,'RJ ATTENDENCE SHEET'!$C:$CG,('DATA '!$AA$3+21+('DATA '!$AA$3-1)),0),"") -> P | E17: =IFERROR(VLOOKUP(B17,'RJ ATTENDENCE SHEET'!$C:$CG,('DATA '!$AA$3+22+('DATA '!$AA$3-1)),0),"") -> A | H17: 10 | I17: =VLOOKUP(J17,'DATA '!$O:$P,2,0) -> HELPER | J17: ='DATA '!O12 -> NAYAN MONDAL | K17: =IFERROR(VLOOKUP(J17,'RJ ATTENDENCE SHEET'!$C:$CG,('DATA '!$AA$3+21+('DATA '!$AA$3-1)),0),"") -> P | L17: =IFERROR(VLOOKUP(J17,'RJ ATTENDENCE SHEET'!$C:$CG,('DATA '!$AA$3+22+('DATA '!$AA$3-1)),0),"") -> A | M17: =IFERROR(VLOOKUP(J17,'RJ ATTENDENCE SHEET'!$C:$DM,('DATA '!$AA$3+84),0),"") -> 0
A18: 11 | B18: ='DATA '!S13 -> UJJAL MUKHERJEE | D18: =IFERROR(VLOOKUP(B18,'RJ ATTENDENCE SHEET'!$C:$CG,('DATA '!$AA$3+21+('DATA '!$AA$3-1)),0),"") -> P | E18: =IFERROR(VLOOKUP(B18,'RJ ATTENDENCE SHEET'!$C:$CG,('DATA '!$AA$3+22+('DATA '!$AA$3-1)),0),"") -> A | H18: 11 | I18: =VLOOKUP(J18,'DATA '!$O:$P,2,0) -> OTHERS | J18: ='DATA '!O13 -> SHIB SANKAR MAJHI | K18: =IFERROR(VLOOKUP(J18,'RJ ATTENDENCE SHEET'!$C:$CG,('DATA '!$AA$3+21+('DATA '!$AA$3-1)),0),"") -> P | L18: =IFERROR(VLOOKUP(J18,'RJ ATTENDENCE SHEET'!$C:$CG,('DATA '!$AA$3+22+('DATA '!$AA$3-1)),0),"") -> A | M18: =IFERROR(VLOOKUP(J18,'RJ ATTENDENCE SHEET'!$C:$DM,('DATA '!$AA$3+84),0),"") -> 0
A19: 12 | B19: ='DATA '!S14 -> PROBIR GHOSH | D19: =IFERROR(VLOOKUP(B19,'RJ ATTENDENCE SHEET'!$C:$CG,('DATA '!$AA$3+21+('DATA '!$AA$3-1)),0),"") -> P | E19: =IFERROR(VLOOKUP(B19,'RJ ATTENDENCE SHEET'!$C:$CG,('DATA '!$AA$3+22+('DATA '!$AA$3-1)),0),"") -> A | H19: 12 | I19: =VLOOKUP(J19,'DATA '!$O:$P,2,0) -> OTHERS | J19: ='DATA '!O14 -> ABUL KALAM AZAD | K19: =IFERROR(VLOOKUP(J19,'RJ ATTENDENCE SHEET'!$C:$CG,('DATA '!$AA$3+21+('DATA '!$AA$3-1)),0),"") -> P | L19: =IFERROR(VLOOKUP(J19,'RJ ATTENDENCE SHEET'!$C:$CG,('DATA '!$AA$3+22+('DATA '!$AA$3-1)),0),"") -> A | M19: =IFERROR(VLOOKUP(J19,'RJ ATTENDENCE SHEET'!$C:$DM,('DATA '!$AA$3+84),0),"") -> 0
... A27: 20 | B27: ='DATA '!S22 | D27: =IFERROR(VLOOKUP(B27,'RJ ATTENDENCE SHEET'!$C:$CG,('DATA '!$AA$3+21+('DATA '!$AA$3-1)),0),"") | E27: =IFERROR(VLOOKUP(B27,'RJ ATTENDENCE SHEET'!$C:$CG,('DATA '!$AA$3+22+('DATA '!$AA$3-1)),0),"") | H27: 20 | I27: =VLOOKUP(J27,'DATA '!$O:$P,2,0) -> DRIVER | J27: ='DATA '!O22 -> MOFIJUL ALI | K27: =IFERROR(VLOOKUP(J27,'RJ ATTENDENCE SHEET'!$C:$CG,('DATA '!$AA$3+21+('DATA '!$AA$3-1)),0),"") -> P | L27: =IFERROR(VLOOKUP(J27,'RJ ATTENDENCE SHEET'!$C:$CG,('DATA '!$AA$3+22+('DATA '!$AA$3-1)),0),"") -> A | M27: =IFERROR(VLOOKUP(J27,'RJ ATTENDENCE SHEET'!$C:$DM,('DATA '!$AA$3+84),0),"") -> 0
B28: ='DATA '!S23 | D28: =IFERROR(VLOOKUP(B28,'RJ ATTENDENCE SHEET'!$C:$CG,('DATA '!$AA$3+21+('DATA '!$AA$3-1)),0),"") | E28: =IFERROR(VLOOKUP(B28,'RJ ATTENDENCE SHEET'!$C:$CG,('DATA '!$AA$3+22+('DATA '!$AA$3-1)),0),"") | H28: 21 | I28: =VLOOKUP(J28,'DATA '!$O:$P,2,0) -> LAB | J28: ='DATA '!O23 -> ASHIK AHMED | K28: =IFERROR(VLOOKUP(J28,'RJ ATTENDENCE SHEET'!$C:$CG,('DATA '!$AA$3+21+('DATA '!$AA$3-1)),0),"") -> A | L28: =IFERROR(VLOOKUP(J28,'RJ ATTENDENCE SHEET'!$C:$CG,('DATA '!$AA$3+22+('DATA '!$AA$3-1)),0),"") -> P | M28: =IFERROR(VLOOKUP(J28,'RJ ATTENDENCE SHEET'!$C:$DM,('DATA '!$AA$3+84),0),"") -> 0
B29: ='DATA '!S24 | D29: =IFERROR(VLOOKUP(B29,'RJ ATTENDENCE SHEET'!$C:$CG,('DATA '!$AA$3+21+('DATA '!$AA$3-1)),0),"") | E29: =IFERROR(VLOOKUP(B29,'RJ ATTENDENCE SHEET'!$C:$CG,('DATA '!$AA$3+22+('DATA '!$AA$3-1)),0),"") | H29: 22 | I29: =VLOOKUP(J29,'DATA '!$O:$P,2,0) -> LAB | J29: ='DATA '!O24 -> SAMIT MONDAL | K29: =IFERROR(VLOOKUP(J29,'RJ ATTENDENCE SHEET'!$C:$CG,('DATA '!$AA$3+21+('DATA '!$AA$3-1)),0),"") -> P | L29: =IFERROR(VLOOKUP(J29,'RJ ATTENDENCE SHEET'!$C:$CG,('DATA '!$AA$3+22+('DATA '!$AA$3-1)),0),"") -> A | M29: =IFERROR(VLOOKUP(J29,'RJ ATTENDENCE SHEET'!$C:$DM,('DATA '!$AA$3+84),0),"") -> 0
B30: ='DATA '!S25 | D30: =IFERROR(VLOOKUP(B30,'RJ ATTENDENCE SHEET'!$C:$CG,('DATA '!$AA$3+21+('DATA '!$AA$3-1)),0),"") | E30: =IFERROR(VLOOKUP(B30,'RJ ATTENDENCE SHEET'!$C:$CG,('DATA '!$AA$3+22+('DATA '!$AA$3-1)),0),"") | H30: 23 | I30: =VLOOKUP(J30,'DATA '!$O:$P,2,0) -> LAB | J30: ='DATA '!O25 -> SIDHARTHA MONDAL | K30: =IFERROR(VLOOKUP(J30,'RJ ATTENDENCE SHEET'!$C:$CG,('DATA '!$AA$3+21+('DATA '!$AA$3-1)),0),"") -> P | L30: =IFERROR(VLOOKUP(J30,'RJ ATTENDENCE SHEET'!$C:$CG,('DATA '!$AA$3+22+('DATA '!$AA$3-1)),0),"") -> A | M30: =IFERROR(VLOOKUP(J30,'RJ ATTENDENCE SHEET'!$C:$DM,('DATA '!$AA$3+84),0),"") -> 0
B31: ='DATA '!S26 | D31: =IFERROR(VLOOKUP(B31,'RJ ATTENDENCE SHEET'!$C:$CG,('DATA '!$AA$3+21+('DATA '!$AA$3-1)),0),"") | E31: =IFERROR(VLOOKUP(B31,'RJ ATTENDENCE SHEET'!$C:$CG,('DATA '!$AA$3+22+('DATA '!$AA$3-1)),0),"") | H31: 24 | I31: =VLOOKUP(J31,'DATA '!$O:$P,2,0) -> HOPPER | J31: ='DATA '!O26 -> SUBRATA MONDAL | K31: =IFERROR(VLOOKUP(J31,'RJ ATTENDENCE SHEET'!$C:$CG,('DATA '!$AA$3+21+('DATA '!$AA$3-1)),0),"") -> P | L31: =IFERROR(VLOOKUP(J31,'RJ ATTENDENCE SHEET'!$C:$CG,('DATA '!$AA$3+22+('DATA '!$AA$3-1)),0),"") -> A | M31: =IFERROR(VLOOKUP(J31,'RJ ATTENDENCE SHEET'!$C:$DM,('DATA '!$AA$3+84),0),"") -> 0
B32: ='DATA '!S27 | D32: =IFERROR(VLOOKUP(B32,'RJ ATTENDENCE SHEET'!$C:$CG,('DATA '!$AA$3+21+('DATA '!$AA$3-1)),0),"") | E32: =IFERROR(VLOOKUP(B32,'RJ ATTENDENCE SHEET'!$C:$CG,('DATA '!$AA$3+22+('DATA '!$AA$3-1)),0),"") | H32: 25 | I32: =VLOOKUP(J32,'DATA '!$O:$P,2,0) -> HELPER | J32: ='DATA '!O27 -> REJJAK MONDAL | K32: =IFERROR(VLOOKUP(J32,'RJ ATTENDENCE SHEET'!$C:$CG,('DATA '!$AA$3+21+('DATA '!$AA$3-1)),0),"") -> P | L32: =IFERROR(VLOOKUP(J32,'RJ ATTENDENCE SHEET'!$C:$CG,('DATA '!$AA$3+22+('DATA '!$AA$3-1)),0),"") -> A | M32: =IFERROR(VLOOKUP(J32,'RJ ATTENDENCE SHEET'!$C:$DM,('DATA '!$AA$3+84),0),"") -> 0
B33: ='DATA '!S28 | D33: =IFERROR(VLOOKUP(B33,'RJ ATTENDENCE SHEET'!$C:$CG,('DATA '!$AA$3+21+('DATA '!$AA$3-1)),0),"") | E33: =IFERROR(VLOOKUP(B33,'RJ ATTENDENCE SHEET'!$C:$CG,('DATA '!$AA$3+22+('DATA '!$AA$3-1)),0),"") | H33: 26 | I33: =VLOOKUP(J33,'DATA '!$O:$P,2,0) -> DRIVER | J33: ='DATA '!O28 -> BISWANTH MONDAL | K33: =IFERROR(VLOOKUP(J33,'RJ ATTENDENCE SHEET'!$C:$CG,('DATA '!$AA$3+21+('DATA '!$AA$3-1)),0),"") -> A | L33: =IFERROR(VLOOKUP(J33,'RJ ATTENDENCE SHEET'!$C:$CG,('DATA '!$AA$3+22+('DATA '!$AA$3-1)),0),"") -> P | M33: =IFERROR(VLOOKUP(J33,'RJ ATTENDENCE SHEET'!$C:$DM,('DATA '!$AA$3+84),0),"") -> 0
B34: ='DATA '!S29 | D34: =IFERROR(VLOOKUP(B34,'RJ ATTENDENCE SHEET'!$C:$CG,('DATA '!$AA$3+21+('DATA '!$AA$3-1)),0),"") | E34: =IFERROR(VLOOKUP(B34,'RJ ATTENDENCE SHEET'!$C:$CG,('DATA '!$AA$3+22+('DATA '!$AA$3-1)),0),"") | H34: 27 | I34: =VLOOKUP(J34,'DATA '!$O:$P,2,0) -> HELPER | J34: ='DATA '!O29 -> TAPAS MONDAL | K34: =IFERROR(VLOOKUP(J34,'RJ ATTENDENCE SHEET'!$C:$CG,('DATA '!$AA$3+21+('DATA '!$AA$3-1)),0),"") -> P | L34: =IFERROR(VLOOKUP(J34,'RJ ATTENDENCE SHEET'!$C:$CG,('DATA '!$AA$3+22+('DATA '!$AA$3-1)),0),"") -> P | M34: =IFERROR(VLOOKUP(J34,'RJ ATTENDENCE SHEET'!$C:$DM,('DATA '!$AA$3+84),0),"") -> 1
B35: ='DATA '!S30 | D35: =IFERROR(VLOOKUP(B35,'RJ ATTENDENCE SHEET'!$C:$CG,('DATA '!$AA$3+21+('DATA '!$AA$3-1)),0),"") | E35: =IFERROR(VLOOKUP(B35,'RJ ATTENDENCE SHEET'!$C:$CG,('DATA '!$AA$3+22+('DATA '!$AA$3-1)),0),"") | H35: 28 | I35: =VLOOKUP(J35,'DATA '!$O:$P,2,0) -> HELPER | J35: ='DATA '!O30 -> RASHID MONDAL | K35: =IFERROR(VLOOKUP(J35,'RJ ATTENDENCE SHEET'!$C:$CG,('DATA '!$AA$3+21+('DATA '!$AA$3-1)),0),"") -> P | L35: =IFERROR(VLOOKUP(J35,'RJ ATTENDENCE SHEET'!$C:$CG,('DATA '!$AA$3+22+('DATA '!$AA$3-1)),0),"") -> A | M35: =IFERROR(VLOOKUP(J35,'RJ ATTENDENCE SHEET'!$C:$DM,('DATA '!$AA$3+84),0),"") -> 0
B36: ='DATA '!S31 | D36: =IFERROR(VLOOKUP(B36,'RJ ATTENDENCE SHEET'!$C:$CG,('DATA '!$AA$3+21+('DATA '!$AA$3-1)),0),"") | E36: =IFERROR(VLOOKUP(B36,'RJ ATTENDENCE SHEET'!$C:$CG,('DATA '!$AA$3+22+('DATA '!$AA$3-1)),0),"") | H36: 29 | I36: =VLOOKUP(J36,'DATA '!$O:$P,2,0) -> HELPER | J36: ='DATA '!O31 -> RAJU MONDAL | K36: =IFERROR(VLOOKUP(J36,'RJ ATTENDENCE SHEET'!$C:$CG,('DATA '!$AA$3+21+('DATA '!$AA$3-1)),0),"") -> A | L36: =IFERROR(VLOOKUP(J36,'RJ ATTENDENCE SHEET'!$C:$CG,('DATA '!$AA$3+22+('DATA '!$AA$3-1)),0),"") -> P | M36: =IFERROR(VLOOKUP(J36,'RJ ATTENDENCE SHEET'!$C:$DM,('DATA '!$AA$3+84),0),"") -> 0
B37: ='DATA '!S32 | D37: =IFERROR(VLOOKUP(B37,'RJ ATTENDENCE SHEET'!$C:$CG,('DATA '!$AA$3+21+('DATA '!$AA$3-1)),0),"") | E37: =IFERROR(VLOOKUP(B37,'RJ ATTENDENCE SHEET'!$C:$CG,('DATA '!$AA$3+22+('DATA '!$AA$3-1)),0),"") | H37: 30 | I37: =VLOOKUP(J37,'DATA '!$O:$P,2,0) -> HELPER | J37: ='DATA '!O32 -> SUDIP MONDAL | K37: =IFERROR(VLOOKUP(J37,'RJ ATTENDENCE SHEET'!$C:$CG,('DATA '!$AA$3+21+('DATA '!$AA$3-1)),0),"") -> A | L37: =IFERROR(VLOOKUP(J37,'RJ ATTENDENCE SHEET'!$C:$CG,('DATA '!$AA$3+22+('DATA '!$AA$3-1)),0),"") -> P | M37: =IFERROR(VLOOKUP(J37,'RJ ATTENDENCE SHEET'!$C:$DM,('DATA '!$AA$3+84),0),"") -> 0
B38: ='DATA '!S33 | D38: =IFERROR(VLOOKUP(B38,'RJ ATTENDENCE SHEET'!$C:$CG,('DATA '!$AA$3+21+('DATA '!$AA$3-1)),0),"") | E38: =IFERROR(VLOOKUP(B38,'RJ ATTENDENCE SHEET'!$C:$CG,('DATA '!$AA$3+22+('DATA '!$AA$3-1)),0),"") | H38: 31 | I38: =VLOOKUP(J38,'DATA '!$O:$P,2,0) -> OTHERS | J38: ='DATA '!O33 -> ALMIRAJ JHAN | K38: =IFERROR(VLOOKUP(J38,'RJ ATTENDENCE SHEET'!$C:$CG,('DATA '!$AA$3+21+('DATA '!$AA$3-1)),0),"") -> 0 | L38: =IFERROR(VLOOKUP(J38,'RJ ATTENDENCE SHEET'!$C:$CG,('DATA '!$AA$3+22+('DATA '!$AA$3-1)),0),"") -> 0 | M38: =IFERROR(VLOOKUP(J38,'RJ ATTENDENCE SHEET'!$C:$DM,('DATA '!$AA$3+84),0),"") -> 0
